2024-11-30 11:04:02,569 - [INFO] -  config - (app.py).create_app(9) - Создана БД
2024-11-30 11:04:02,572 - [INFO] -  config - (app.py).create_app(12) - Зарегистрирован (<Blueprint 'timer'>, <Blueprint 'users'>)
2024-11-30 11:04:03,146 - [INFO] -  config - (app.py).create_app(9) - Создана БД
2024-11-30 11:04:03,160 - [INFO] -  config - (app.py).create_app(12) - Зарегистрирован (<Blueprint 'timer'>, <Blueprint 'users'>)
2024-11-30 11:04:08,376 - [INFO] -  config - (endpoints.py).get(53) - Анонимный пользователь зашел на страницу
2024-11-30 11:04:21,749 - [INFO] -  config - (user.py).post(42) - Пользователь qwerty зарегистирован!
2024-11-30 11:04:27,038 - [INFO] -  config - (user.py).post(69) - Пользователь qwerty вошел в систему!
2024-11-30 11:04:27,061 - [INFO] -  config - (endpoints.py).get(53) - Анонимный пользователь зашел на страницу
2024-11-30 11:04:37,374 - [INFO] -  config - (endpoints.py).get(53) - Анонимный пользователь зашел на страницу
2024-11-30 11:04:38,862 - [INFO] -  config - (endpoints.py).get(53) - Анонимный пользователь зашел на страницу
2024-11-30 11:04:42,369 - [INFO] -  config - (endpoints.py).get(53) - Анонимный пользователь зашел на страницу
2024-11-30 11:04:43,864 - [INFO] -  config - (endpoints.py).get(53) - Анонимный пользователь зашел на страницу
2024-11-30 11:04:44,409 - [INFO] -  config - (endpoints.py).get(53) - Анонимный пользователь зашел на страницу
2024-11-30 11:04:44,614 - [INFO] -  config - (endpoints.py).get(53) - Анонимный пользователь зашел на страницу
2024-11-30 11:04:45,500 - [INFO] -  config - (endpoints.py).get(53) - Анонимный пользователь зашел на страницу
2024-11-30 11:04:53,286 - [INFO] -  config - (endpoints.py).get(53) - Анонимный пользователь зашел на страницу
2024-11-30 11:06:09,816 - [INFO] -  config - (app.py).create_app(9) - Создана БД
2024-11-30 11:06:09,816 - [INFO] -  config - (app.py).create_app(12) - Зарегистрирован (<Blueprint 'timer'>, <Blueprint 'users'>)
2024-11-30 11:06:10,376 - [INFO] -  config - (app.py).create_app(9) - Создана БД
2024-11-30 11:06:10,376 - [INFO] -  config - (app.py).create_app(12) - Зарегистрирован (<Blueprint 'timer'>, <Blueprint 'users'>)
2024-11-30 11:06:14,462 - [INFO] -  config - (endpoints.py).get(53) - Анонимный пользователь зашел на страницу
2024-11-30 11:06:22,502 - [INFO] -  config - (endpoints.py).get(53) - Анонимный пользователь зашел на страницу
2024-11-30 11:06:57,733 - [INFO] -  config - (endpoints.py).get(53) - Анонимный пользователь зашел на страницу
2024-12-25 20:12:51,009 - [INFO] -  config - (app.py).create_app(9) - Создана БД
2024-12-25 20:12:51,028 - [INFO] -  config - (app.py).create_app(12) - Зарегистрирован (<Blueprint 'timer'>, <Blueprint 'users'>)
2024-12-25 20:12:51,738 - [INFO] -  config - (app.py).create_app(9) - Создана БД
2024-12-25 20:12:51,742 - [INFO] -  config - (app.py).create_app(12) - Зарегистрирован (<Blueprint 'timer'>, <Blueprint 'users'>)
2024-12-25 20:12:55,780 - [ERROR] -  config - (app.py).log_exception(838) - Exception on / [GET]
Traceback (most recent call last):
  File "W:\WEB_WORK\Homework\NAA\time_tracker-last\venv\lib\site-packages\flask\app.py", line 1473, in wsgi_app
    response = self.full_dispatch_request()
  File "W:\WEB_WORK\Homework\NAA\time_tracker-last\venv\lib\site-packages\flask\app.py", line 882, in full_dispatch_request
    rv = self.handle_user_exception(e)
  File "W:\WEB_WORK\Homework\NAA\time_tracker-last\venv\lib\site-packages\flask\app.py", line 880, in full_dispatch_request
    rv = self.dispatch_request()
  File "W:\WEB_WORK\Homework\NAA\time_tracker-last\venv\lib\site-packages\flask\app.py", line 865, in dispatch_request
    return self.ensure_sync(self.view_functions[rule.endpoint])(**view_args)  # type: ignore[no-any-return]
  File "W:\WEB_WORK\Homework\NAA\time_tracker-last\venv\lib\site-packages\flask\views.py", line 110, in view
    return current_app.ensure_sync(self.dispatch_request)(**kwargs)  # type: ignore[no-any-return]
  File "W:\WEB_WORK\Homework\NAA\time_tracker-last\venv\lib\site-packages\flask\views.py", line 191, in dispatch_request
    return current_app.ensure_sync(meth)(**kwargs)  # type: ignore[no-any-return]
  File "W:\WEB_WORK\Homework\NAA\time_tracker-last\sources\endpoints.py", line 21, in get
    return render_template('index.html')
  File "W:\WEB_WORK\Homework\NAA\time_tracker-last\venv\lib\site-packages\flask\templating.py", line 150, in render_template
    return _render(app, template, context)
  File "W:\WEB_WORK\Homework\NAA\time_tracker-last\venv\lib\site-packages\flask\templating.py", line 131, in _render
    rv = template.render(context)
  File "W:\WEB_WORK\Homework\NAA\time_tracker-last\venv\lib\site-packages\jinja2\environment.py", line 1304, in render
    self.environment.handle_exception()
  File "W:\WEB_WORK\Homework\NAA\time_tracker-last\venv\lib\site-packages\jinja2\environment.py", line 939, in handle_exception
    raise rewrite_traceback_stack(source=source)
  File "W:\WEB_WORK\Homework\NAA\time_tracker-last\templates\index.html", line 1, in top-level template code
    {% extends 'base.html' %} {% block title %}Учет рабочего времени{% endblock %}
  File "W:\WEB_WORK\Homework\NAA\time_tracker-last\templates\base.html", line 27, in top-level template code
    {% block content %}
  File "W:\WEB_WORK\Homework\NAA\time_tracker-last\templates\index.html", line 51, in block 'content'
    {% if pagination.total > 0 %}
  File "W:\WEB_WORK\Homework\NAA\time_tracker-last\venv\lib\site-packages\jinja2\environment.py", line 487, in getattr
    return getattr(obj, attribute)
jinja2.exceptions.UndefinedError: 'pagination' is undefined
2024-12-25 20:12:58,165 - [ERROR] -  config - (app.py).log_exception(838) - Exception on / [GET]
Traceback (most recent call last):
  File "W:\WEB_WORK\Homework\NAA\time_tracker-last\venv\lib\site-packages\flask\app.py", line 1473, in wsgi_app
    response = self.full_dispatch_request()
  File "W:\WEB_WORK\Homework\NAA\time_tracker-last\venv\lib\site-packages\flask\app.py", line 882, in full_dispatch_request
    rv = self.handle_user_exception(e)
  File "W:\WEB_WORK\Homework\NAA\time_tracker-last\venv\lib\site-packages\flask\app.py", line 880, in full_dispatch_request
    rv = self.dispatch_request()
  File "W:\WEB_WORK\Homework\NAA\time_tracker-last\venv\lib\site-packages\flask\app.py", line 865, in dispatch_request
    return self.ensure_sync(self.view_functions[rule.endpoint])(**view_args)  # type: ignore[no-any-return]
  File "W:\WEB_WORK\Homework\NAA\time_tracker-last\venv\lib\site-packages\flask\views.py", line 110, in view
    return current_app.ensure_sync(self.dispatch_request)(**kwargs)  # type: ignore[no-any-return]
  File "W:\WEB_WORK\Homework\NAA\time_tracker-last\venv\lib\site-packages\flask\views.py", line 191, in dispatch_request
    return current_app.ensure_sync(meth)(**kwargs)  # type: ignore[no-any-return]
  File "W:\WEB_WORK\Homework\NAA\time_tracker-last\sources\endpoints.py", line 21, in get
    return render_template('index.html')
  File "W:\WEB_WORK\Homework\NAA\time_tracker-last\venv\lib\site-packages\flask\templating.py", line 150, in render_template
    return _render(app, template, context)
  File "W:\WEB_WORK\Homework\NAA\time_tracker-last\venv\lib\site-packages\flask\templating.py", line 131, in _render
    rv = template.render(context)
  File "W:\WEB_WORK\Homework\NAA\time_tracker-last\venv\lib\site-packages\jinja2\environment.py", line 1304, in render
    self.environment.handle_exception()
  File "W:\WEB_WORK\Homework\NAA\time_tracker-last\venv\lib\site-packages\jinja2\environment.py", line 939, in handle_exception
    raise rewrite_traceback_stack(source=source)
  File "W:\WEB_WORK\Homework\NAA\time_tracker-last\templates\index.html", line 1, in top-level template code
    {% extends 'base.html' %} {% block title %}Учет рабочего времени{% endblock %}
  File "W:\WEB_WORK\Homework\NAA\time_tracker-last\templates\base.html", line 27, in top-level template code
    {% block content %}
  File "W:\WEB_WORK\Homework\NAA\time_tracker-last\templates\index.html", line 51, in block 'content'
    {% if pagination.total > 0 %}
  File "W:\WEB_WORK\Homework\NAA\time_tracker-last\venv\lib\site-packages\jinja2\environment.py", line 487, in getattr
    return getattr(obj, attribute)
jinja2.exceptions.UndefinedError: 'pagination' is undefined
2024-12-25 20:12:59,043 - [ERROR] -  config - (app.py).log_exception(838) - Exception on / [GET]
Traceback (most recent call last):
  File "W:\WEB_WORK\Homework\NAA\time_tracker-last\venv\lib\site-packages\flask\app.py", line 1473, in wsgi_app
    response = self.full_dispatch_request()
  File "W:\WEB_WORK\Homework\NAA\time_tracker-last\venv\lib\site-packages\flask\app.py", line 882, in full_dispatch_request
    rv = self.handle_user_exception(e)
  File "W:\WEB_WORK\Homework\NAA\time_tracker-last\venv\lib\site-packages\flask\app.py", line 880, in full_dispatch_request
    rv = self.dispatch_request()
  File "W:\WEB_WORK\Homework\NAA\time_tracker-last\venv\lib\site-packages\flask\app.py", line 865, in dispatch_request
    return self.ensure_sync(self.view_functions[rule.endpoint])(**view_args)  # type: ignore[no-any-return]
  File "W:\WEB_WORK\Homework\NAA\time_tracker-last\venv\lib\site-packages\flask\views.py", line 110, in view
    return current_app.ensure_sync(self.dispatch_request)(**kwargs)  # type: ignore[no-any-return]
  File "W:\WEB_WORK\Homework\NAA\time_tracker-last\venv\lib\site-packages\flask\views.py", line 191, in dispatch_request
    return current_app.ensure_sync(meth)(**kwargs)  # type: ignore[no-any-return]
  File "W:\WEB_WORK\Homework\NAA\time_tracker-last\sources\endpoints.py", line 21, in get
    return render_template('index.html')
  File "W:\WEB_WORK\Homework\NAA\time_tracker-last\venv\lib\site-packages\flask\templating.py", line 150, in render_template
    return _render(app, template, context)
  File "W:\WEB_WORK\Homework\NAA\time_tracker-last\venv\lib\site-packages\flask\templating.py", line 131, in _render
    rv = template.render(context)
  File "W:\WEB_WORK\Homework\NAA\time_tracker-last\venv\lib\site-packages\jinja2\environment.py", line 1304, in render
    self.environment.handle_exception()
  File "W:\WEB_WORK\Homework\NAA\time_tracker-last\venv\lib\site-packages\jinja2\environment.py", line 939, in handle_exception
    raise rewrite_traceback_stack(source=source)
  File "W:\WEB_WORK\Homework\NAA\time_tracker-last\templates\index.html", line 1, in top-level template code
    {% extends 'base.html' %} {% block title %}Учет рабочего времени{% endblock %}
  File "W:\WEB_WORK\Homework\NAA\time_tracker-last\templates\base.html", line 27, in top-level template code
    {% block content %}
  File "W:\WEB_WORK\Homework\NAA\time_tracker-last\templates\index.html", line 51, in block 'content'
    {% if pagination.total > 0 %}
  File "W:\WEB_WORK\Homework\NAA\time_tracker-last\venv\lib\site-packages\jinja2\environment.py", line 487, in getattr
    return getattr(obj, attribute)
jinja2.exceptions.UndefinedError: 'pagination' is undefined
2024-12-25 20:13:25,517 - [ERROR] -  config - (user.py).post(46) - Неудачная регистрация!
2024-12-25 20:13:57,817 - [ERROR] -  config - (user.py).post(91) - Неудачная аутентификация!
2024-12-25 20:14:36,298 - [INFO] -  config - (user.py).post(43) - Пользователь seva зарегистирован!
2024-12-25 20:14:45,573 - [INFO] -  config - (user.py).post(89) - Пользователь seva вошел в систему!
2024-12-25 20:14:45,589 - [ERROR] -  config - (app.py).log_exception(838) - Exception on / [GET]
Traceback (most recent call last):
  File "W:\WEB_WORK\Homework\NAA\time_tracker-last\venv\lib\site-packages\flask\app.py", line 1473, in wsgi_app
    response = self.full_dispatch_request()
  File "W:\WEB_WORK\Homework\NAA\time_tracker-last\venv\lib\site-packages\flask\app.py", line 882, in full_dispatch_request
    rv = self.handle_user_exception(e)
  File "W:\WEB_WORK\Homework\NAA\time_tracker-last\venv\lib\site-packages\flask\app.py", line 880, in full_dispatch_request
    rv = self.dispatch_request()
  File "W:\WEB_WORK\Homework\NAA\time_tracker-last\venv\lib\site-packages\flask\app.py", line 865, in dispatch_request
    return self.ensure_sync(self.view_functions[rule.endpoint])(**view_args)  # type: ignore[no-any-return]
  File "W:\WEB_WORK\Homework\NAA\time_tracker-last\venv\lib\site-packages\flask\views.py", line 110, in view
    return current_app.ensure_sync(self.dispatch_request)(**kwargs)  # type: ignore[no-any-return]
  File "W:\WEB_WORK\Homework\NAA\time_tracker-last\venv\lib\site-packages\flask\views.py", line 191, in dispatch_request
    return current_app.ensure_sync(meth)(**kwargs)  # type: ignore[no-any-return]
  File "W:\WEB_WORK\Homework\NAA\time_tracker-last\sources\endpoints.py", line 21, in get
    return render_template('index.html')
  File "W:\WEB_WORK\Homework\NAA\time_tracker-last\venv\lib\site-packages\flask\templating.py", line 150, in render_template
    return _render(app, template, context)
  File "W:\WEB_WORK\Homework\NAA\time_tracker-last\venv\lib\site-packages\flask\templating.py", line 131, in _render
    rv = template.render(context)
  File "W:\WEB_WORK\Homework\NAA\time_tracker-last\venv\lib\site-packages\jinja2\environment.py", line 1304, in render
    self.environment.handle_exception()
  File "W:\WEB_WORK\Homework\NAA\time_tracker-last\venv\lib\site-packages\jinja2\environment.py", line 939, in handle_exception
    raise rewrite_traceback_stack(source=source)
  File "W:\WEB_WORK\Homework\NAA\time_tracker-last\templates\index.html", line 1, in top-level template code
    {% extends 'base.html' %} {% block title %}Учет рабочего времени{% endblock %}
  File "W:\WEB_WORK\Homework\NAA\time_tracker-last\templates\base.html", line 27, in top-level template code
    {% block content %}
  File "W:\WEB_WORK\Homework\NAA\time_tracker-last\templates\index.html", line 51, in block 'content'
    {% if pagination.total > 0 %}
  File "W:\WEB_WORK\Homework\NAA\time_tracker-last\venv\lib\site-packages\jinja2\environment.py", line 487, in getattr
    return getattr(obj, attribute)
jinja2.exceptions.UndefinedError: 'pagination' is undefined
2024-12-25 20:16:22,234 - [INFO] -  config - (endpoints.py).api_data(195) - Ошибка при получении данных
2024-12-25 20:24:45,759 - [ERROR] -  config - (endpoints.py).post(28) - 1 validation error for TimeTrackerSchema
name_of_work
  Value error, Название проекта может содержать только буквы и цифры, а также не превышать 25 символов [type=value_error, input_value='ййй', input_type=str]
    For further information visit https://errors.pydantic.dev/2.10/v/value_error
2024-12-25 20:25:10,961 - [ERROR] -  config - (app.py).log_exception(838) - Exception on / [POST]
Traceback (most recent call last):
  File "W:\WEB_WORK\Homework\NAA\time_tracker-last\venv\lib\site-packages\sqlalchemy\engine\base.py", line 1967, in _exec_single_context
    self.dialect.do_execute(
  File "W:\WEB_WORK\Homework\NAA\time_tracker-last\venv\lib\site-packages\sqlalchemy\engine\default.py", line 941, in do_execute
    cursor.execute(statement, parameters)
sqlite3.OperationalError: no such column: time_tracker.username

The above exception was the direct cause of the following exception:

Traceback (most recent call last):
  File "W:\WEB_WORK\Homework\NAA\time_tracker-last\venv\lib\site-packages\flask\app.py", line 1473, in wsgi_app
    response = self.full_dispatch_request()
  File "W:\WEB_WORK\Homework\NAA\time_tracker-last\venv\lib\site-packages\flask\app.py", line 882, in full_dispatch_request
    rv = self.handle_user_exception(e)
  File "W:\WEB_WORK\Homework\NAA\time_tracker-last\venv\lib\site-packages\flask\app.py", line 880, in full_dispatch_request
    rv = self.dispatch_request()
  File "W:\WEB_WORK\Homework\NAA\time_tracker-last\venv\lib\site-packages\flask\app.py", line 865, in dispatch_request
    return self.ensure_sync(self.view_functions[rule.endpoint])(**view_args)  # type: ignore[no-any-return]
  File "W:\WEB_WORK\Homework\NAA\time_tracker-last\venv\lib\site-packages\flask\views.py", line 110, in view
    return current_app.ensure_sync(self.dispatch_request)(**kwargs)  # type: ignore[no-any-return]
  File "W:\WEB_WORK\Homework\NAA\time_tracker-last\venv\lib\site-packages\flask\views.py", line 191, in dispatch_request
    return current_app.ensure_sync(meth)(**kwargs)  # type: ignore[no-any-return]
  File "W:\WEB_WORK\Homework\NAA\time_tracker-last\venv\lib\site-packages\flask_jwt_extended\view_decorators.py", line 170, in decorator
    return current_app.ensure_sync(fn)(*args, **kwargs)
  File "W:\WEB_WORK\Homework\NAA\time_tracker-last\sources\endpoints.py", line 39, in post
    for value in values:
  File "W:\WEB_WORK\Homework\NAA\time_tracker-last\venv\lib\site-packages\sqlalchemy\orm\query.py", line 2813, in __iter__
    result = self._iter()
  File "W:\WEB_WORK\Homework\NAA\time_tracker-last\venv\lib\site-packages\sqlalchemy\orm\query.py", line 2827, in _iter
    result: Union[ScalarResult[_T], Result[_T]] = self.session.execute(
  File "W:\WEB_WORK\Homework\NAA\time_tracker-last\venv\lib\site-packages\sqlalchemy\orm\session.py", line 2362, in execute
    return self._execute_internal(
  File "W:\WEB_WORK\Homework\NAA\time_tracker-last\venv\lib\site-packages\sqlalchemy\orm\session.py", line 2247, in _execute_internal
    result: Result[Any] = compile_state_cls.orm_execute_statement(
  File "W:\WEB_WORK\Homework\NAA\time_tracker-last\venv\lib\site-packages\sqlalchemy\orm\context.py", line 305, in orm_execute_statement
    result = conn.execute(
  File "W:\WEB_WORK\Homework\NAA\time_tracker-last\venv\lib\site-packages\sqlalchemy\engine\base.py", line 1418, in execute
    return meth(
  File "W:\WEB_WORK\Homework\NAA\time_tracker-last\venv\lib\site-packages\sqlalchemy\sql\elements.py", line 515, in _execute_on_connection
    return connection._execute_clauseelement(
  File "W:\WEB_WORK\Homework\NAA\time_tracker-last\venv\lib\site-packages\sqlalchemy\engine\base.py", line 1640, in _execute_clauseelement
    ret = self._execute_context(
  File "W:\WEB_WORK\Homework\NAA\time_tracker-last\venv\lib\site-packages\sqlalchemy\engine\base.py", line 1846, in _execute_context
    return self._exec_single_context(
  File "W:\WEB_WORK\Homework\NAA\time_tracker-last\venv\lib\site-packages\sqlalchemy\engine\base.py", line 1986, in _exec_single_context
    self._handle_dbapi_exception(
  File "W:\WEB_WORK\Homework\NAA\time_tracker-last\venv\lib\site-packages\sqlalchemy\engine\base.py", line 2355, in _handle_dbapi_exception
    raise sqlalchemy_exception.with_traceback(exc_info[2]) from e
  File "W:\WEB_WORK\Homework\NAA\time_tracker-last\venv\lib\site-packages\sqlalchemy\engine\base.py", line 1967, in _exec_single_context
    self.dialect.do_execute(
  File "W:\WEB_WORK\Homework\NAA\time_tracker-last\venv\lib\site-packages\sqlalchemy\engine\default.py", line 941, in do_execute
    cursor.execute(statement, parameters)
sqlalchemy.exc.OperationalError: (sqlite3.OperationalError) no such column: time_tracker.username
[SQL: SELECT time_tracker.id AS time_tracker_id, time_tracker.name_of_work AS time_tracker_name_of_work, time_tracker.date AS time_tracker_date, time_tracker.time AS time_tracker_time, time_tracker.description AS time_tracker_description, time_tracker.username AS time_tracker_username 
FROM time_tracker 
WHERE time_tracker.date = ? AND time_tracker.username = ?]
[parameters: ('2024-12-25', 'seva')]
(Background on this error at: https://sqlalche.me/e/20/e3q8)
2024-12-25 20:26:36,202 - [ERROR] -  config - (endpoints.py).post(28) - 1 validation error for TimeTrackerSchema
name_of_work
  Value error, Название проекта может содержать только буквы и цифры, а также не превышать 25 символов [type=value_error, input_value='ввв', input_type=str]
    For further information visit https://errors.pydantic.dev/2.10/v/value_error
2024-12-25 20:32:58,080 - [ERROR] -  config - (app.py).log_exception(838) - Exception on / [POST]
Traceback (most recent call last):
  File "W:\WEB_WORK\Homework\NAA\time_tracker-last\venv\lib\site-packages\sqlalchemy\engine\base.py", line 1967, in _exec_single_context
    self.dialect.do_execute(
  File "W:\WEB_WORK\Homework\NAA\time_tracker-last\venv\lib\site-packages\sqlalchemy\engine\default.py", line 941, in do_execute
    cursor.execute(statement, parameters)
sqlite3.OperationalError: no such column: time_tracker.username

The above exception was the direct cause of the following exception:

Traceback (most recent call last):
  File "W:\WEB_WORK\Homework\NAA\time_tracker-last\venv\lib\site-packages\flask\app.py", line 1473, in wsgi_app
    response = self.full_dispatch_request()
  File "W:\WEB_WORK\Homework\NAA\time_tracker-last\venv\lib\site-packages\flask\app.py", line 882, in full_dispatch_request
    rv = self.handle_user_exception(e)
  File "W:\WEB_WORK\Homework\NAA\time_tracker-last\venv\lib\site-packages\flask\app.py", line 880, in full_dispatch_request
    rv = self.dispatch_request()
  File "W:\WEB_WORK\Homework\NAA\time_tracker-last\venv\lib\site-packages\flask\app.py", line 865, in dispatch_request
    return self.ensure_sync(self.view_functions[rule.endpoint])(**view_args)  # type: ignore[no-any-return]
  File "W:\WEB_WORK\Homework\NAA\time_tracker-last\venv\lib\site-packages\flask\views.py", line 110, in view
    return current_app.ensure_sync(self.dispatch_request)(**kwargs)  # type: ignore[no-any-return]
  File "W:\WEB_WORK\Homework\NAA\time_tracker-last\venv\lib\site-packages\flask\views.py", line 191, in dispatch_request
    return current_app.ensure_sync(meth)(**kwargs)  # type: ignore[no-any-return]
  File "W:\WEB_WORK\Homework\NAA\time_tracker-last\venv\lib\site-packages\flask_jwt_extended\view_decorators.py", line 170, in decorator
    return current_app.ensure_sync(fn)(*args, **kwargs)
  File "W:\WEB_WORK\Homework\NAA\time_tracker-last\sources\endpoints.py", line 39, in post
    for value in values:
  File "W:\WEB_WORK\Homework\NAA\time_tracker-last\venv\lib\site-packages\sqlalchemy\orm\query.py", line 2813, in __iter__
    result = self._iter()
  File "W:\WEB_WORK\Homework\NAA\time_tracker-last\venv\lib\site-packages\sqlalchemy\orm\query.py", line 2827, in _iter
    result: Union[ScalarResult[_T], Result[_T]] = self.session.execute(
  File "W:\WEB_WORK\Homework\NAA\time_tracker-last\venv\lib\site-packages\sqlalchemy\orm\session.py", line 2362, in execute
    return self._execute_internal(
  File "W:\WEB_WORK\Homework\NAA\time_tracker-last\venv\lib\site-packages\sqlalchemy\orm\session.py", line 2247, in _execute_internal
    result: Result[Any] = compile_state_cls.orm_execute_statement(
  File "W:\WEB_WORK\Homework\NAA\time_tracker-last\venv\lib\site-packages\sqlalchemy\orm\context.py", line 305, in orm_execute_statement
    result = conn.execute(
  File "W:\WEB_WORK\Homework\NAA\time_tracker-last\venv\lib\site-packages\sqlalchemy\engine\base.py", line 1418, in execute
    return meth(
  File "W:\WEB_WORK\Homework\NAA\time_tracker-last\venv\lib\site-packages\sqlalchemy\sql\elements.py", line 515, in _execute_on_connection
    return connection._execute_clauseelement(
  File "W:\WEB_WORK\Homework\NAA\time_tracker-last\venv\lib\site-packages\sqlalchemy\engine\base.py", line 1640, in _execute_clauseelement
    ret = self._execute_context(
  File "W:\WEB_WORK\Homework\NAA\time_tracker-last\venv\lib\site-packages\sqlalchemy\engine\base.py", line 1846, in _execute_context
    return self._exec_single_context(
  File "W:\WEB_WORK\Homework\NAA\time_tracker-last\venv\lib\site-packages\sqlalchemy\engine\base.py", line 1986, in _exec_single_context
    self._handle_dbapi_exception(
  File "W:\WEB_WORK\Homework\NAA\time_tracker-last\venv\lib\site-packages\sqlalchemy\engine\base.py", line 2355, in _handle_dbapi_exception
    raise sqlalchemy_exception.with_traceback(exc_info[2]) from e
  File "W:\WEB_WORK\Homework\NAA\time_tracker-last\venv\lib\site-packages\sqlalchemy\engine\base.py", line 1967, in _exec_single_context
    self.dialect.do_execute(
  File "W:\WEB_WORK\Homework\NAA\time_tracker-last\venv\lib\site-packages\sqlalchemy\engine\default.py", line 941, in do_execute
    cursor.execute(statement, parameters)
sqlalchemy.exc.OperationalError: (sqlite3.OperationalError) no such column: time_tracker.username
[SQL: SELECT time_tracker.id AS time_tracker_id, time_tracker.name_of_work AS time_tracker_name_of_work, time_tracker.date AS time_tracker_date, time_tracker.time AS time_tracker_time, time_tracker.description AS time_tracker_description, time_tracker.username AS time_tracker_username 
FROM time_tracker 
WHERE time_tracker.date = ? AND time_tracker.username = ?]
[parameters: ('2024-12-25', 'seva')]
(Background on this error at: https://sqlalche.me/e/20/e3q8)
2024-12-25 20:34:58,935 - [INFO] -  config - (endpoints.py).api_data(195) - Ошибка при получении данных
2024-12-25 20:35:34,617 - [INFO] -  config - (endpoints.py).api_data(195) - Ошибка при получении данных
2024-12-25 20:43:48,326 - [INFO] -  config - (endpoints.py).api_data(195) - Ошибка при получении данных
2024-12-25 20:47:18,693 - [INFO] -  config - (endpoints.py).api_data(195) - Ошибка при получении данных
2024-12-25 20:49:30,281 - [INFO] -  config - (endpoints.py).api_data(195) - Ошибка при получении данных
2024-12-25 20:52:04,705 - [INFO] -  config - (endpoints.py).api_data(195) - Ошибка при получении данных
2024-12-25 20:52:16,760 - [INFO] -  config - (endpoints.py).api_data(195) - Ошибка при получении данных
2024-12-25 20:52:24,408 - [INFO] -  config - (endpoints.py).api_data(195) - Ошибка при получении данных
2024-12-25 20:52:58,514 - [INFO] -  config - (endpoints.py).api_data(195) - Ошибка при получении данных
2024-12-25 20:53:04,782 - [INFO] -  config - (endpoints.py).api_data(195) - Ошибка при получении данных
2024-12-25 20:53:24,304 - [INFO] -  config - (endpoints.py).api_data(195) - Ошибка при получении данных
2024-12-25 20:57:05,621 - [INFO] -  config - (endpoints.py).api_data(195) - Ошибка при получении данных
2024-12-25 20:57:10,474 - [INFO] -  config - (endpoints.py).api_data(195) - Ошибка при получении данных
2024-12-25 20:57:51,024 - [INFO] -  config - (endpoints.py).api_data(195) - Ошибка при получении данных
2024-12-25 21:02:17,713 - [INFO] -  config - (endpoints.py).api_data(195) - Ошибка при получении данных
2024-12-25 21:02:26,846 - [INFO] -  config - (endpoints.py).api_data(195) - Ошибка при получении данных
2024-12-25 21:02:57,197 - [INFO] -  config - (endpoints.py).api_data(195) - Ошибка при получении данных
2024-12-25 21:03:20,898 - [ERROR] -  config - (app.py).log_exception(838) - Exception on /edit/25.12.2024/ddd [POST]
Traceback (most recent call last):
  File "W:\WEB_WORK\Homework\NAA\time_tracker-last\sources\endpoints.py", line 87, in post
    form_data = TimeTrackerSchema(**request.form.to_dict()).dict()
  File "W:\WEB_WORK\Homework\NAA\time_tracker-last\venv\lib\site-packages\pydantic\main.py", line 214, in __init__
    validated_self = self.__pydantic_validator__.validate_python(data, self_instance=self)
pydantic_core._pydantic_core.ValidationError: 3 validation errors for TimeTrackerSchema
name_of_work
  Field required [type=missing, input_value={}, input_type=dict]
    For further information visit https://errors.pydantic.dev/2.10/v/missing
time
  Field required [type=missing, input_value={}, input_type=dict]
    For further information visit https://errors.pydantic.dev/2.10/v/missing
date
  Field required [type=missing, input_value={}, input_type=dict]
    For further information visit https://errors.pydantic.dev/2.10/v/missing

During handling of the above exception, another exception occurred:

Traceback (most recent call last):
  File "W:\WEB_WORK\Homework\NAA\time_tracker-last\venv\lib\site-packages\flask\app.py", line 1473, in wsgi_app
    response = self.full_dispatch_request()
  File "W:\WEB_WORK\Homework\NAA\time_tracker-last\venv\lib\site-packages\flask\app.py", line 882, in full_dispatch_request
    rv = self.handle_user_exception(e)
  File "W:\WEB_WORK\Homework\NAA\time_tracker-last\venv\lib\site-packages\flask\app.py", line 880, in full_dispatch_request
    rv = self.dispatch_request()
  File "W:\WEB_WORK\Homework\NAA\time_tracker-last\venv\lib\site-packages\flask\app.py", line 865, in dispatch_request
    return self.ensure_sync(self.view_functions[rule.endpoint])(**view_args)  # type: ignore[no-any-return]
  File "W:\WEB_WORK\Homework\NAA\time_tracker-last\venv\lib\site-packages\flask\views.py", line 110, in view
    return current_app.ensure_sync(self.dispatch_request)(**kwargs)  # type: ignore[no-any-return]
  File "W:\WEB_WORK\Homework\NAA\time_tracker-last\venv\lib\site-packages\flask\views.py", line 191, in dispatch_request
    return current_app.ensure_sync(meth)(**kwargs)  # type: ignore[no-any-return]
  File "W:\WEB_WORK\Homework\NAA\time_tracker-last\venv\lib\site-packages\flask_jwt_extended\view_decorators.py", line 170, in decorator
    return current_app.ensure_sync(fn)(*args, **kwargs)
  File "W:\WEB_WORK\Homework\NAA\time_tracker-last\sources\endpoints.py", line 90, in post
    error = errors[0].split('error,')[1]
IndexError: list index out of range
2024-12-25 21:06:06,566 - [INFO] -  config - (endpoints.py).api_data(195) - Ошибка при получении данных
2024-12-25 21:06:27,227 - [INFO] -  config - (endpoints.py).api_data(195) - Ошибка при получении данных
2024-12-25 21:07:38,132 - [INFO] -  config - (endpoints.py).api_data(195) - Ошибка при получении данных
2024-12-25 21:10:20,894 - [INFO] -  config - (endpoints.py).api_data(195) - Ошибка при получении данных
2024-12-25 21:10:42,713 - [INFO] -  config - (endpoints.py).api_data(195) - Ошибка при получении данных
2024-12-25 21:10:57,740 - [INFO] -  config - (endpoints.py).api_data(195) - Ошибка при получении данных
2024-12-25 21:11:19,901 - [INFO] -  config - (endpoints.py).api_data(195) - Ошибка при получении данных
2024-12-25 21:11:52,554 - [INFO] -  config - (endpoints.py).api_data(195) - Ошибка при получении данных
2024-12-25 21:12:35,670 - [INFO] -  config - (endpoints.py).api_data(195) - Ошибка при получении данных
2024-12-25 21:14:38,206 - [INFO] -  config - (endpoints.py).api_data(195) - Ошибка при получении данных
2024-12-25 21:15:41,668 - [ERROR] -  config - (endpoints.py).post(28) - 1 validation error for TimeTrackerSchema
name_of_work
  Value error, Название проекта может содержать только буквы и цифры, а также не превышать 25 символов [type=value_error, input_value='ввв', input_type=str]
    For further information visit https://errors.pydantic.dev/2.10/v/value_error
2024-12-25 21:16:29,643 - [ERROR] -  config - (app.py).log_exception(838) - Exception on /delete/25.12.2024/ввв [DELETE]
Traceback (most recent call last):
  File "W:\WEB_WORK\Homework\NAA\time_tracker-last\venv\lib\site-packages\sqlalchemy\engine\base.py", line 1967, in _exec_single_context
    self.dialect.do_execute(
  File "W:\WEB_WORK\Homework\NAA\time_tracker-last\venv\lib\site-packages\sqlalchemy\engine\default.py", line 941, in do_execute
    cursor.execute(statement, parameters)
sqlite3.OperationalError: no such column: time_tracker.username

The above exception was the direct cause of the following exception:

Traceback (most recent call last):
  File "W:\WEB_WORK\Homework\NAA\time_tracker-last\venv\lib\site-packages\flask\app.py", line 1473, in wsgi_app
    response = self.full_dispatch_request()
  File "W:\WEB_WORK\Homework\NAA\time_tracker-last\venv\lib\site-packages\flask\app.py", line 882, in full_dispatch_request
    rv = self.handle_user_exception(e)
  File "W:\WEB_WORK\Homework\NAA\time_tracker-last\venv\lib\site-packages\flask\app.py", line 880, in full_dispatch_request
    rv = self.dispatch_request()
  File "W:\WEB_WORK\Homework\NAA\time_tracker-last\venv\lib\site-packages\flask\app.py", line 865, in dispatch_request
    return self.ensure_sync(self.view_functions[rule.endpoint])(**view_args)  # type: ignore[no-any-return]
  File "W:\WEB_WORK\Homework\NAA\time_tracker-last\venv\lib\site-packages\flask_jwt_extended\view_decorators.py", line 170, in decorator
    return current_app.ensure_sync(fn)(*args, **kwargs)
  File "W:\WEB_WORK\Homework\NAA\time_tracker-last\sources\endpoints.py", line 160, in delete_item
    ).delete():
  File "W:\WEB_WORK\Homework\NAA\time_tracker-last\venv\lib\site-packages\sqlalchemy\orm\query.py", line 3162, in delete
    result: CursorResult[Any] = self.session.execute(
  File "W:\WEB_WORK\Homework\NAA\time_tracker-last\venv\lib\site-packages\sqlalchemy\orm\session.py", line 2362, in execute
    return self._execute_internal(
  File "W:\WEB_WORK\Homework\NAA\time_tracker-last\venv\lib\site-packages\sqlalchemy\orm\session.py", line 2247, in _execute_internal
    result: Result[Any] = compile_state_cls.orm_execute_statement(
  File "W:\WEB_WORK\Homework\NAA\time_tracker-last\venv\lib\site-packages\sqlalchemy\orm\bulk_persistence.py", line 2021, in orm_execute_statement
    return super().orm_execute_statement(
  File "W:\WEB_WORK\Homework\NAA\time_tracker-last\venv\lib\site-packages\sqlalchemy\orm\context.py", line 305, in orm_execute_statement
    result = conn.execute(
  File "W:\WEB_WORK\Homework\NAA\time_tracker-last\venv\lib\site-packages\sqlalchemy\engine\base.py", line 1418, in execute
    return meth(
  File "W:\WEB_WORK\Homework\NAA\time_tracker-last\venv\lib\site-packages\sqlalchemy\sql\elements.py", line 515, in _execute_on_connection
    return connection._execute_clauseelement(
  File "W:\WEB_WORK\Homework\NAA\time_tracker-last\venv\lib\site-packages\sqlalchemy\engine\base.py", line 1640, in _execute_clauseelement
    ret = self._execute_context(
  File "W:\WEB_WORK\Homework\NAA\time_tracker-last\venv\lib\site-packages\sqlalchemy\engine\base.py", line 1846, in _execute_context
    return self._exec_single_context(
  File "W:\WEB_WORK\Homework\NAA\time_tracker-last\venv\lib\site-packages\sqlalchemy\engine\base.py", line 1986, in _exec_single_context
    self._handle_dbapi_exception(
  File "W:\WEB_WORK\Homework\NAA\time_tracker-last\venv\lib\site-packages\sqlalchemy\engine\base.py", line 2355, in _handle_dbapi_exception
    raise sqlalchemy_exception.with_traceback(exc_info[2]) from e
  File "W:\WEB_WORK\Homework\NAA\time_tracker-last\venv\lib\site-packages\sqlalchemy\engine\base.py", line 1967, in _exec_single_context
    self.dialect.do_execute(
  File "W:\WEB_WORK\Homework\NAA\time_tracker-last\venv\lib\site-packages\sqlalchemy\engine\default.py", line 941, in do_execute
    cursor.execute(statement, parameters)
sqlalchemy.exc.OperationalError: (sqlite3.OperationalError) no such column: time_tracker.username
[SQL: DELETE FROM time_tracker WHERE time_tracker.name_of_work = ? AND time_tracker.date = ? AND time_tracker.username = ?]
[parameters: ('name_of_work', '2024-12-25', 'seva')]
(Background on this error at: https://sqlalche.me/e/20/e3q8)
2024-12-25 21:18:24,782 - [INFO] -  config - (endpoints.py).api_data(195) - Ошибка при получении данных
2024-12-25 21:19:10,612 - [ERROR] -  config - (endpoints.py).post(28) - 1 validation error for TimeTrackerSchema
name_of_work
  Value error, Название проекта может содержать только буквы и цифры, а также не превышать 25 символов [type=value_error, input_value='ккк', input_type=str]
    For further information visit https://errors.pydantic.dev/2.10/v/value_error
2024-12-25 21:45:28,622 - [INFO] -  config - (app.py).create_app(9) - Создана БД
2024-12-25 21:45:28,627 - [INFO] -  config - (app.py).create_app(12) - Зарегистрирован (<Blueprint 'timer'>, <Blueprint 'users'>)
2024-12-25 21:45:29,410 - [INFO] -  config - (app.py).create_app(9) - Создана БД
2024-12-25 21:45:29,414 - [INFO] -  config - (app.py).create_app(12) - Зарегистрирован (<Blueprint 'timer'>, <Blueprint 'users'>)
2024-12-25 21:45:50,089 - [INFO] -  config - (endpoints.py).api_data(195) - Ошибка при получении данных
2024-12-25 21:45:53,917 - [INFO] -  config - (user.py).get(113) - Пользователь seva вышел из системы!
2024-12-25 21:45:53,941 - [ERROR] -  config - (config.py).load_logged_in_user(83) - Error in load_logged_in_user: Token has been revoked
2024-12-25 21:45:53,982 - [ERROR] -  config - (config.py).load_logged_in_user(83) - Error in load_logged_in_user: Token has been revoked
2024-12-25 21:45:55,373 - [ERROR] -  config - (config.py).load_logged_in_user(83) - Error in load_logged_in_user: Token has been revoked
2024-12-25 21:45:55,409 - [ERROR] -  config - (config.py).load_logged_in_user(83) - Error in load_logged_in_user: Token has been revoked
2024-12-25 21:45:55,551 - [ERROR] -  config - (config.py).load_logged_in_user(83) - Error in load_logged_in_user: Token has been revoked
2024-12-25 21:45:55,588 - [ERROR] -  config - (config.py).load_logged_in_user(83) - Error in load_logged_in_user: Token has been revoked
2024-12-25 21:45:56,856 - [ERROR] -  config - (config.py).load_logged_in_user(83) - Error in load_logged_in_user: Token has been revoked
2024-12-25 21:45:56,970 - [ERROR] -  config - (config.py).load_logged_in_user(83) - Error in load_logged_in_user: Token has been revoked
2024-12-25 21:46:07,309 - [ERROR] -  config - (config.py).load_logged_in_user(83) - Error in load_logged_in_user: Token has been revoked
2024-12-25 21:46:07,341 - [ERROR] -  config - (config.py).load_logged_in_user(83) - Error in load_logged_in_user: Token has been revoked
2024-12-25 21:46:07,395 - [ERROR] -  config - (config.py).load_logged_in_user(83) - Error in load_logged_in_user: Token has been revoked
2024-12-25 21:46:18,316 - [ERROR] -  config - (config.py).load_logged_in_user(83) - Error in load_logged_in_user: Token has been revoked
2024-12-25 21:46:18,460 - [INFO] -  config - (user.py).post(43) - Пользователь Александр зарегистирован!
2024-12-25 21:46:18,469 - [ERROR] -  config - (config.py).load_logged_in_user(83) - Error in load_logged_in_user: Token has been revoked
2024-12-25 21:46:18,496 - [ERROR] -  config - (config.py).load_logged_in_user(83) - Error in load_logged_in_user: Token has been revoked
2024-12-25 21:46:30,708 - [ERROR] -  config - (config.py).load_logged_in_user(83) - Error in load_logged_in_user: Token has been revoked
2024-12-25 21:46:30,817 - [INFO] -  config - (user.py).post(89) - Пользователь Александр вошел в систему!
2024-12-25 21:46:30,976 - [INFO] -  config - (endpoints.py).api_data(195) - Ошибка при получении данных
2024-12-25 21:47:18,725 - [ERROR] -  config - (endpoints.py).post(28) - 1 validation error for TimeTrackerSchema
name_of_work
  Value error, Название проекта может содержать только буквы и цифры, а также не превышать 25 символов [type=value_error, input_value='йцу', input_type=str]
    For further information visit https://errors.pydantic.dev/2.10/v/value_error
2024-12-25 21:47:24,021 - [INFO] -  config - (endpoints.py).api_data(195) - Ошибка при получении данных
2024-12-25 21:48:14,863 - [INFO] -  config - (endpoints.py).api_data(195) - Ошибка при получении данных
2024-12-25 21:50:29,417 - [INFO] -  config - (endpoints.py).api_data(195) - Ошибка при получении данных
2024-12-25 21:51:10,450 - [INFO] -  config - (user.py).get(113) - Пользователь Александр вышел из системы!
2024-12-25 21:51:10,465 - [ERROR] -  config - (config.py).load_logged_in_user(83) - Error in load_logged_in_user: Token has been revoked
2024-12-25 21:51:10,490 - [ERROR] -  config - (config.py).load_logged_in_user(83) - Error in load_logged_in_user: Token has been revoked
2024-12-25 21:51:11,693 - [ERROR] -  config - (config.py).load_logged_in_user(83) - Error in load_logged_in_user: Token has been revoked
2024-12-25 21:51:11,715 - [ERROR] -  config - (config.py).load_logged_in_user(83) - Error in load_logged_in_user: Token has been revoked
2024-12-25 21:51:17,843 - [ERROR] -  config - (config.py).load_logged_in_user(83) - Error in load_logged_in_user: Token has been revoked
2024-12-25 21:51:21,085 - [ERROR] -  config - (config.py).load_logged_in_user(83) - Error in load_logged_in_user: Token has been revoked
2024-12-25 21:51:21,112 - [ERROR] -  config - (config.py).load_logged_in_user(83) - Error in load_logged_in_user: Token has been revoked
2024-12-25 21:51:25,521 - [ERROR] -  config - (config.py).load_logged_in_user(83) - Error in load_logged_in_user: Token has been revoked
2024-12-25 21:51:25,636 - [INFO] -  config - (user.py).post(43) - Пользователь wwww зарегистирован!
2024-12-25 21:51:25,643 - [ERROR] -  config - (config.py).load_logged_in_user(83) - Error in load_logged_in_user: Token has been revoked
2024-12-25 21:51:25,671 - [ERROR] -  config - (config.py).load_logged_in_user(83) - Error in load_logged_in_user: Token has been revoked
2024-12-25 21:51:29,757 - [ERROR] -  config - (config.py).load_logged_in_user(83) - Error in load_logged_in_user: Token has been revoked
2024-12-25 21:51:29,841 - [INFO] -  config - (user.py).post(89) - Пользователь wwww вошел в систему!
2024-12-25 21:51:29,905 - [INFO] -  config - (endpoints.py).api_data(195) - Ошибка при получении данных
2024-12-25 21:53:36,800 - [INFO] -  config - (app.py).create_app(9) - Создана БД
2024-12-25 21:53:36,803 - [INFO] -  config - (app.py).create_app(12) - Зарегистрирован (<Blueprint 'timer'>, <Blueprint 'users'>)
2024-12-25 21:53:37,704 - [INFO] -  config - (app.py).create_app(9) - Создана БД
2024-12-25 21:53:37,708 - [INFO] -  config - (app.py).create_app(12) - Зарегистрирован (<Blueprint 'timer'>, <Blueprint 'users'>)
2024-12-25 21:53:45,353 - [ERROR] -  config - (app.py).log_exception(838) - Exception on /api/data/ [GET]
Traceback (most recent call last):
  File "W:\WEB_WORK\Homework\NAA\time_tracker-last\venv\lib\site-packages\sqlalchemy\engine\base.py", line 1967, in _exec_single_context
    self.dialect.do_execute(
  File "W:\WEB_WORK\Homework\NAA\time_tracker-last\venv\lib\site-packages\sqlalchemy\engine\default.py", line 941, in do_execute
    cursor.execute(statement, parameters)
sqlite3.OperationalError: no such column: time_tracker.username

The above exception was the direct cause of the following exception:

Traceback (most recent call last):
  File "W:\WEB_WORK\Homework\NAA\time_tracker-last\venv\lib\site-packages\flask\app.py", line 1473, in wsgi_app
    response = self.full_dispatch_request()
  File "W:\WEB_WORK\Homework\NAA\time_tracker-last\venv\lib\site-packages\flask\app.py", line 882, in full_dispatch_request
    rv = self.handle_user_exception(e)
  File "W:\WEB_WORK\Homework\NAA\time_tracker-last\venv\lib\site-packages\flask\app.py", line 880, in full_dispatch_request
    rv = self.dispatch_request()
  File "W:\WEB_WORK\Homework\NAA\time_tracker-last\venv\lib\site-packages\flask\app.py", line 865, in dispatch_request
    return self.ensure_sync(self.view_functions[rule.endpoint])(**view_args)  # type: ignore[no-any-return]
  File "W:\WEB_WORK\Homework\NAA\time_tracker-last\venv\lib\site-packages\flask_jwt_extended\view_decorators.py", line 170, in decorator
    return current_app.ensure_sync(fn)(*args, **kwargs)
  File "W:\WEB_WORK\Homework\NAA\time_tracker-last\sources\endpoints.py", line 188, in api_data
    total_time = sum_time(data_total_time.all()).strftime('%H:%M:%S')
  File "W:\WEB_WORK\Homework\NAA\time_tracker-last\venv\lib\site-packages\sqlalchemy\orm\query.py", line 2673, in all
    return self._iter().all()  # type: ignore
  File "W:\WEB_WORK\Homework\NAA\time_tracker-last\venv\lib\site-packages\sqlalchemy\orm\query.py", line 2827, in _iter
    result: Union[ScalarResult[_T], Result[_T]] = self.session.execute(
  File "W:\WEB_WORK\Homework\NAA\time_tracker-last\venv\lib\site-packages\sqlalchemy\orm\session.py", line 2362, in execute
    return self._execute_internal(
  File "W:\WEB_WORK\Homework\NAA\time_tracker-last\venv\lib\site-packages\sqlalchemy\orm\session.py", line 2247, in _execute_internal
    result: Result[Any] = compile_state_cls.orm_execute_statement(
  File "W:\WEB_WORK\Homework\NAA\time_tracker-last\venv\lib\site-packages\sqlalchemy\orm\context.py", line 305, in orm_execute_statement
    result = conn.execute(
  File "W:\WEB_WORK\Homework\NAA\time_tracker-last\venv\lib\site-packages\sqlalchemy\engine\base.py", line 1418, in execute
    return meth(
  File "W:\WEB_WORK\Homework\NAA\time_tracker-last\venv\lib\site-packages\sqlalchemy\sql\elements.py", line 515, in _execute_on_connection
    return connection._execute_clauseelement(
  File "W:\WEB_WORK\Homework\NAA\time_tracker-last\venv\lib\site-packages\sqlalchemy\engine\base.py", line 1640, in _execute_clauseelement
    ret = self._execute_context(
  File "W:\WEB_WORK\Homework\NAA\time_tracker-last\venv\lib\site-packages\sqlalchemy\engine\base.py", line 1846, in _execute_context
    return self._exec_single_context(
  File "W:\WEB_WORK\Homework\NAA\time_tracker-last\venv\lib\site-packages\sqlalchemy\engine\base.py", line 1986, in _exec_single_context
    self._handle_dbapi_exception(
  File "W:\WEB_WORK\Homework\NAA\time_tracker-last\venv\lib\site-packages\sqlalchemy\engine\base.py", line 2355, in _handle_dbapi_exception
    raise sqlalchemy_exception.with_traceback(exc_info[2]) from e
  File "W:\WEB_WORK\Homework\NAA\time_tracker-last\venv\lib\site-packages\sqlalchemy\engine\base.py", line 1967, in _exec_single_context
    self.dialect.do_execute(
  File "W:\WEB_WORK\Homework\NAA\time_tracker-last\venv\lib\site-packages\sqlalchemy\engine\default.py", line 941, in do_execute
    cursor.execute(statement, parameters)
sqlalchemy.exc.OperationalError: (sqlite3.OperationalError) no such column: time_tracker.username
[SQL: SELECT time_tracker.id AS time_tracker_id, time_tracker.name_of_work AS time_tracker_name_of_work, time_tracker.date AS time_tracker_date, time_tracker.time AS time_tracker_time, time_tracker.description AS time_tracker_description, time_tracker.username AS time_tracker_username 
FROM time_tracker 
WHERE time_tracker.username = ? AND time_tracker.date = ?]
[parameters: ('wwww', '2024-12-25')]
(Background on this error at: https://sqlalche.me/e/20/e3q8)
2024-12-25 21:55:29,877 - [INFO] -  config - (app.py).create_app(9) - Создана БД
2024-12-25 21:55:29,881 - [INFO] -  config - (app.py).create_app(12) - Зарегистрирован (<Blueprint 'timer'>, <Blueprint 'users'>)
2024-12-25 21:55:30,676 - [INFO] -  config - (app.py).create_app(9) - Создана БД
2024-12-25 21:55:30,680 - [INFO] -  config - (app.py).create_app(12) - Зарегистрирован (<Blueprint 'timer'>, <Blueprint 'users'>)
2024-12-25 21:55:46,695 - [INFO] -  config - (user.py).get(113) - Пользователь wwww вышел из системы!
2024-12-25 21:55:46,707 - [ERROR] -  config - (config.py).load_logged_in_user(83) - Error in load_logged_in_user: Token has been revoked
2024-12-25 21:55:46,748 - [ERROR] -  config - (config.py).load_logged_in_user(83) - Error in load_logged_in_user: Token has been revoked
2024-12-25 21:55:47,733 - [ERROR] -  config - (config.py).load_logged_in_user(83) - Error in load_logged_in_user: Token has been revoked
2024-12-25 21:55:47,759 - [ERROR] -  config - (config.py).load_logged_in_user(83) - Error in load_logged_in_user: Token has been revoked
2024-12-25 21:55:48,084 - [ERROR] -  config - (config.py).load_logged_in_user(83) - Error in load_logged_in_user: Token has been revoked
2024-12-25 21:55:48,123 - [ERROR] -  config - (config.py).load_logged_in_user(83) - Error in load_logged_in_user: Token has been revoked
2024-12-25 21:55:49,415 - [ERROR] -  config - (config.py).load_logged_in_user(83) - Error in load_logged_in_user: Token has been revoked
2024-12-25 21:55:49,456 - [ERROR] -  config - (config.py).load_logged_in_user(83) - Error in load_logged_in_user: Token has been revoked
2024-12-25 21:55:55,806 - [ERROR] -  config - (config.py).load_logged_in_user(83) - Error in load_logged_in_user: Token has been revoked
2024-12-25 21:55:57,652 - [ERROR] -  config - (config.py).load_logged_in_user(83) - Error in load_logged_in_user: Token has been revoked
2024-12-25 21:55:57,691 - [ERROR] -  config - (config.py).load_logged_in_user(83) - Error in load_logged_in_user: Token has been revoked
2024-12-25 21:56:02,193 - [ERROR] -  config - (config.py).load_logged_in_user(83) - Error in load_logged_in_user: Token has been revoked
2024-12-25 21:56:02,301 - [INFO] -  config - (user.py).post(43) - Пользователь wwww зарегистирован!
2024-12-25 21:56:02,312 - [ERROR] -  config - (config.py).load_logged_in_user(83) - Error in load_logged_in_user: Token has been revoked
2024-12-25 21:56:02,404 - [ERROR] -  config - (config.py).load_logged_in_user(83) - Error in load_logged_in_user: Token has been revoked
2024-12-25 21:56:06,849 - [ERROR] -  config - (config.py).load_logged_in_user(83) - Error in load_logged_in_user: Token has been revoked
2024-12-25 21:56:06,945 - [INFO] -  config - (user.py).post(89) - Пользователь wwww вошел в систему!
2024-12-25 21:57:19,646 - [INFO] -  config - (endpoints.py).post(59) - Данные по задаче eee добавлены в БД
2024-12-25 21:57:28,314 - [ERROR] -  config - (endpoints.py).delete_item(166) - Ошибка при удалении задачи: name = eee, date = 2024-12-25
2024-12-25 21:57:46,928 - [ERROR] -  config - (endpoints.py).delete_item(166) - Ошибка при удалении задачи: name = eee, date = 2024-12-25
2024-12-25 22:03:28,120 - [INFO] -  config - (app.py).create_app(9) - Создана БД
2024-12-25 22:03:28,124 - [INFO] -  config - (app.py).create_app(12) - Зарегистрирован (<Blueprint 'timer'>, <Blueprint 'users'>)
2024-12-25 22:03:28,846 - [INFO] -  config - (app.py).create_app(9) - Создана БД
2024-12-25 22:03:28,850 - [INFO] -  config - (app.py).create_app(12) - Зарегистрирован (<Blueprint 'timer'>, <Blueprint 'users'>)
2024-12-25 22:03:59,543 - [ERROR] -  config - (endpoints.py).delete_item(166) - Ошибка при удалении задачи: name = eee, date = 2024-12-25
2024-12-25 22:04:36,333 - [INFO] -  config - (app.py).create_app(9) - Создана БД
2024-12-25 22:04:36,339 - [INFO] -  config - (app.py).create_app(12) - Зарегистрирован (<Blueprint 'timer'>, <Blueprint 'users'>)
2024-12-25 22:04:39,546 - [INFO] -  config - (app.py).create_app(9) - Создана БД
2024-12-25 22:04:39,550 - [INFO] -  config - (app.py).create_app(12) - Зарегистрирован (<Blueprint 'timer'>, <Blueprint 'users'>)
2024-12-25 22:04:44,586 - [INFO] -  config - (app.py).create_app(9) - Создана БД
2024-12-25 22:04:44,590 - [INFO] -  config - (app.py).create_app(12) - Зарегистрирован (<Blueprint 'timer'>, <Blueprint 'users'>)
2024-12-25 22:04:48,683 - [INFO] -  config - (app.py).create_app(9) - Создана БД
2024-12-25 22:04:48,686 - [INFO] -  config - (app.py).create_app(12) - Зарегистрирован (<Blueprint 'timer'>, <Blueprint 'users'>)
2024-12-25 22:04:50,818 - [INFO] -  config - (app.py).create_app(9) - Создана БД
2024-12-25 22:04:50,823 - [INFO] -  config - (app.py).create_app(12) - Зарегистрирован (<Blueprint 'timer'>, <Blueprint 'users'>)
2024-12-25 22:04:52,785 - [INFO] -  config - (app.py).create_app(9) - Создана БД
2024-12-25 22:04:52,788 - [INFO] -  config - (app.py).create_app(12) - Зарегистрирован (<Blueprint 'timer'>, <Blueprint 'users'>)
2024-12-25 22:05:01,959 - [INFO] -  config - (app.py).create_app(9) - Создана БД
2024-12-25 22:05:01,963 - [INFO] -  config - (app.py).create_app(12) - Зарегистрирован (<Blueprint 'timer'>, <Blueprint 'users'>)
2024-12-25 22:05:07,123 - [ERROR] -  config - (endpoints.py).delete_item(168) - Ошибка при удалении задачи: name = eee, date = 2024-12-25
2024-12-25 22:11:34,041 - [ERROR] -  config - (endpoints.py).delete_item(168) - Ошибка при удалении задачи: name = eee, date = 2024-12-25
2024-12-25 22:12:29,756 - [ERROR] -  config - (endpoints.py).delete_item(168) - Ошибка при удалении задачи: name = eee, date = 2024-12-25
2024-12-25 22:12:52,565 - [INFO] -  config - (app.py).create_app(9) - Создана БД
2024-12-25 22:12:52,568 - [INFO] -  config - (app.py).create_app(12) - Зарегистрирован (<Blueprint 'timer'>, <Blueprint 'users'>)
2024-12-25 22:12:54,532 - [INFO] -  config - (app.py).create_app(9) - Создана БД
2024-12-25 22:12:54,536 - [INFO] -  config - (app.py).create_app(12) - Зарегистрирован (<Blueprint 'timer'>, <Blueprint 'users'>)
2024-12-25 22:13:21,215 - [INFO] -  config - (app.py).create_app(9) - Создана БД
2024-12-25 22:13:21,223 - [INFO] -  config - (app.py).create_app(12) - Зарегистрирован (<Blueprint 'timer'>, <Blueprint 'users'>)
2024-12-25 22:13:35,658 - [INFO] -  config - (endpoints.py).delete_item(162) - Удалена задача: name = eee, date = 2024-12-25
2024-12-25 22:14:16,258 - [INFO] -  config - (endpoints.py).post(59) - Данные по задаче eee добавлены в БД
2024-12-25 22:14:21,165 - [INFO] -  config - (endpoints.py).post(59) - Данные по задаче rrr добавлены в БД
2024-12-25 22:14:24,477 - [INFO] -  config - (endpoints.py).post(144) - Измененны данные по задаче eee. Название: eee, Время: 00:00:03, Дата: 2024-12-25.
2024-12-25 22:14:36,007 - [INFO] -  config - (endpoints.py).post(144) - Измененны данные по задаче eee. Название: eee, Время: 00:00:25, Дата: 2024-12-25.
2024-12-25 22:14:43,592 - [INFO] -  config - (endpoints.py).post(144) - Измененны данные по задаче eee. Название: eee, Время: 00:00:25, Дата: 2024-12-20.
2024-12-25 22:14:54,373 - [INFO] -  config - (endpoints.py).post(59) - Данные по задаче fff добавлены в БД
2024-12-25 22:15:26,344 - [INFO] -  config - (endpoints.py).post(59) - Данные по задаче eee добавлены в БД
2024-12-25 22:16:26,628 - [INFO] -  config - (endpoints.py).post(44) - Обновлены данные по задаче fff. Время: 00:00:13
2024-12-25 22:16:55,631 - [INFO] -  config - (endpoints.py).post(44) - Обновлены данные по задаче fff. Время: 00:00:26
2024-12-25 22:16:58,922 - [INFO] -  config - (endpoints.py).delete_item(162) - Удалена задача: name = fff, date = 2024-12-25
2024-12-25 22:17:03,143 - [INFO] -  config - (endpoints.py).delete_item(162) - Удалена задача: name = eee, date = 2024-12-25
2024-12-26 13:22:23,458 - [INFO] -  config - (app.py).create_app(9) - Создана БД
2024-12-26 13:22:23,458 - [INFO] -  config - (app.py).create_app(12) - Зарегистрирован (<Blueprint 'timer'>, <Blueprint 'users'>)
2024-12-26 13:22:24,189 - [INFO] -  config - (app.py).create_app(9) - Создана БД
2024-12-26 13:22:24,189 - [INFO] -  config - (app.py).create_app(12) - Зарегистрирован (<Blueprint 'timer'>, <Blueprint 'users'>)
2024-12-26 13:22:25,786 - [ERROR] -  config - (config.py).load_logged_in_user(83) - Error in load_logged_in_user: Signature has expired
2024-12-26 13:22:25,885 - [ERROR] -  config - (config.py).load_logged_in_user(83) - Error in load_logged_in_user: Signature has expired
2024-12-26 13:22:27,078 - [ERROR] -  config - (config.py).load_logged_in_user(83) - Error in load_logged_in_user: Signature has expired
2024-12-26 13:22:27,119 - [ERROR] -  config - (config.py).load_logged_in_user(83) - Error in load_logged_in_user: Signature has expired
2024-12-26 13:22:29,154 - [ERROR] -  config - (config.py).load_logged_in_user(83) - Error in load_logged_in_user: Signature has expired
2024-12-26 13:22:29,218 - [ERROR] -  config - (config.py).load_logged_in_user(83) - Error in load_logged_in_user: Signature has expired
2024-12-26 13:22:48,211 - [ERROR] -  config - (config.py).load_logged_in_user(83) - Error in load_logged_in_user: Signature has expired
2024-12-26 13:22:48,299 - [INFO] -  config - (user.py).post(89) - Пользователь wwww вошел в систему!
2024-12-26 15:42:19,095 - [INFO] -  config - (app.py).create_app(9) - Создана БД
2024-12-26 15:42:19,099 - [INFO] -  config - (app.py).create_app(12) - Зарегистрирован (<Blueprint 'timer'>, <Blueprint 'users'>)
2024-12-26 15:42:19,795 - [INFO] -  config - (app.py).create_app(9) - Создана БД
2024-12-26 15:42:19,795 - [INFO] -  config - (app.py).create_app(12) - Зарегистрирован (<Blueprint 'timer'>, <Blueprint 'users'>)
2024-12-26 15:52:03,855 - [INFO] -  config - (app.py).create_app(9) - Создана БД
2024-12-26 15:52:03,855 - [INFO] -  config - (app.py).create_app(12) - Зарегистрирован (<Blueprint 'timer'>, <Blueprint 'users'>)
2024-12-26 15:52:24,254 - [INFO] -  config - (app.py).create_app(9) - Создана БД
2024-12-26 15:52:24,258 - [INFO] -  config - (app.py).create_app(12) - Зарегистрирован (<Blueprint 'timer'>, <Blueprint 'users'>)
2024-12-26 15:53:29,066 - [INFO] -  config - (app.py).create_app(9) - Создана БД
2024-12-26 15:53:29,068 - [INFO] -  config - (app.py).create_app(12) - Зарегистрирован (<Blueprint 'timer'>, <Blueprint 'users'>)
2024-12-26 15:53:29,378 - [INFO] -  config - (endpoints.py).api_statistics(208) - Ошибка при получении данных
2024-12-26 15:54:17,370 - [INFO] -  config - (app.py).create_app(9) - Создана БД
2024-12-26 15:54:17,370 - [INFO] -  config - (app.py).create_app(12) - Зарегистрирован (<Blueprint 'timer'>, <Blueprint 'users'>)
2024-12-26 15:54:47,400 - [INFO] -  config - (app.py).create_app(9) - Создана БД
2024-12-26 15:54:47,404 - [INFO] -  config - (app.py).create_app(12) - Зарегистрирован (<Blueprint 'timer'>, <Blueprint 'users'>)
2024-12-26 15:54:48,112 - [INFO] -  config - (app.py).create_app(9) - Создана БД
2024-12-26 15:54:48,116 - [INFO] -  config - (app.py).create_app(12) - Зарегистрирован (<Blueprint 'timer'>, <Blueprint 'users'>)
2024-12-26 15:54:48,361 - [INFO] -  config - (endpoints.py).api_statistics(208) - Ошибка при получении данных
2024-12-26 15:54:50,854 - [INFO] -  config - (endpoints.py).api_statistics(208) - Ошибка при получении данных
2024-12-26 15:54:53,795 - [INFO] -  config - (endpoints.py).api_statistics(208) - Ошибка при получении данных
2024-12-26 15:55:57,709 - [INFO] -  config - (app.py).create_app(9) - Создана БД
2024-12-26 15:55:57,709 - [INFO] -  config - (app.py).create_app(12) - Зарегистрирован (<Blueprint 'timer'>, <Blueprint 'users'>)
2024-12-26 15:55:58,450 - [INFO] -  config - (app.py).create_app(9) - Создана БД
2024-12-26 15:55:58,453 - [INFO] -  config - (app.py).create_app(12) - Зарегистрирован (<Blueprint 'timer'>, <Blueprint 'users'>)
2024-12-26 15:55:59,153 - [INFO] -  config - (endpoints.py).api_statistics(208) - Ошибка при получении данных
2024-12-26 15:56:07,798 - [INFO] -  config - (app.py).create_app(9) - Создана БД
2024-12-26 15:56:07,798 - [INFO] -  config - (app.py).create_app(12) - Зарегистрирован (<Blueprint 'timer'>, <Blueprint 'users'>)
2024-12-26 16:05:18,834 - [INFO] -  config - (endpoints.py).post(59) - Данные по задаче fff добавлены в БД
2024-12-26 16:05:25,661 - [INFO] -  config - (endpoints.py).post(44) - Обновлены данные по задаче fff. Время: 00:00:09
2024-12-26 16:05:35,998 - [INFO] -  config - (endpoints.py).post(59) - Данные по задаче eee добавлены в БД
2024-12-26 16:05:49,358 - [INFO] -  config - (endpoints.py).post(44) - Обновлены данные по задаче eee. Время: 00:00:08
2024-12-26 16:05:56,159 - [INFO] -  config - (endpoints.py).post(59) - Данные по задаче ttt добавлены в БД
2024-12-26 17:23:06,167 - [INFO] -  config - (app.py).create_app(9) - Создана БД
2024-12-26 17:23:06,167 - [INFO] -  config - (app.py).create_app(12) - Зарегистрирован (<Blueprint 'timer'>, <Blueprint 'users'>)
2024-12-26 17:23:06,863 - [INFO] -  config - (app.py).create_app(9) - Создана БД
2024-12-26 17:23:06,863 - [INFO] -  config - (app.py).create_app(12) - Зарегистрирован (<Blueprint 'timer'>, <Blueprint 'users'>)
2024-12-26 18:46:47,866 - [ERROR] -  config - (config.py).load_logged_in_user(83) - Error in load_logged_in_user: Signature has expired
2024-12-26 18:46:49,401 - [ERROR] -  config - (config.py).load_logged_in_user(83) - Error in load_logged_in_user: Signature has expired
2024-12-26 18:47:00,804 - [ERROR] -  config - (config.py).load_logged_in_user(83) - Error in load_logged_in_user: Signature has expired
2024-12-26 18:47:04,473 - [ERROR] -  config - (config.py).load_logged_in_user(83) - Error in load_logged_in_user: Signature has expired
2024-12-26 18:47:04,570 - [ERROR] -  config - (config.py).load_logged_in_user(83) - Error in load_logged_in_user: Signature has expired
2024-12-26 18:47:06,624 - [ERROR] -  config - (config.py).load_logged_in_user(83) - Error in load_logged_in_user: Signature has expired
2024-12-26 18:47:06,711 - [ERROR] -  config - (config.py).load_logged_in_user(83) - Error in load_logged_in_user: Signature has expired
2024-12-26 18:47:16,799 - [ERROR] -  config - (config.py).load_logged_in_user(83) - Error in load_logged_in_user: Signature has expired
2024-12-26 18:47:23,567 - [ERROR] -  config - (config.py).load_logged_in_user(83) - Error in load_logged_in_user: Signature has expired
2024-12-26 18:47:23,661 - [INFO] -  config - (user.py).post(89) - Пользователь wwww вошел в систему!
2024-12-26 19:08:40,424 - [INFO] -  config - (app.py).create_app(9) - Создана БД
2024-12-26 19:08:40,424 - [INFO] -  config - (app.py).create_app(12) - Зарегистрирован (<Blueprint 'timer'>, <Blueprint 'users'>)
2024-12-26 19:08:41,105 - [INFO] -  config - (app.py).create_app(9) - Создана БД
2024-12-26 19:08:41,105 - [INFO] -  config - (app.py).create_app(12) - Зарегистрирован (<Blueprint 'timer'>, <Blueprint 'users'>)
2024-12-26 21:04:28,322 - [INFO] -  config - (endpoints.py).post(59) - Данные по задаче  добавлены в БД
2024-12-26 21:09:28,203 - [INFO] -  config - (endpoints.py).post(59) - Данные по задаче ddd добавлены в БД
2024-12-26 21:10:05,483 - [INFO] -  config - (endpoints.py).post(44) - Обновлены данные по задаче ddd. Время: 00:00:06
2024-12-26 21:12:55,185 - [INFO] -  config - (endpoints.py).post(44) - Обновлены данные по задаче . Время: 00:00:14
2024-12-27 10:29:44,351 - [ERROR] -  config - (config.py).load_logged_in_user(83) - Error in load_logged_in_user: Signature has expired
2024-12-27 10:29:46,259 - [ERROR] -  config - (config.py).load_logged_in_user(83) - Error in load_logged_in_user: Signature has expired
2024-12-27 10:29:50,304 - [ERROR] -  config - (config.py).load_logged_in_user(83) - Error in load_logged_in_user: Signature has expired
2024-12-27 10:29:50,321 - [ERROR] -  config - (config.py).load_logged_in_user(83) - Error in load_logged_in_user: Signature has expired
2024-12-27 10:29:51,908 - [ERROR] -  config - (config.py).load_logged_in_user(83) - Error in load_logged_in_user: Signature has expired
2024-12-27 10:29:51,944 - [ERROR] -  config - (config.py).load_logged_in_user(83) - Error in load_logged_in_user: Signature has expired
2024-12-27 10:29:58,074 - [ERROR] -  config - (config.py).load_logged_in_user(83) - Error in load_logged_in_user: Signature has expired
2024-12-27 10:29:58,166 - [INFO] -  config - (user.py).post(89) - Пользователь wwww вошел в систему!
2024-12-27 11:49:32,002 - [INFO] -  config - (app.py).create_app(9) - Создана БД
2024-12-27 11:49:32,002 - [INFO] -  config - (app.py).create_app(12) - Зарегистрирован (<Blueprint 'timer'>, <Blueprint 'users'>)
2024-12-27 11:49:32,695 - [INFO] -  config - (app.py).create_app(9) - Создана БД
2024-12-27 11:49:32,695 - [INFO] -  config - (app.py).create_app(12) - Зарегистрирован (<Blueprint 'timer'>, <Blueprint 'users'>)
2024-12-28 14:17:56,449 - [INFO] -  config - (app.py).create_app(9) - Создана БД
2024-12-28 14:17:56,449 - [INFO] -  config - (app.py).create_app(12) - Зарегистрирован (<Blueprint 'timer'>, <Blueprint 'users'>)
2024-12-28 14:17:57,237 - [INFO] -  config - (app.py).create_app(9) - Создана БД
2024-12-28 14:17:57,237 - [INFO] -  config - (app.py).create_app(12) - Зарегистрирован (<Blueprint 'timer'>, <Blueprint 'users'>)
2024-12-28 14:18:26,722 - [ERROR] -  config - (config.py).load_logged_in_user(83) - Error in load_logged_in_user: Signature has expired
2024-12-28 14:18:26,826 - [ERROR] -  config - (config.py).load_logged_in_user(83) - Error in load_logged_in_user: Signature has expired
2024-12-28 14:18:32,088 - [ERROR] -  config - (config.py).load_logged_in_user(83) - Error in load_logged_in_user: Signature has expired
2024-12-28 14:18:32,147 - [ERROR] -  config - (config.py).load_logged_in_user(83) - Error in load_logged_in_user: Signature has expired
2024-12-28 14:18:38,185 - [ERROR] -  config - (config.py).load_logged_in_user(83) - Error in load_logged_in_user: Signature has expired
2024-12-28 14:18:38,269 - [INFO] -  config - (user.py).post(89) - Пользователь wwww вошел в систему!
2024-12-28 14:18:59,290 - [INFO] -  config - (endpoints.py).post(59) - Данные по задаче  добавлены в БД
2024-12-28 14:20:43,277 - [INFO] -  config - (endpoints.py).post(44) - Обновлены данные по задаче . Время: 00:00:13
2024-12-28 14:21:11,445 - [INFO] -  config - (endpoints.py).post(44) - Обновлены данные по задаче . Время: 00:00:28
2024-12-28 14:21:19,065 - [INFO] -  config - (endpoints.py).post(44) - Обновлены данные по задаче . Время: 00:00:48
2024-12-28 14:21:35,686 - [INFO] -  config - (endpoints.py).post(44) - Обновлены данные по задаче . Время: 00:01:37
2024-12-28 14:22:38,167 - [INFO] -  config - (endpoints.py).post(59) - Данные по задаче r добавлены в БД
2024-12-28 14:24:42,964 - [INFO] -  config - (endpoints.py).post(59) - Данные по задаче sss добавлены в БД
2024-12-28 14:25:42,441 - [INFO] -  config - (endpoints.py).post(59) - Данные по задаче ddd добавлены в БД
2024-12-28 14:28:02,279 - [INFO] -  config - (endpoints.py).post(44) - Обновлены данные по задаче . Время: 00:03:16
2024-12-28 14:29:02,395 - [INFO] -  config - (endpoints.py).post(44) - Обновлены данные по задаче . Время: 00:06:35
2024-12-28 14:30:34,380 - [INFO] -  config - (endpoints.py).post(44) - Обновлены данные по задаче . Время: 00:13:11
2024-12-28 14:31:00,381 - [INFO] -  config - (endpoints.py).post(44) - Обновлены данные по задаче . Время: 00:26:30
2024-12-28 14:31:09,606 - [INFO] -  config - (endpoints.py).post(44) - Обновлены данные по задаче . Время: 00:39:55
2024-12-28 14:31:16,357 - [INFO] -  config - (endpoints.py).post(44) - Обновлены данные по задаче . Время: 00:53:24
2024-12-28 14:31:23,116 - [INFO] -  config - (endpoints.py).post(44) - Обновлены данные по задаче . Время: 01:06:55
2024-12-28 14:32:56,951 - [INFO] -  config - (endpoints.py).post(44) - Обновлены данные по задаче sss. Время: 00:00:12
2024-12-28 14:33:10,355 - [INFO] -  config - (endpoints.py).post(59) - Данные по задаче eee добавлены в БД
2024-12-28 16:18:43,563 - [ERROR] -  config - (endpoints.py).post(28) - 1 validation error for TimeTrackerSchema
name_of_work
  Value error, Название проекта может содержать только буквы и цифры, а также не превышать 25 символов [type=value_error, input_value='Это дело всей...х продуктов.', input_type=str]
    For further information visit https://errors.pydantic.dev/2.10/v/value_error
2024-12-28 16:19:27,405 - [ERROR] -  config - (endpoints.py).post(28) - 1 validation error for TimeTrackerSchema
name_of_work
  Value error, Название проекта может содержать только буквы и цифры, а также не превышать 25 символов [type=value_error, input_value='Это дело всей...х продуктов.', input_type=str]
    For further information visit https://errors.pydantic.dev/2.10/v/value_error
2024-12-28 16:19:38,922 - [ERROR] -  config - (endpoints.py).post(28) - 1 validation error for TimeTrackerSchema
name_of_work
  Value error, Название проекта может содержать только буквы и цифры, а также не превышать 25 символов [type=value_error, input_value='Это дело всей моей жизни. ', input_type=str]
    For further information visit https://errors.pydantic.dev/2.10/v/value_error
2024-12-28 16:22:40,750 - [ERROR] -  config - (endpoints.py).post(28) - 1 validation error for TimeTrackerSchema
name_of_work
  Value error, Название проекта может содержать только буквы и цифры, а также не превышать 25 символов [type=value_error, input_value='дело норм', input_type=str]
    For further information visit https://errors.pydantic.dev/2.10/v/value_error
2024-12-28 16:23:04,843 - [ERROR] -  config - (endpoints.py).post(28) - 1 validation error for TimeTrackerSchema
name_of_work
  Value error, Название проекта может содержать только буквы и цифры, а также не превышать 25 символов [type=value_error, input_value='norm delo', input_type=str]
    For further information visit https://errors.pydantic.dev/2.10/v/value_error
2024-12-28 16:24:09,497 - [INFO] -  config - (endpoints.py).post(59) - Данные по задаче dddddddddddddddd добавлены в БД
2024-12-28 16:24:21,067 - [ERROR] -  config - (endpoints.py).post(28) - 1 validation error for TimeTrackerSchema
name_of_work
  Value error, Название проекта может содержать только буквы и цифры, а также не превышать 25 символов [type=value_error, input_value='ddd d', input_type=str]
    For further information visit https://errors.pydantic.dev/2.10/v/value_error
2024-12-28 16:27:03,353 - [INFO] -  config - (endpoints.py).post(59) - Данные по задаче eeeeeeeeeeeeeeeeee добавлены в БД
2024-12-28 16:27:28,679 - [INFO] -  config - (endpoints.py).post(59) - Данные по задаче trtrttttttttttteeeuuuu добавлены в БД
2024-12-28 16:34:10,595 - [INFO] -  config - (app.py).create_app(9) - Создана БД
2024-12-28 16:34:10,598 - [INFO] -  config - (app.py).create_app(12) - Зарегистрирован (<Blueprint 'timer'>, <Blueprint 'users'>)
2024-12-28 16:34:11,770 - [INFO] -  config - (app.py).create_app(9) - Создана БД
2024-12-28 16:34:11,773 - [INFO] -  config - (app.py).create_app(12) - Зарегистрирован (<Blueprint 'timer'>, <Blueprint 'users'>)
2024-12-28 16:36:03,776 - [ERROR] -  config - (app.py).log_exception(838) - Exception on / [POST]
Traceback (most recent call last):
  File "W:\WEB_WORK\Homework\NAA\time_tracker-last\venv\lib\site-packages\flask\app.py", line 1473, in wsgi_app
    response = self.full_dispatch_request()
  File "W:\WEB_WORK\Homework\NAA\time_tracker-last\venv\lib\site-packages\flask\app.py", line 882, in full_dispatch_request
    rv = self.handle_user_exception(e)
  File "W:\WEB_WORK\Homework\NAA\time_tracker-last\venv\lib\site-packages\flask\app.py", line 880, in full_dispatch_request
    rv = self.dispatch_request()
  File "W:\WEB_WORK\Homework\NAA\time_tracker-last\venv\lib\site-packages\flask\app.py", line 865, in dispatch_request
    return self.ensure_sync(self.view_functions[rule.endpoint])(**view_args)  # type: ignore[no-any-return]
  File "W:\WEB_WORK\Homework\NAA\time_tracker-last\venv\lib\site-packages\flask\views.py", line 110, in view
    return current_app.ensure_sync(self.dispatch_request)(**kwargs)  # type: ignore[no-any-return]
  File "W:\WEB_WORK\Homework\NAA\time_tracker-last\venv\lib\site-packages\flask\views.py", line 191, in dispatch_request
    return current_app.ensure_sync(meth)(**kwargs)  # type: ignore[no-any-return]
  File "W:\WEB_WORK\Homework\NAA\time_tracker-last\venv\lib\site-packages\flask_jwt_extended\view_decorators.py", line 170, in decorator
    return current_app.ensure_sync(fn)(*args, **kwargs)
  File "W:\WEB_WORK\Homework\NAA\time_tracker-last\sources\endpoints.py", line 26, in post
    data = TimeTrackerSchema(**request.get_json()).dict()
  File "W:\WEB_WORK\Homework\NAA\time_tracker-last\venv\lib\site-packages\pydantic\main.py", line 214, in __init__
    validated_self = self.__pydantic_validator__.validate_python(data, self_instance=self)
  File "W:\WEB_WORK\Homework\NAA\time_tracker-last\venv\lib\site-packages\pydantic\_internal\_decorators_v1.py", line 103, in wrapper2
    return val2(value)
  File "W:\WEB_WORK\Homework\NAA\time_tracker-last\schemas.py", line 15, in validate_name_of_work
    if len(name) > LENGHT_NAME or not re.match("^[a-zA-Z0-9\s\p{Emoji}]*$/u", name):
  File "C:\Users\Всеволод\AppData\Local\Programs\Python\Python310\lib\re.py", line 190, in match
    return _compile(pattern, flags).match(string)
  File "C:\Users\Всеволод\AppData\Local\Programs\Python\Python310\lib\re.py", line 303, in _compile
    p = sre_compile.compile(pattern, flags)
  File "C:\Users\Всеволод\AppData\Local\Programs\Python\Python310\lib\sre_compile.py", line 788, in compile
    p = sre_parse.parse(p, flags)
  File "C:\Users\Всеволод\AppData\Local\Programs\Python\Python310\lib\sre_parse.py", line 955, in parse
    p = _parse_sub(source, state, flags & SRE_FLAG_VERBOSE, 0)
  File "C:\Users\Всеволод\AppData\Local\Programs\Python\Python310\lib\sre_parse.py", line 444, in _parse_sub
    itemsappend(_parse(source, state, verbose, nested + 1,
  File "C:\Users\Всеволод\AppData\Local\Programs\Python\Python310\lib\sre_parse.py", line 555, in _parse
    code1 = _class_escape(source, this)
  File "C:\Users\Всеволод\AppData\Local\Programs\Python\Python310\lib\sre_parse.py", line 350, in _class_escape
    raise source.error('bad escape %s' % escape, len(escape))
re.error: bad escape \p at position 13
2024-12-28 16:36:25,782 - [ERROR] -  config - (app.py).log_exception(838) - Exception on / [POST]
Traceback (most recent call last):
  File "W:\WEB_WORK\Homework\NAA\time_tracker-last\venv\lib\site-packages\flask\app.py", line 1473, in wsgi_app
    response = self.full_dispatch_request()
  File "W:\WEB_WORK\Homework\NAA\time_tracker-last\venv\lib\site-packages\flask\app.py", line 882, in full_dispatch_request
    rv = self.handle_user_exception(e)
  File "W:\WEB_WORK\Homework\NAA\time_tracker-last\venv\lib\site-packages\flask\app.py", line 880, in full_dispatch_request
    rv = self.dispatch_request()
  File "W:\WEB_WORK\Homework\NAA\time_tracker-last\venv\lib\site-packages\flask\app.py", line 865, in dispatch_request
    return self.ensure_sync(self.view_functions[rule.endpoint])(**view_args)  # type: ignore[no-any-return]
  File "W:\WEB_WORK\Homework\NAA\time_tracker-last\venv\lib\site-packages\flask\views.py", line 110, in view
    return current_app.ensure_sync(self.dispatch_request)(**kwargs)  # type: ignore[no-any-return]
  File "W:\WEB_WORK\Homework\NAA\time_tracker-last\venv\lib\site-packages\flask\views.py", line 191, in dispatch_request
    return current_app.ensure_sync(meth)(**kwargs)  # type: ignore[no-any-return]
  File "W:\WEB_WORK\Homework\NAA\time_tracker-last\venv\lib\site-packages\flask_jwt_extended\view_decorators.py", line 170, in decorator
    return current_app.ensure_sync(fn)(*args, **kwargs)
  File "W:\WEB_WORK\Homework\NAA\time_tracker-last\sources\endpoints.py", line 26, in post
    data = TimeTrackerSchema(**request.get_json()).dict()
  File "W:\WEB_WORK\Homework\NAA\time_tracker-last\venv\lib\site-packages\pydantic\main.py", line 214, in __init__
    validated_self = self.__pydantic_validator__.validate_python(data, self_instance=self)
  File "W:\WEB_WORK\Homework\NAA\time_tracker-last\venv\lib\site-packages\pydantic\_internal\_decorators_v1.py", line 103, in wrapper2
    return val2(value)
  File "W:\WEB_WORK\Homework\NAA\time_tracker-last\schemas.py", line 15, in validate_name_of_work
    if len(name) > LENGHT_NAME or not re.match("^[a-zA-Z0-9\s\p{Emoji}]*$/u", name):
  File "C:\Users\Всеволод\AppData\Local\Programs\Python\Python310\lib\re.py", line 190, in match
    return _compile(pattern, flags).match(string)
  File "C:\Users\Всеволод\AppData\Local\Programs\Python\Python310\lib\re.py", line 303, in _compile
    p = sre_compile.compile(pattern, flags)
  File "C:\Users\Всеволод\AppData\Local\Programs\Python\Python310\lib\sre_compile.py", line 788, in compile
    p = sre_parse.parse(p, flags)
  File "C:\Users\Всеволод\AppData\Local\Programs\Python\Python310\lib\sre_parse.py", line 955, in parse
    p = _parse_sub(source, state, flags & SRE_FLAG_VERBOSE, 0)
  File "C:\Users\Всеволод\AppData\Local\Programs\Python\Python310\lib\sre_parse.py", line 444, in _parse_sub
    itemsappend(_parse(source, state, verbose, nested + 1,
  File "C:\Users\Всеволод\AppData\Local\Programs\Python\Python310\lib\sre_parse.py", line 555, in _parse
    code1 = _class_escape(source, this)
  File "C:\Users\Всеволод\AppData\Local\Programs\Python\Python310\lib\sre_parse.py", line 350, in _class_escape
    raise source.error('bad escape %s' % escape, len(escape))
re.error: bad escape \p at position 13
2024-12-28 16:37:04,582 - [ERROR] -  config - (app.py).log_exception(838) - Exception on / [POST]
Traceback (most recent call last):
  File "W:\WEB_WORK\Homework\NAA\time_tracker-last\venv\lib\site-packages\flask\app.py", line 1473, in wsgi_app
    response = self.full_dispatch_request()
  File "W:\WEB_WORK\Homework\NAA\time_tracker-last\venv\lib\site-packages\flask\app.py", line 882, in full_dispatch_request
    rv = self.handle_user_exception(e)
  File "W:\WEB_WORK\Homework\NAA\time_tracker-last\venv\lib\site-packages\flask\app.py", line 880, in full_dispatch_request
    rv = self.dispatch_request()
  File "W:\WEB_WORK\Homework\NAA\time_tracker-last\venv\lib\site-packages\flask\app.py", line 865, in dispatch_request
    return self.ensure_sync(self.view_functions[rule.endpoint])(**view_args)  # type: ignore[no-any-return]
  File "W:\WEB_WORK\Homework\NAA\time_tracker-last\venv\lib\site-packages\flask\views.py", line 110, in view
    return current_app.ensure_sync(self.dispatch_request)(**kwargs)  # type: ignore[no-any-return]
  File "W:\WEB_WORK\Homework\NAA\time_tracker-last\venv\lib\site-packages\flask\views.py", line 191, in dispatch_request
    return current_app.ensure_sync(meth)(**kwargs)  # type: ignore[no-any-return]
  File "W:\WEB_WORK\Homework\NAA\time_tracker-last\venv\lib\site-packages\flask_jwt_extended\view_decorators.py", line 170, in decorator
    return current_app.ensure_sync(fn)(*args, **kwargs)
  File "W:\WEB_WORK\Homework\NAA\time_tracker-last\sources\endpoints.py", line 26, in post
    data = TimeTrackerSchema(**request.get_json()).dict()
  File "W:\WEB_WORK\Homework\NAA\time_tracker-last\venv\lib\site-packages\pydantic\main.py", line 214, in __init__
    validated_self = self.__pydantic_validator__.validate_python(data, self_instance=self)
  File "W:\WEB_WORK\Homework\NAA\time_tracker-last\venv\lib\site-packages\pydantic\_internal\_decorators_v1.py", line 103, in wrapper2
    return val2(value)
  File "W:\WEB_WORK\Homework\NAA\time_tracker-last\schemas.py", line 15, in validate_name_of_work
    if len(name) > LENGHT_NAME or not re.match("^[a-zA-Z0-9\s\p{Emoji}]*$/u", name):
  File "C:\Users\Всеволод\AppData\Local\Programs\Python\Python310\lib\re.py", line 190, in match
    return _compile(pattern, flags).match(string)
  File "C:\Users\Всеволод\AppData\Local\Programs\Python\Python310\lib\re.py", line 303, in _compile
    p = sre_compile.compile(pattern, flags)
  File "C:\Users\Всеволод\AppData\Local\Programs\Python\Python310\lib\sre_compile.py", line 788, in compile
    p = sre_parse.parse(p, flags)
  File "C:\Users\Всеволод\AppData\Local\Programs\Python\Python310\lib\sre_parse.py", line 955, in parse
    p = _parse_sub(source, state, flags & SRE_FLAG_VERBOSE, 0)
  File "C:\Users\Всеволод\AppData\Local\Programs\Python\Python310\lib\sre_parse.py", line 444, in _parse_sub
    itemsappend(_parse(source, state, verbose, nested + 1,
  File "C:\Users\Всеволод\AppData\Local\Programs\Python\Python310\lib\sre_parse.py", line 555, in _parse
    code1 = _class_escape(source, this)
  File "C:\Users\Всеволод\AppData\Local\Programs\Python\Python310\lib\sre_parse.py", line 350, in _class_escape
    raise source.error('bad escape %s' % escape, len(escape))
re.error: bad escape \p at position 13
2024-12-28 16:41:50,584 - [ERROR] -  config - (app.py).log_exception(838) - Exception on / [POST]
Traceback (most recent call last):
  File "W:\WEB_WORK\Homework\NAA\time_tracker-last\venv\lib\site-packages\flask\app.py", line 1473, in wsgi_app
    response = self.full_dispatch_request()
  File "W:\WEB_WORK\Homework\NAA\time_tracker-last\venv\lib\site-packages\flask\app.py", line 882, in full_dispatch_request
    rv = self.handle_user_exception(e)
  File "W:\WEB_WORK\Homework\NAA\time_tracker-last\venv\lib\site-packages\flask\app.py", line 880, in full_dispatch_request
    rv = self.dispatch_request()
  File "W:\WEB_WORK\Homework\NAA\time_tracker-last\venv\lib\site-packages\flask\app.py", line 865, in dispatch_request
    return self.ensure_sync(self.view_functions[rule.endpoint])(**view_args)  # type: ignore[no-any-return]
  File "W:\WEB_WORK\Homework\NAA\time_tracker-last\venv\lib\site-packages\flask\views.py", line 110, in view
    return current_app.ensure_sync(self.dispatch_request)(**kwargs)  # type: ignore[no-any-return]
  File "W:\WEB_WORK\Homework\NAA\time_tracker-last\venv\lib\site-packages\flask\views.py", line 191, in dispatch_request
    return current_app.ensure_sync(meth)(**kwargs)  # type: ignore[no-any-return]
  File "W:\WEB_WORK\Homework\NAA\time_tracker-last\venv\lib\site-packages\flask_jwt_extended\view_decorators.py", line 170, in decorator
    return current_app.ensure_sync(fn)(*args, **kwargs)
  File "W:\WEB_WORK\Homework\NAA\time_tracker-last\sources\endpoints.py", line 26, in post
    data = TimeTrackerSchema(**request.get_json()).dict()
  File "W:\WEB_WORK\Homework\NAA\time_tracker-last\venv\lib\site-packages\pydantic\main.py", line 214, in __init__
    validated_self = self.__pydantic_validator__.validate_python(data, self_instance=self)
  File "W:\WEB_WORK\Homework\NAA\time_tracker-last\venv\lib\site-packages\pydantic\_internal\_decorators_v1.py", line 103, in wrapper2
    return val2(value)
  File "W:\WEB_WORK\Homework\NAA\time_tracker-last\schemas.py", line 15, in validate_name_of_work
    if len(name) > LENGHT_NAME or not re.match("^[a-zA-Z0-9\s\p{Emoji}]*$/u", name):
  File "C:\Users\Всеволод\AppData\Local\Programs\Python\Python310\lib\re.py", line 190, in match
    return _compile(pattern, flags).match(string)
  File "C:\Users\Всеволод\AppData\Local\Programs\Python\Python310\lib\re.py", line 303, in _compile
    p = sre_compile.compile(pattern, flags)
  File "C:\Users\Всеволод\AppData\Local\Programs\Python\Python310\lib\sre_compile.py", line 788, in compile
    p = sre_parse.parse(p, flags)
  File "C:\Users\Всеволод\AppData\Local\Programs\Python\Python310\lib\sre_parse.py", line 955, in parse
    p = _parse_sub(source, state, flags & SRE_FLAG_VERBOSE, 0)
  File "C:\Users\Всеволод\AppData\Local\Programs\Python\Python310\lib\sre_parse.py", line 444, in _parse_sub
    itemsappend(_parse(source, state, verbose, nested + 1,
  File "C:\Users\Всеволод\AppData\Local\Programs\Python\Python310\lib\sre_parse.py", line 555, in _parse
    code1 = _class_escape(source, this)
  File "C:\Users\Всеволод\AppData\Local\Programs\Python\Python310\lib\sre_parse.py", line 350, in _class_escape
    raise source.error('bad escape %s' % escape, len(escape))
re.error: bad escape \p at position 13
2024-12-28 16:42:55,808 - [INFO] -  config - (app.py).create_app(9) - Создана БД
2024-12-28 16:42:55,808 - [INFO] -  config - (app.py).create_app(12) - Зарегистрирован (<Blueprint 'timer'>, <Blueprint 'users'>)
2024-12-28 16:42:59,751 - [INFO] -  config - (app.py).create_app(9) - Создана БД
2024-12-28 16:42:59,751 - [INFO] -  config - (app.py).create_app(12) - Зарегистрирован (<Blueprint 'timer'>, <Blueprint 'users'>)
2024-12-28 16:43:03,617 - [INFO] -  config - (app.py).create_app(9) - Создана БД
2024-12-28 16:43:03,617 - [INFO] -  config - (app.py).create_app(12) - Зарегистрирован (<Blueprint 'timer'>, <Blueprint 'users'>)
2024-12-28 16:43:22,149 - [ERROR] -  config - (app.py).log_exception(838) - Exception on / [POST]
Traceback (most recent call last):
  File "W:\WEB_WORK\Homework\NAA\time_tracker-last\venv\lib\site-packages\flask\app.py", line 1473, in wsgi_app
    response = self.full_dispatch_request()
  File "W:\WEB_WORK\Homework\NAA\time_tracker-last\venv\lib\site-packages\flask\app.py", line 882, in full_dispatch_request
    rv = self.handle_user_exception(e)
  File "W:\WEB_WORK\Homework\NAA\time_tracker-last\venv\lib\site-packages\flask\app.py", line 880, in full_dispatch_request
    rv = self.dispatch_request()
  File "W:\WEB_WORK\Homework\NAA\time_tracker-last\venv\lib\site-packages\flask\app.py", line 865, in dispatch_request
    return self.ensure_sync(self.view_functions[rule.endpoint])(**view_args)  # type: ignore[no-any-return]
  File "W:\WEB_WORK\Homework\NAA\time_tracker-last\venv\lib\site-packages\flask\views.py", line 110, in view
    return current_app.ensure_sync(self.dispatch_request)(**kwargs)  # type: ignore[no-any-return]
  File "W:\WEB_WORK\Homework\NAA\time_tracker-last\venv\lib\site-packages\flask\views.py", line 191, in dispatch_request
    return current_app.ensure_sync(meth)(**kwargs)  # type: ignore[no-any-return]
  File "W:\WEB_WORK\Homework\NAA\time_tracker-last\venv\lib\site-packages\flask_jwt_extended\view_decorators.py", line 170, in decorator
    return current_app.ensure_sync(fn)(*args, **kwargs)
  File "W:\WEB_WORK\Homework\NAA\time_tracker-last\sources\endpoints.py", line 26, in post
    data = TimeTrackerSchema(**request.get_json()).dict()
  File "W:\WEB_WORK\Homework\NAA\time_tracker-last\venv\lib\site-packages\pydantic\main.py", line 214, in __init__
    validated_self = self.__pydantic_validator__.validate_python(data, self_instance=self)
  File "W:\WEB_WORK\Homework\NAA\time_tracker-last\venv\lib\site-packages\pydantic\_internal\_decorators_v1.py", line 103, in wrapper2
    return val2(value)
  File "W:\WEB_WORK\Homework\NAA\time_tracker-last\schemas.py", line 15, in validate_name_of_work
    if len(name) > LENGHT_NAME or not re.match("^[a-zA-Z0-9\s\p{Emoji}]*$/u", name):
  File "C:\Users\Всеволод\AppData\Local\Programs\Python\Python310\lib\re.py", line 190, in match
    return _compile(pattern, flags).match(string)
  File "C:\Users\Всеволод\AppData\Local\Programs\Python\Python310\lib\re.py", line 303, in _compile
    p = sre_compile.compile(pattern, flags)
  File "C:\Users\Всеволод\AppData\Local\Programs\Python\Python310\lib\sre_compile.py", line 788, in compile
    p = sre_parse.parse(p, flags)
  File "C:\Users\Всеволод\AppData\Local\Programs\Python\Python310\lib\sre_parse.py", line 955, in parse
    p = _parse_sub(source, state, flags & SRE_FLAG_VERBOSE, 0)
  File "C:\Users\Всеволод\AppData\Local\Programs\Python\Python310\lib\sre_parse.py", line 444, in _parse_sub
    itemsappend(_parse(source, state, verbose, nested + 1,
  File "C:\Users\Всеволод\AppData\Local\Programs\Python\Python310\lib\sre_parse.py", line 555, in _parse
    code1 = _class_escape(source, this)
  File "C:\Users\Всеволод\AppData\Local\Programs\Python\Python310\lib\sre_parse.py", line 350, in _class_escape
    raise source.error('bad escape %s' % escape, len(escape))
re.error: bad escape \p at position 13
2024-12-28 16:43:46,625 - [INFO] -  config - (app.py).create_app(9) - Создана БД
2024-12-28 16:43:46,625 - [INFO] -  config - (app.py).create_app(12) - Зарегистрирован (<Blueprint 'timer'>, <Blueprint 'users'>)
2024-12-28 16:43:47,310 - [INFO] -  config - (app.py).create_app(9) - Создана БД
2024-12-28 16:43:47,313 - [INFO] -  config - (app.py).create_app(12) - Зарегистрирован (<Blueprint 'timer'>, <Blueprint 'users'>)
2024-12-28 16:44:02,852 - [ERROR] -  config - (endpoints.py).post(28) - 1 validation error for TimeTrackerSchema
name_of_work
  Value error, Название проекта может содержать только буквы и цифры, а также не превышать 25 символов [type=value_error, input_value='ккк ккк', input_type=str]
    For further information visit https://errors.pydantic.dev/2.10/v/value_error
2024-12-28 16:45:16,738 - [INFO] -  config - (app.py).create_app(9) - Создана БД
2024-12-28 16:45:16,738 - [INFO] -  config - (app.py).create_app(12) - Зарегистрирован (<Blueprint 'timer'>, <Blueprint 'users'>)
2024-12-28 16:45:25,807 - [ERROR] -  config - (endpoints.py).post(28) - 1 validation error for TimeTrackerSchema
name_of_work
  Value error, Название проекта может содержать только буквы и цифры, а также не превышать 25 символов [type=value_error, input_value='ddd ee ', input_type=str]
    For further information visit https://errors.pydantic.dev/2.10/v/value_error
2024-12-28 16:45:32,799 - [ERROR] -  config - (endpoints.py).post(28) - 1 validation error for TimeTrackerSchema
name_of_work
  Value error, Название проекта может содержать только буквы и цифры, а также не превышать 25 символов [type=value_error, input_value='ввв', input_type=str]
    For further information visit https://errors.pydantic.dev/2.10/v/value_error
2024-12-28 16:45:52,138 - [INFO] -  config - (app.py).create_app(9) - Создана БД
2024-12-28 16:45:52,141 - [INFO] -  config - (app.py).create_app(12) - Зарегистрирован (<Blueprint 'timer'>, <Blueprint 'users'>)
2024-12-28 16:45:54,105 - [INFO] -  config - (app.py).create_app(9) - Создана БД
2024-12-28 16:45:54,105 - [INFO] -  config - (app.py).create_app(12) - Зарегистрирован (<Blueprint 'timer'>, <Blueprint 'users'>)
2024-12-28 16:45:57,162 - [ERROR] -  config - (endpoints.py).post(28) - 1 validation error for TimeTrackerSchema
name_of_work
  Value error, Название проекта может содержать только буквы и цифры, а также не превышать 25 символов [type=value_error, input_value='ввв', input_type=str]
    For further information visit https://errors.pydantic.dev/2.10/v/value_error
2024-12-28 16:46:06,111 - [INFO] -  config - (app.py).create_app(9) - Создана БД
2024-12-28 16:46:06,111 - [INFO] -  config - (app.py).create_app(12) - Зарегистрирован (<Blueprint 'timer'>, <Blueprint 'users'>)
2024-12-28 16:46:06,805 - [INFO] -  config - (app.py).create_app(9) - Создана БД
2024-12-28 16:46:06,805 - [INFO] -  config - (app.py).create_app(12) - Зарегистрирован (<Blueprint 'timer'>, <Blueprint 'users'>)
2024-12-28 16:46:13,599 - [ERROR] -  config - (endpoints.py).post(28) - 1 validation error for TimeTrackerSchema
name_of_work
  Value error, Название проекта может содержать только буквы и цифры, а также не превышать 25 символов [type=value_error, input_value='ввв', input_type=str]
    For further information visit https://errors.pydantic.dev/2.10/v/value_error
2024-12-28 16:46:20,973 - [INFO] -  config - (app.py).create_app(9) - Создана БД
2024-12-28 16:46:20,973 - [INFO] -  config - (app.py).create_app(12) - Зарегистрирован (<Blueprint 'timer'>, <Blueprint 'users'>)
2024-12-28 16:46:47,352 - [ERROR] -  config - (endpoints.py).post(28) - 1 validation error for TimeTrackerSchema
name_of_work
  Value error, Название проекта может содержать только буквы и цифры, а также не превышать 25 символов [type=value_error, input_value='ввв', input_type=str]
    For further information visit https://errors.pydantic.dev/2.10/v/value_error
2024-12-28 16:47:04,213 - [INFO] -  config - (endpoints.py).post(44) - Обновлены данные по задаче ddd. Время: 00:00:07
2024-12-28 16:50:49,949 - [INFO] -  config - (app.py).create_app(9) - Создана БД
2024-12-28 16:50:49,965 - [INFO] -  config - (app.py).create_app(12) - Зарегистрирован (<Blueprint 'timer'>, <Blueprint 'users'>)
2024-12-28 16:51:04,698 - [INFO] -  config - (endpoints.py).post(59) - Данные по задаче ааа ааа добавлены в БД
2024-12-28 16:51:25,263 - [ERROR] -  config - (endpoints.py).post(28) - 1 validation error for TimeTrackerSchema
name_of_work
  Value error, Название проекта может содержать только буквы и цифры, а также не превышать 25 символов [type=value_error, input_value='Дело всей моей жизни!!!', input_type=str]
    For further information visit https://errors.pydantic.dev/2.10/v/value_error
2024-12-28 16:51:46,256 - [INFO] -  config - (endpoints.py).post(59) - Данные по задаче Дело всей моей жизни добавлены в БД
2024-12-28 16:52:11,033 - [INFO] -  config - (endpoints.py).post(59) - Данные по задаче My work добавлены в БД
2024-12-28 16:55:26,739 - [INFO] -  config - (app.py).create_app(9) - Создана БД
2024-12-28 16:55:26,739 - [INFO] -  config - (app.py).create_app(12) - Зарегистрирован (<Blueprint 'timer'>, <Blueprint 'users'>)
2024-12-28 16:56:29,345 - [ERROR] -  config - (endpoints.py).post(28) - 1 validation error for TimeTrackerSchema
name_of_work
  Value error, Название проекта может содержать только буквы и цифры, а также не превышать 25 символов [type=value_error, input_value='Таймер дело в...жизни 😊😊😊', input_type=str]
    For further information visit https://errors.pydantic.dev/2.10/v/value_error
2024-12-28 16:56:40,585 - [ERROR] -  config - (endpoints.py).post(28) - 1 validation error for TimeTrackerSchema
name_of_work
  Value error, Название проекта может содержать только буквы и цифры, а также не превышать 25 символов [type=value_error, input_value='Таймер дело в...й моей жизни ', input_type=str]
    For further information visit https://errors.pydantic.dev/2.10/v/value_error
2024-12-28 16:57:21,897 - [ERROR] -  config - (endpoints.py).post(28) - 1 validation error for TimeTrackerSchema
name_of_work
  Value error, Название проекта может содержать только буквы и цифры, а также не превышать 25 символов [type=value_error, input_value='Таймер дело в... моей жизни =)', input_type=str]
    For further information visit https://errors.pydantic.dev/2.10/v/value_error
2024-12-28 16:58:11,054 - [INFO] -  config - (app.py).create_app(9) - Создана БД
2024-12-28 16:58:11,054 - [INFO] -  config - (app.py).create_app(12) - Зарегистрирован (<Blueprint 'timer'>, <Blueprint 'users'>)
2024-12-28 16:58:11,954 - [INFO] -  config - (app.py).create_app(9) - Создана БД
2024-12-28 16:58:11,954 - [INFO] -  config - (app.py).create_app(12) - Зарегистрирован (<Blueprint 'timer'>, <Blueprint 'users'>)
2024-12-28 16:58:49,821 - [ERROR] -  config - (app.py).log_exception(838) - Exception on / [POST]
Traceback (most recent call last):
  File "W:\WEB_WORK\Homework\NAA\time_tracker-last\venv\lib\site-packages\flask\app.py", line 1473, in wsgi_app
    response = self.full_dispatch_request()
  File "W:\WEB_WORK\Homework\NAA\time_tracker-last\venv\lib\site-packages\flask\app.py", line 882, in full_dispatch_request
    rv = self.handle_user_exception(e)
  File "W:\WEB_WORK\Homework\NAA\time_tracker-last\venv\lib\site-packages\flask\app.py", line 880, in full_dispatch_request
    rv = self.dispatch_request()
  File "W:\WEB_WORK\Homework\NAA\time_tracker-last\venv\lib\site-packages\flask\app.py", line 865, in dispatch_request
    return self.ensure_sync(self.view_functions[rule.endpoint])(**view_args)  # type: ignore[no-any-return]
  File "W:\WEB_WORK\Homework\NAA\time_tracker-last\venv\lib\site-packages\flask\views.py", line 110, in view
    return current_app.ensure_sync(self.dispatch_request)(**kwargs)  # type: ignore[no-any-return]
  File "W:\WEB_WORK\Homework\NAA\time_tracker-last\venv\lib\site-packages\flask\views.py", line 191, in dispatch_request
    return current_app.ensure_sync(meth)(**kwargs)  # type: ignore[no-any-return]
  File "W:\WEB_WORK\Homework\NAA\time_tracker-last\venv\lib\site-packages\flask_jwt_extended\view_decorators.py", line 170, in decorator
    return current_app.ensure_sync(fn)(*args, **kwargs)
  File "W:\WEB_WORK\Homework\NAA\time_tracker-last\sources\endpoints.py", line 26, in post
    data = TimeTrackerSchema(**request.get_json()).dict()
  File "W:\WEB_WORK\Homework\NAA\time_tracker-last\venv\lib\site-packages\pydantic\main.py", line 214, in __init__
    validated_self = self.__pydantic_validator__.validate_python(data, self_instance=self)
  File "W:\WEB_WORK\Homework\NAA\time_tracker-last\venv\lib\site-packages\pydantic\_internal\_decorators_v1.py", line 103, in wrapper2
    return val2(value)
  File "W:\WEB_WORK\Homework\NAA\time_tracker-last\schemas.py", line 15, in validate_name_of_work
    if len(name) > LENGHT_NAME or not re.match("^[a-zA-Z0-9\sА-Яа-яЁё\p{Emoji}]*$", name):
  File "C:\Users\Всеволод\AppData\Local\Programs\Python\Python310\lib\re.py", line 190, in match
    return _compile(pattern, flags).match(string)
  File "C:\Users\Всеволод\AppData\Local\Programs\Python\Python310\lib\re.py", line 303, in _compile
    p = sre_compile.compile(pattern, flags)
  File "C:\Users\Всеволод\AppData\Local\Programs\Python\Python310\lib\sre_compile.py", line 788, in compile
    p = sre_parse.parse(p, flags)
  File "C:\Users\Всеволод\AppData\Local\Programs\Python\Python310\lib\sre_parse.py", line 955, in parse
    p = _parse_sub(source, state, flags & SRE_FLAG_VERBOSE, 0)
  File "C:\Users\Всеволод\AppData\Local\Programs\Python\Python310\lib\sre_parse.py", line 444, in _parse_sub
    itemsappend(_parse(source, state, verbose, nested + 1,
  File "C:\Users\Всеволод\AppData\Local\Programs\Python\Python310\lib\sre_parse.py", line 555, in _parse
    code1 = _class_escape(source, this)
  File "C:\Users\Всеволод\AppData\Local\Programs\Python\Python310\lib\sre_parse.py", line 350, in _class_escape
    raise source.error('bad escape %s' % escape, len(escape))
re.error: bad escape \p at position 21
2024-12-28 16:59:46,540 - [INFO] -  config - (app.py).create_app(9) - Создана БД
2024-12-28 16:59:46,540 - [INFO] -  config - (app.py).create_app(12) - Зарегистрирован (<Blueprint 'timer'>, <Blueprint 'users'>)
2024-12-28 17:00:11,417 - [INFO] -  config - (app.py).create_app(9) - Создана БД
2024-12-28 17:00:11,434 - [INFO] -  config - (app.py).create_app(12) - Зарегистрирован (<Blueprint 'timer'>, <Blueprint 'users'>)
2024-12-28 17:00:12,351 - [INFO] -  config - (app.py).create_app(9) - Создана БД
2024-12-28 17:00:12,354 - [INFO] -  config - (app.py).create_app(12) - Зарегистрирован (<Blueprint 'timer'>, <Blueprint 'users'>)
2024-12-28 17:00:43,080 - [INFO] -  config - (endpoints.py).post(59) - Данные по задаче Лучшее дело в Мире World добавлены в БД
2024-12-28 17:00:58,499 - [ERROR] -  config - (endpoints.py).post(28) - 1 validation error for TimeTrackerSchema
name_of_work
  Value error, Название проекта может содержать только буквы и цифры, а также не превышать 25 символов [type=value_error, input_value='!!!', input_type=str]
    For further information visit https://errors.pydantic.dev/2.10/v/value_error
2024-12-28 17:01:25,387 - [INFO] -  config - (app.py).create_app(9) - Создана БД
2024-12-28 17:01:25,407 - [INFO] -  config - (app.py).create_app(12) - Зарегистрирован (<Blueprint 'timer'>, <Blueprint 'users'>)
2024-12-28 17:01:26,110 - [INFO] -  config - (app.py).create_app(9) - Создана БД
2024-12-28 17:01:26,110 - [INFO] -  config - (app.py).create_app(12) - Зарегистрирован (<Blueprint 'timer'>, <Blueprint 'users'>)
2024-12-28 17:18:45,962 - [INFO] -  config - (endpoints.py).post(144) - Измененны данные по задаче My work. Название: My work, Время: 01:00:02, Дата: 2024-12-28.
2024-12-28 17:19:06,829 - [INFO] -  config - (endpoints.py).post(144) - Измененны данные по задаче Дело всей моей жизни. Название: Дело всей моей жизни, Время: 00:45:02, Дата: 2024-12-28.
2024-12-28 17:19:46,715 - [INFO] -  config - (endpoints.py).post(144) - Измененны данные по задаче Лучшее дело в Мире World. Название: Лучшее дело в Мире World, Время: 02:00:03, Дата: 2024-12-28.
2024-12-28 17:21:22,593 - [INFO] -  config - (endpoints.py).post(144) - Измененны данные по задаче r. Название: r, Время: 00:25:05, Дата: 2024-12-28.
2024-12-28 17:26:06,579 - [INFO] -  config - (endpoints.py).post(59) - Данные по задаче Это дело состоит из 25смв добавлены в БД
2024-12-29 10:40:59,288 - [ERROR] -  config - (config.py).load_logged_in_user(83) - Error in load_logged_in_user: Signature has expired
2024-12-29 10:41:02,763 - [ERROR] -  config - (config.py).load_logged_in_user(83) - Error in load_logged_in_user: Signature has expired
2024-12-29 10:41:07,080 - [ERROR] -  config - (config.py).load_logged_in_user(83) - Error in load_logged_in_user: Signature has expired
2024-12-29 10:41:07,105 - [ERROR] -  config - (config.py).load_logged_in_user(83) - Error in load_logged_in_user: Signature has expired
2024-12-29 10:41:13,537 - [ERROR] -  config - (config.py).load_logged_in_user(83) - Error in load_logged_in_user: Signature has expired
2024-12-29 10:41:13,680 - [ERROR] -  config - (config.py).load_logged_in_user(83) - Error in load_logged_in_user: Signature has expired
2024-12-29 10:41:19,358 - [ERROR] -  config - (config.py).load_logged_in_user(83) - Error in load_logged_in_user: Signature has expired
2024-12-29 10:41:19,466 - [INFO] -  config - (user.py).post(89) - Пользователь wwww вошел в систему!
2024-12-29 15:11:59,820 - [INFO] -  config - (endpoints.py).post(59) - Данные по задаче My work добавлены в БД
2024-12-29 15:12:13,074 - [INFO] -  config - (endpoints.py).post(144) - Измененны данные по задаче My work. Название: My work, Время: 01:00:04, Дата: 2024-12-29.
2024-12-29 15:13:08,330 - [INFO] -  config - (endpoints.py).post(59) - Данные по задаче Лучшее дело в Мире World добавлены в БД
2024-12-29 15:13:42,244 - [INFO] -  config - (endpoints.py).post(144) - Измененны данные по задаче Лучшее дело в Мире World. Название: Лучшее дело в Мире World, Время: 00:01:03, Дата: 2024-12-27.
2024-12-29 15:16:21,885 - [INFO] -  config - (endpoints.py).post(59) - Данные по задаче ddd добавлены в БД
2024-12-29 15:16:36,847 - [INFO] -  config - (endpoints.py).delete_item(162) - Удалена задача: name = ddd, date = 2024-12-29
2024-12-29 15:17:32,622 - [INFO] -  config - (endpoints.py).post(59) - Данные по задаче ddd добавлены в БД
2024-12-29 15:17:38,396 - [INFO] -  config - (endpoints.py).delete_item(162) - Удалена задача: name = ddd, date = 2024-12-29
2024-12-29 16:46:24,384 - [INFO] -  config - (app.py).create_app(9) - Создана БД
2024-12-29 16:46:24,389 - [INFO] -  config - (app.py).create_app(12) - Зарегистрирован (<Blueprint 'timer'>, <Blueprint 'users'>)
2024-12-29 16:46:25,212 - [INFO] -  config - (app.py).create_app(9) - Создана БД
2024-12-29 16:46:25,215 - [INFO] -  config - (app.py).create_app(12) - Зарегистрирован (<Blueprint 'timer'>, <Blueprint 'users'>)
2024-12-29 16:59:14,404 - [INFO] -  config - (endpoints.py).delete_item(162) - Удалена задача: name = My work, date = 2024-12-29
2024-12-29 16:59:32,206 - [INFO] -  config - (endpoints.py).post(59) - Данные по задаче fff добавлены в БД
2024-12-29 17:01:36,167 - [INFO] -  config - (endpoints.py).post(59) - Данные по задаче ddd добавлены в БД
2024-12-29 17:01:39,077 - [INFO] -  config - (endpoints.py).delete_item(162) - Удалена задача: name = ddd, date = 2024-12-29
2024-12-29 17:01:40,938 - [INFO] -  config - (endpoints.py).delete_item(162) - Удалена задача: name = fff, date = 2024-12-29
2024-12-29 17:01:48,485 - [INFO] -  config - (endpoints.py).post(59) - Данные по задаче ddd добавлены в БД
2024-12-29 17:01:52,904 - [INFO] -  config - (endpoints.py).delete_item(162) - Удалена задача: name = ddd, date = 2024-12-29
2024-12-29 17:19:48,921 - [INFO] -  config - (endpoints.py).delete_item(162) - Удалена задача: name = ddd, date = 2024-12-28
2024-12-30 17:40:14,758 - [INFO] -  config - (app.py).create_app(9) - Создана БД
2024-12-30 17:40:14,763 - [INFO] -  config - (app.py).create_app(12) - Зарегистрирован (<Blueprint 'timer'>, <Blueprint 'users'>)
2024-12-30 17:40:15,480 - [INFO] -  config - (app.py).create_app(9) - Создана БД
2024-12-30 17:40:15,480 - [INFO] -  config - (app.py).create_app(12) - Зарегистрирован (<Blueprint 'timer'>, <Blueprint 'users'>)
2024-12-30 17:40:57,423 - [ERROR] -  config - (config.py).load_logged_in_user(83) - Error in load_logged_in_user: Signature has expired
2024-12-30 17:40:57,570 - [ERROR] -  config - (config.py).load_logged_in_user(83) - Error in load_logged_in_user: Signature has expired
2024-12-30 17:40:59,579 - [ERROR] -  config - (config.py).load_logged_in_user(83) - Error in load_logged_in_user: Signature has expired
2024-12-30 17:40:59,657 - [ERROR] -  config - (config.py).load_logged_in_user(83) - Error in load_logged_in_user: Signature has expired
2024-12-30 17:41:05,629 - [ERROR] -  config - (config.py).load_logged_in_user(83) - Error in load_logged_in_user: Signature has expired
2024-12-30 17:41:05,712 - [INFO] -  config - (user.py).post(89) - Пользователь wwww вошел в систему!
2024-12-30 18:33:23,156 - [INFO] -  config - (app.py).create_app(9) - Создана БД
2024-12-30 18:33:23,172 - [INFO] -  config - (app.py).create_app(12) - Зарегистрирован (<Blueprint 'timer'>, <Blueprint 'users'>)
2024-12-30 18:33:23,845 - [INFO] -  config - (app.py).create_app(9) - Создана БД
2024-12-30 18:33:23,845 - [INFO] -  config - (app.py).create_app(12) - Зарегистрирован (<Blueprint 'timer'>, <Blueprint 'users'>)
2024-12-30 18:38:35,329 - [INFO] -  config - (endpoints.py).delete_item(162) - Удалена задача: name = eee, date = 2024-12-28
2024-12-30 19:06:57,118 - [INFO] -  config - (endpoints.py).delete_item(162) - Удалена задача: name = My work, date = 2024-12-28
2024-12-30 21:10:27,871 - [INFO] -  config - (endpoints.py).delete_item(162) - Удалена задача: name = dddddddddddddddd, date = 2024-12-28
2024-12-30 21:10:47,920 - [INFO] -  config - (endpoints.py).delete_item(162) - Удалена задача: name = sss, date = 2024-12-28
2024-12-30 21:14:47,949 - [INFO] -  config - (endpoints.py).delete_item(162) - Удалена задача: name = r, date = 2024-12-28
2024-12-30 21:15:27,836 - [INFO] -  config - (endpoints.py).delete_item(162) - Удалена задача: name = ааа ааа, date = 2024-12-28
2024-12-30 21:25:03,091 - [INFO] -  config - (endpoints.py).delete_item(162) - Удалена задача: name = eee, date = 2024-12-26
2024-12-30 22:57:44,710 - [ERROR] -  config - (config.py).load_logged_in_user(83) - Error in load_logged_in_user: Signature has expired
2024-12-30 22:57:44,734 - [ERROR] -  config - (config.py).load_logged_in_user(83) - Error in load_logged_in_user: Signature has expired
2024-12-30 22:57:49,824 - [ERROR] -  config - (config.py).load_logged_in_user(83) - Error in load_logged_in_user: Signature has expired
2024-12-30 22:57:49,899 - [ERROR] -  config - (config.py).load_logged_in_user(83) - Error in load_logged_in_user: Signature has expired
2024-12-30 22:57:57,299 - [ERROR] -  config - (config.py).load_logged_in_user(83) - Error in load_logged_in_user: Signature has expired
2024-12-30 22:57:57,399 - [INFO] -  config - (user.py).post(89) - Пользователь wwww вошел в систему!
2024-12-30 22:58:04,056 - [INFO] -  config - (endpoints.py).delete_item(162) - Удалена задача: name = eeeeeeeeeeeeeeeeee, date = 2024-12-28
2024-12-30 22:58:40,033 - [INFO] -  config - (endpoints.py).delete_item(162) - Удалена задача: name = trtrttttttttttteeeuuuu, date = 2024-12-28
2025-01-02 17:39:36,934 - [INFO] -  config - (app.py).create_app(9) - Создана БД
2025-01-02 17:39:36,934 - [INFO] -  config - (app.py).create_app(12) - Зарегистрирован (<Blueprint 'timer'>, <Blueprint 'users'>)
2025-01-02 17:39:37,680 - [INFO] -  config - (app.py).create_app(9) - Создана БД
2025-01-02 17:39:37,680 - [INFO] -  config - (app.py).create_app(12) - Зарегистрирован (<Blueprint 'timer'>, <Blueprint 'users'>)
2025-01-02 17:39:53,682 - [ERROR] -  config - (config.py).load_logged_in_user(83) - Error in load_logged_in_user: Signature has expired
2025-01-02 17:39:53,810 - [ERROR] -  config - (config.py).load_logged_in_user(83) - Error in load_logged_in_user: Signature has expired
2025-01-02 17:39:55,214 - [ERROR] -  config - (config.py).load_logged_in_user(83) - Error in load_logged_in_user: Signature has expired
2025-01-02 17:39:55,296 - [ERROR] -  config - (config.py).load_logged_in_user(83) - Error in load_logged_in_user: Signature has expired
2025-01-02 17:40:01,510 - [ERROR] -  config - (config.py).load_logged_in_user(83) - Error in load_logged_in_user: Signature has expired
2025-01-02 17:40:01,610 - [INFO] -  config - (user.py).post(89) - Пользователь wwww вошел в систему!
2025-01-02 17:40:32,162 - [INFO] -  config - (endpoints.py).post(59) - Данные по задаче new year добавлены в БД
2025-01-02 17:51:04,566 - [INFO] -  config - (endpoints.py).post(59) - Данные по задаче пуск1 добавлены в БД
2025-01-02 17:57:52,225 - [INFO] -  config - (endpoints.py).post(59) - Данные по задаче fff добавлены в БД
2025-01-02 17:58:20,694 - [INFO] -  config - (endpoints.py).post(59) - Данные по задаче rrr добавлены в БД
2025-01-02 18:39:40,374 - [INFO] -  config - (endpoints.py).post(44) - Обновлены данные по задаче fff. Время: 00:00:12
2025-01-02 18:40:41,905 - [INFO] -  config - (endpoints.py).post(44) - Обновлены данные по задаче fff. Время: 00:00:26
2025-01-02 19:46:11,478 - [INFO] -  config - (endpoints.py).post(44) - Обновлены данные по задаче fff. Время: 00:00:53
2025-01-03 00:00:17,587 - [ERROR] -  config - (config.py).load_logged_in_user(83) - Error in load_logged_in_user: Signature has expired
2025-01-02 21:10:34,381 - [INFO] -  config - (app.py).create_app(9) - Создана БД
2025-01-02 21:10:34,381 - [INFO] -  config - (app.py).create_app(12) - Зарегистрирован (<Blueprint 'timer'>, <Blueprint 'users'>)
2025-01-02 21:10:35,081 - [INFO] -  config - (app.py).create_app(9) - Создана БД
2025-01-02 21:10:35,081 - [INFO] -  config - (app.py).create_app(12) - Зарегистрирован (<Blueprint 'timer'>, <Blueprint 'users'>)
2025-01-02 23:58:17,308 - [ERROR] -  config - (config.py).load_logged_in_user(83) - Error in load_logged_in_user: Signature has expired
2025-01-02 23:58:17,335 - [ERROR] -  config - (config.py).load_logged_in_user(83) - Error in load_logged_in_user: Signature has expired
2025-01-02 23:58:20,048 - [ERROR] -  config - (config.py).load_logged_in_user(83) - Error in load_logged_in_user: Signature has expired
2025-01-02 23:58:20,089 - [ERROR] -  config - (config.py).load_logged_in_user(83) - Error in load_logged_in_user: Signature has expired
2025-01-02 23:58:27,088 - [ERROR] -  config - (config.py).load_logged_in_user(83) - Error in load_logged_in_user: Signature has expired
2025-01-02 23:58:27,165 - [INFO] -  config - (user.py).post(89) - Пользователь wwww вошел в систему!
2025-01-03 00:00:04,920 - [INFO] -  config - (endpoints.py).post(59) - Данные по задаче test добавлены в БД
2025-01-03 00:00:09,614 - [INFO] -  config - (endpoints.py).delete_item(162) - Удалена задача: name = test, date = 2025-01-03
2025-01-03 00:00:07,960 - [INFO] -  config - (endpoints.py).post(59) - Данные по задаче delo добавлены в БД
2025-01-03 00:00:11,289 - [INFO] -  config - (endpoints.py).delete_item(162) - Удалена задача: name = delo, date = 2025-01-03
2025-01-03 00:00:31,041 - [INFO] -  config - (endpoints.py).post(59) - Данные по задаче click добавлены в БД
2025-01-03 00:00:34,505 - [INFO] -  config - (endpoints.py).delete_item(162) - Удалена задача: name = click, date = 2025-01-03
2025-01-03 00:21:35,097 - [INFO] -  config - (app.py).create_app(9) - Создана БД
2025-01-03 00:21:35,097 - [INFO] -  config - (app.py).create_app(12) - Зарегистрирован (<Blueprint 'timer'>, <Blueprint 'users'>)
2025-01-03 00:21:35,960 - [INFO] -  config - (app.py).create_app(9) - Создана БД
2025-01-03 00:21:35,966 - [INFO] -  config - (app.py).create_app(12) - Зарегистрирован (<Blueprint 'timer'>, <Blueprint 'users'>)
2025-01-03 00:00:00,127 - [INFO] -  config - (endpoints.py).post(59) - Данные по задаче fff добавлены в БД
2025-01-03 00:00:16,344 - [INFO] -  config - (endpoints.py).delete_item(162) - Удалена задача: name = fff, date = 2025-01-03
2025-01-03 00:00:34,929 - [INFO] -  config - (endpoints.py).post(59) - Данные по задаче sss добавлены в БД
2025-01-03 00:00:37,524 - [INFO] -  config - (endpoints.py).delete_item(162) - Удалена задача: name = sss, date = 2025-01-03
2025-01-03 00:00:05,536 - [INFO] -  config - (endpoints.py).post(59) - Данные по задаче fff добавлены в БД
2025-01-03 00:00:07,973 - [INFO] -  config - (endpoints.py).delete_item(162) - Удалена задача: name = fff, date = 2025-01-03
2025-01-02 23:59:59,377 - [INFO] -  config - (endpoints.py).post(59) - Данные по задаче sss добавлены в БД
2025-01-03 23:58:50,901 - [ERROR] -  config - (config.py).load_logged_in_user(83) - Error in load_logged_in_user: Signature has expired
2025-01-03 23:58:50,936 - [ERROR] -  config - (config.py).load_logged_in_user(83) - Error in load_logged_in_user: Signature has expired
2025-01-03 23:58:52,908 - [ERROR] -  config - (config.py).load_logged_in_user(83) - Error in load_logged_in_user: Signature has expired
2025-01-03 23:58:53,033 - [ERROR] -  config - (config.py).load_logged_in_user(83) - Error in load_logged_in_user: Signature has expired
2025-01-03 23:58:59,186 - [ERROR] -  config - (config.py).load_logged_in_user(83) - Error in load_logged_in_user: Signature has expired
2025-01-03 23:58:59,294 - [INFO] -  config - (user.py).post(89) - Пользователь wwww вошел в систему!
2025-01-04 00:00:14,591 - [INFO] -  config - (endpoints.py).post(59) - Данные по задаче workTest добавлены в БД
2025-01-03 23:58:43,526 - [ERROR] -  config - (config.py).load_logged_in_user(83) - Error in load_logged_in_user: The token is not yet valid (iat)
2025-01-03 23:58:43,549 - [ERROR] -  config - (config.py).load_logged_in_user(83) - Error in load_logged_in_user: The token is not yet valid (iat)
2025-01-03 23:58:45,188 - [ERROR] -  config - (config.py).load_logged_in_user(83) - Error in load_logged_in_user: The token is not yet valid (iat)
2025-01-03 23:58:45,214 - [ERROR] -  config - (config.py).load_logged_in_user(83) - Error in load_logged_in_user: The token is not yet valid (iat)
2025-01-03 23:58:47,213 - [ERROR] -  config - (config.py).load_logged_in_user(83) - Error in load_logged_in_user: The token is not yet valid (iat)
2025-01-03 23:58:47,235 - [ERROR] -  config - (config.py).load_logged_in_user(83) - Error in load_logged_in_user: The token is not yet valid (iat)
2025-01-03 23:58:55,574 - [ERROR] -  config - (config.py).load_logged_in_user(83) - Error in load_logged_in_user: The token is not yet valid (iat)
2025-01-03 23:58:55,651 - [INFO] -  config - (user.py).post(89) - Пользователь wwww вошел в систему!
2025-01-03 23:59:59,118 - [INFO] -  config - (endpoints.py).post(59) - Данные по задаче delo1 добавлены в БД
2025-01-04 00:00:22,433 - [INFO] -  config - (endpoints.py).post(59) - Данные по задаче delo1 добавлены в БД
2025-01-04 00:00:37,727 - [INFO] -  config - (endpoints.py).delete_item(162) - Удалена задача: name = workTest, date = 2025-01-04
2025-01-04 00:00:40,093 - [INFO] -  config - (endpoints.py).delete_item(162) - Удалена задача: name = delo1, date = 2025-01-04
2025-01-04 00:00:56,302 - [INFO] -  config - (endpoints.py).delete_item(162) - Удалена задача: name = delo1, date = 2025-01-03
2025-01-03 23:58:48,144 - [ERROR] -  config - (config.py).load_logged_in_user(83) - Error in load_logged_in_user: The token is not yet valid (iat)
2025-01-03 23:58:48,163 - [ERROR] -  config - (config.py).load_logged_in_user(83) - Error in load_logged_in_user: The token is not yet valid (iat)
2025-01-03 23:58:49,587 - [ERROR] -  config - (config.py).load_logged_in_user(83) - Error in load_logged_in_user: The token is not yet valid (iat)
2025-01-03 23:58:49,593 - [ERROR] -  config - (config.py).load_logged_in_user(83) - Error in load_logged_in_user: The token is not yet valid (iat)
2025-01-03 23:58:54,863 - [ERROR] -  config - (config.py).load_logged_in_user(83) - Error in load_logged_in_user: The token is not yet valid (iat)
2025-01-03 23:58:54,949 - [INFO] -  config - (user.py).post(89) - Пользователь wwww вошел в систему!
2025-01-04 00:00:04,428 - [INFO] -  config - (endpoints.py).post(59) - Данные по задаче delo1 добавлены в БД
2025-01-03 23:58:25,270 - [ERROR] -  config - (config.py).load_logged_in_user(83) - Error in load_logged_in_user: The token is not yet valid (iat)
2025-01-03 23:58:25,293 - [ERROR] -  config - (config.py).load_logged_in_user(83) - Error in load_logged_in_user: The token is not yet valid (iat)
2025-01-03 23:58:28,052 - [ERROR] -  config - (config.py).load_logged_in_user(83) - Error in load_logged_in_user: The token is not yet valid (iat)
2025-01-03 23:58:28,071 - [ERROR] -  config - (config.py).load_logged_in_user(83) - Error in load_logged_in_user: The token is not yet valid (iat)
2025-01-03 23:58:34,677 - [ERROR] -  config - (config.py).load_logged_in_user(83) - Error in load_logged_in_user: The token is not yet valid (iat)
2025-01-03 23:58:34,761 - [INFO] -  config - (user.py).post(89) - Пользователь wwww вошел в систему!
2025-01-03 23:58:55,676 - [ERROR] -  config - (app.py).log_exception(838) - Exception on / [POST]
Traceback (most recent call last):
  File "W:\WEB_WORK\Homework\NAA\time_tracker-last\venv\lib\site-packages\sqlalchemy\engine\base.py", line 1967, in _exec_single_context
    self.dialect.do_execute(
  File "W:\WEB_WORK\Homework\NAA\time_tracker-last\venv\lib\site-packages\sqlalchemy\engine\default.py", line 941, in do_execute
    cursor.execute(statement, parameters)
sqlite3.IntegrityError: UNIQUE constraint failed: time_tracker.name_of_work, time_tracker.date, time_tracker.username

The above exception was the direct cause of the following exception:

Traceback (most recent call last):
  File "W:\WEB_WORK\Homework\NAA\time_tracker-last\venv\lib\site-packages\flask\app.py", line 1473, in wsgi_app
    response = self.full_dispatch_request()
  File "W:\WEB_WORK\Homework\NAA\time_tracker-last\venv\lib\site-packages\flask\app.py", line 882, in full_dispatch_request
    rv = self.handle_user_exception(e)
  File "W:\WEB_WORK\Homework\NAA\time_tracker-last\venv\lib\site-packages\flask\app.py", line 880, in full_dispatch_request
    rv = self.dispatch_request()
  File "W:\WEB_WORK\Homework\NAA\time_tracker-last\venv\lib\site-packages\flask\app.py", line 865, in dispatch_request
    return self.ensure_sync(self.view_functions[rule.endpoint])(**view_args)  # type: ignore[no-any-return]
  File "W:\WEB_WORK\Homework\NAA\time_tracker-last\venv\lib\site-packages\flask\views.py", line 110, in view
    return current_app.ensure_sync(self.dispatch_request)(**kwargs)  # type: ignore[no-any-return]
  File "W:\WEB_WORK\Homework\NAA\time_tracker-last\venv\lib\site-packages\flask\views.py", line 191, in dispatch_request
    return current_app.ensure_sync(meth)(**kwargs)  # type: ignore[no-any-return]
  File "W:\WEB_WORK\Homework\NAA\time_tracker-last\venv\lib\site-packages\flask_jwt_extended\view_decorators.py", line 170, in decorator
    return current_app.ensure_sync(fn)(*args, **kwargs)
  File "W:\WEB_WORK\Homework\NAA\time_tracker-last\sources\endpoints.py", line 58, in post
    db.session.commit()
  File "W:\WEB_WORK\Homework\NAA\time_tracker-last\venv\lib\site-packages\sqlalchemy\orm\scoping.py", line 597, in commit
    return self._proxied.commit()
  File "W:\WEB_WORK\Homework\NAA\time_tracker-last\venv\lib\site-packages\sqlalchemy\orm\session.py", line 2028, in commit
    trans.commit(_to_root=True)
  File "<string>", line 2, in commit
  File "W:\WEB_WORK\Homework\NAA\time_tracker-last\venv\lib\site-packages\sqlalchemy\orm\state_changes.py", line 139, in _go
    ret_value = fn(self, *arg, **kw)
  File "W:\WEB_WORK\Homework\NAA\time_tracker-last\venv\lib\site-packages\sqlalchemy\orm\session.py", line 1313, in commit
    self._prepare_impl()
  File "<string>", line 2, in _prepare_impl
  File "W:\WEB_WORK\Homework\NAA\time_tracker-last\venv\lib\site-packages\sqlalchemy\orm\state_changes.py", line 139, in _go
    ret_value = fn(self, *arg, **kw)
  File "W:\WEB_WORK\Homework\NAA\time_tracker-last\venv\lib\site-packages\sqlalchemy\orm\session.py", line 1288, in _prepare_impl
    self.session.flush()
  File "W:\WEB_WORK\Homework\NAA\time_tracker-last\venv\lib\site-packages\sqlalchemy\orm\session.py", line 4352, in flush
    self._flush(objects)
  File "W:\WEB_WORK\Homework\NAA\time_tracker-last\venv\lib\site-packages\sqlalchemy\orm\session.py", line 4487, in _flush
    with util.safe_reraise():
  File "W:\WEB_WORK\Homework\NAA\time_tracker-last\venv\lib\site-packages\sqlalchemy\util\langhelpers.py", line 146, in __exit__
    raise exc_value.with_traceback(exc_tb)
  File "W:\WEB_WORK\Homework\NAA\time_tracker-last\venv\lib\site-packages\sqlalchemy\orm\session.py", line 4448, in _flush
    flush_context.execute()
  File "W:\WEB_WORK\Homework\NAA\time_tracker-last\venv\lib\site-packages\sqlalchemy\orm\unitofwork.py", line 466, in execute
    rec.execute(self)
  File "W:\WEB_WORK\Homework\NAA\time_tracker-last\venv\lib\site-packages\sqlalchemy\orm\unitofwork.py", line 642, in execute
    util.preloaded.orm_persistence.save_obj(
  File "W:\WEB_WORK\Homework\NAA\time_tracker-last\venv\lib\site-packages\sqlalchemy\orm\persistence.py", line 93, in save_obj
    _emit_insert_statements(
  File "W:\WEB_WORK\Homework\NAA\time_tracker-last\venv\lib\site-packages\sqlalchemy\orm\persistence.py", line 1233, in _emit_insert_statements
    result = connection.execute(
  File "W:\WEB_WORK\Homework\NAA\time_tracker-last\venv\lib\site-packages\sqlalchemy\engine\base.py", line 1418, in execute
    return meth(
  File "W:\WEB_WORK\Homework\NAA\time_tracker-last\venv\lib\site-packages\sqlalchemy\sql\elements.py", line 515, in _execute_on_connection
    return connection._execute_clauseelement(
  File "W:\WEB_WORK\Homework\NAA\time_tracker-last\venv\lib\site-packages\sqlalchemy\engine\base.py", line 1640, in _execute_clauseelement
    ret = self._execute_context(
  File "W:\WEB_WORK\Homework\NAA\time_tracker-last\venv\lib\site-packages\sqlalchemy\engine\base.py", line 1846, in _execute_context
    return self._exec_single_context(
  File "W:\WEB_WORK\Homework\NAA\time_tracker-last\venv\lib\site-packages\sqlalchemy\engine\base.py", line 1986, in _exec_single_context
    self._handle_dbapi_exception(
  File "W:\WEB_WORK\Homework\NAA\time_tracker-last\venv\lib\site-packages\sqlalchemy\engine\base.py", line 2355, in _handle_dbapi_exception
    raise sqlalchemy_exception.with_traceback(exc_info[2]) from e
  File "W:\WEB_WORK\Homework\NAA\time_tracker-last\venv\lib\site-packages\sqlalchemy\engine\base.py", line 1967, in _exec_single_context
    self.dialect.do_execute(
  File "W:\WEB_WORK\Homework\NAA\time_tracker-last\venv\lib\site-packages\sqlalchemy\engine\default.py", line 941, in do_execute
    cursor.execute(statement, parameters)
sqlalchemy.exc.IntegrityError: (sqlite3.IntegrityError) UNIQUE constraint failed: time_tracker.name_of_work, time_tracker.date, time_tracker.username
[SQL: INSERT INTO time_tracker (name_of_work, date, time, description, username) VALUES (?, ?, ?, ?, ?)]
[parameters: ('delo1', '2025-01-04', '00:01:10.000000', None, 'wwww')]
(Background on this error at: https://sqlalche.me/e/20/gkpj)
2025-01-03 10:58:41,394 - [INFO] -  config - (app.py).create_app(9) - Создана БД
2025-01-03 10:58:41,398 - [INFO] -  config - (app.py).create_app(12) - Зарегистрирован (<Blueprint 'timer'>, <Blueprint 'users'>)
2025-01-03 10:58:42,121 - [INFO] -  config - (app.py).create_app(9) - Создана БД
2025-01-03 10:58:42,121 - [INFO] -  config - (app.py).create_app(12) - Зарегистрирован (<Blueprint 'timer'>, <Blueprint 'users'>)
2025-01-03 10:58:44,182 - [ERROR] -  config - (config.py).load_logged_in_user(83) - Error in load_logged_in_user: The token is not yet valid (iat)
2025-01-03 10:59:15,862 - [INFO] -  config - (app.py).create_app(9) - Создана БД
2025-01-03 10:59:15,878 - [INFO] -  config - (app.py).create_app(12) - Зарегистрирован (<Blueprint 'timer'>, <Blueprint 'users'>)
2025-01-03 10:59:16,548 - [INFO] -  config - (app.py).create_app(9) - Создана БД
2025-01-03 10:59:16,548 - [INFO] -  config - (app.py).create_app(12) - Зарегистрирован (<Blueprint 'timer'>, <Blueprint 'users'>)
2025-01-03 10:59:22,151 - [ERROR] -  config - (config.py).load_logged_in_user(83) - Error in load_logged_in_user: The token is not yet valid (iat)
2025-01-03 10:59:22,193 - [ERROR] -  config - (config.py).load_logged_in_user(83) - Error in load_logged_in_user: The token is not yet valid (iat)
2025-01-03 10:59:24,402 - [ERROR] -  config - (config.py).load_logged_in_user(83) - Error in load_logged_in_user: The token is not yet valid (iat)
2025-01-03 10:59:24,485 - [ERROR] -  config - (config.py).load_logged_in_user(83) - Error in load_logged_in_user: The token is not yet valid (iat)
2025-01-03 10:59:32,403 - [ERROR] -  config - (config.py).load_logged_in_user(83) - Error in load_logged_in_user: The token is not yet valid (iat)
2025-01-03 10:59:32,486 - [INFO] -  config - (user.py).post(89) - Пользователь wwww вошел в систему!
2025-01-03 11:00:49,585 - [INFO] -  config - (endpoints.py).post(59) - Данные по задаче delo1 добавлены в БД
2025-01-03 11:00:59,440 - [INFO] -  config - (endpoints.py).post(44) - Обновлены данные по задаче delo1. Время: 00:02:25
2025-01-03 11:03:03,884 - [INFO] -  config - (endpoints.py).delete_item(162) - Удалена задача: name = delo1, date = 2025-01-03
2025-01-03 11:03:55,002 - [INFO] -  config - (endpoints.py).post(59) - Данные по задаче delo2 добавлены в БД
2025-01-03 11:04:55,541 - [INFO] -  config - (endpoints.py).delete_item(162) - Удалена задача: name = delo2, date = 2025-01-03
2025-01-03 11:05:57,688 - [INFO] -  config - (endpoints.py).post(59) - Данные по задаче delo2 добавлены в БД
2025-01-03 11:07:06,793 - [INFO] -  config - (endpoints.py).post(44) - Обновлены данные по задаче delo2. Время: 00:03:24
2025-01-03 11:08:24,058 - [INFO] -  config - (endpoints.py).post(59) - Данные по задаче delo1 добавлены в БД
2025-01-03 11:09:33,785 - [INFO] -  config - (endpoints.py).post(44) - Обновлены данные по задаче delo1. Время: 00:03:24
2025-01-03 11:16:14,793 - [INFO] -  config - (endpoints.py).post(44) - Обновлены данные по задаче delo1. Время: 00:06:48
2025-01-03 11:17:41,116 - [INFO] -  config - (endpoints.py).post(59) - Данные по задаче delo3 добавлены в БД
2025-01-03 11:17:52,844 - [INFO] -  config - (endpoints.py).post(44) - Обновлены данные по задаче delo3. Время: 00:02:27
2025-01-03 11:18:03,686 - [INFO] -  config - (endpoints.py).delete_item(162) - Удалена задача: name = delo3, date = 2025-01-03
2025-01-03 11:23:49,391 - [INFO] -  config - (endpoints.py).post(59) - Данные по задаче дело добавлены в БД
2025-01-03 11:24:05,235 - [INFO] -  config - (endpoints.py).delete_item(162) - Удалена задача: name = дело, date = 2025-01-03
2025-01-03 11:24:07,786 - [INFO] -  config - (endpoints.py).post(59) - Данные по задаче дело добавлены в БД
2025-01-03 11:24:11,992 - [INFO] -  config - (endpoints.py).delete_item(162) - Удалена задача: name = дело, date = 2025-01-03
2025-01-03 11:24:13,487 - [INFO] -  config - (endpoints.py).delete_item(162) - Удалена задача: name = delo2, date = 2025-01-03
2025-01-03 11:24:14,688 - [INFO] -  config - (endpoints.py).delete_item(162) - Удалена задача: name = delo1, date = 2025-01-03
2025-01-03 13:23:29,659 - [INFO] -  config - (endpoints.py).post(59) - Данные по задаче delo добавлены в БД
2025-01-03 13:24:33,645 - [INFO] -  config - (endpoints.py).delete_item(162) - Удалена задача: name = delo, date = 2025-01-03
2025-01-03 13:25:33,364 - [INFO] -  config - (endpoints.py).post(59) - Данные по задаче del добавлены в БД
2025-01-03 13:25:45,858 - [INFO] -  config - (endpoints.py).post(44) - Обновлены данные по задаче del. Время: 00:02:28
2025-01-03 13:25:58,711 - [INFO] -  config - (endpoints.py).delete_item(162) - Удалена задача: name = del, date = 2025-01-03
2025-01-03 23:58:11,914 - [ERROR] -  config - (config.py).load_logged_in_user(83) - Error in load_logged_in_user: Signature has expired
2025-01-03 23:58:11,933 - [ERROR] -  config - (config.py).load_logged_in_user(83) - Error in load_logged_in_user: Signature has expired
2025-01-03 23:58:13,623 - [ERROR] -  config - (config.py).load_logged_in_user(83) - Error in load_logged_in_user: Signature has expired
2025-01-03 23:58:13,652 - [ERROR] -  config - (config.py).load_logged_in_user(83) - Error in load_logged_in_user: Signature has expired
2025-01-03 23:58:19,825 - [ERROR] -  config - (config.py).load_logged_in_user(83) - Error in load_logged_in_user: Signature has expired
2025-01-03 23:58:19,908 - [INFO] -  config - (user.py).post(89) - Пользователь wwww вошел в систему!
2025-01-04 00:00:02,550 - [INFO] -  config - (endpoints.py).post(44) - Обновлены данные по задаче delo1. Время: 00:03:27
2025-01-04 00:00:27,994 - [INFO] -  config - (endpoints.py).post(44) - Обновлены данные по задаче delo1. Время: 00:06:20
2025-01-04 00:01:10,609 - [INFO] -  config - (endpoints.py).delete_item(162) - Удалена задача: name = delo1, date = 2025-01-04
2025-01-03 23:58:45,540 - [INFO] -  config - (endpoints.py).post(59) - Данные по задаче ddd добавлены в БД
2025-01-03 23:58:51,301 - [ERROR] -  config - (app.py).log_exception(838) - Exception on / [POST]
Traceback (most recent call last):
  File "W:\WEB_WORK\Homework\NAA\time_tracker-last\venv\lib\site-packages\sqlalchemy\engine\base.py", line 1967, in _exec_single_context
    self.dialect.do_execute(
  File "W:\WEB_WORK\Homework\NAA\time_tracker-last\venv\lib\site-packages\sqlalchemy\engine\default.py", line 941, in do_execute
    cursor.execute(statement, parameters)
sqlite3.IntegrityError: UNIQUE constraint failed: time_tracker.name_of_work, time_tracker.date, time_tracker.username

The above exception was the direct cause of the following exception:

Traceback (most recent call last):
  File "W:\WEB_WORK\Homework\NAA\time_tracker-last\venv\lib\site-packages\flask\app.py", line 1473, in wsgi_app
    response = self.full_dispatch_request()
  File "W:\WEB_WORK\Homework\NAA\time_tracker-last\venv\lib\site-packages\flask\app.py", line 882, in full_dispatch_request
    rv = self.handle_user_exception(e)
  File "W:\WEB_WORK\Homework\NAA\time_tracker-last\venv\lib\site-packages\flask\app.py", line 880, in full_dispatch_request
    rv = self.dispatch_request()
  File "W:\WEB_WORK\Homework\NAA\time_tracker-last\venv\lib\site-packages\flask\app.py", line 865, in dispatch_request
    return self.ensure_sync(self.view_functions[rule.endpoint])(**view_args)  # type: ignore[no-any-return]
  File "W:\WEB_WORK\Homework\NAA\time_tracker-last\venv\lib\site-packages\flask\views.py", line 110, in view
    return current_app.ensure_sync(self.dispatch_request)(**kwargs)  # type: ignore[no-any-return]
  File "W:\WEB_WORK\Homework\NAA\time_tracker-last\venv\lib\site-packages\flask\views.py", line 191, in dispatch_request
    return current_app.ensure_sync(meth)(**kwargs)  # type: ignore[no-any-return]
  File "W:\WEB_WORK\Homework\NAA\time_tracker-last\venv\lib\site-packages\flask_jwt_extended\view_decorators.py", line 170, in decorator
    return current_app.ensure_sync(fn)(*args, **kwargs)
  File "W:\WEB_WORK\Homework\NAA\time_tracker-last\sources\endpoints.py", line 58, in post
    db.session.commit()
  File "W:\WEB_WORK\Homework\NAA\time_tracker-last\venv\lib\site-packages\sqlalchemy\orm\scoping.py", line 597, in commit
    return self._proxied.commit()
  File "W:\WEB_WORK\Homework\NAA\time_tracker-last\venv\lib\site-packages\sqlalchemy\orm\session.py", line 2028, in commit
    trans.commit(_to_root=True)
  File "<string>", line 2, in commit
  File "W:\WEB_WORK\Homework\NAA\time_tracker-last\venv\lib\site-packages\sqlalchemy\orm\state_changes.py", line 139, in _go
    ret_value = fn(self, *arg, **kw)
  File "W:\WEB_WORK\Homework\NAA\time_tracker-last\venv\lib\site-packages\sqlalchemy\orm\session.py", line 1313, in commit
    self._prepare_impl()
  File "<string>", line 2, in _prepare_impl
  File "W:\WEB_WORK\Homework\NAA\time_tracker-last\venv\lib\site-packages\sqlalchemy\orm\state_changes.py", line 139, in _go
    ret_value = fn(self, *arg, **kw)
  File "W:\WEB_WORK\Homework\NAA\time_tracker-last\venv\lib\site-packages\sqlalchemy\orm\session.py", line 1288, in _prepare_impl
    self.session.flush()
  File "W:\WEB_WORK\Homework\NAA\time_tracker-last\venv\lib\site-packages\sqlalchemy\orm\session.py", line 4352, in flush
    self._flush(objects)
  File "W:\WEB_WORK\Homework\NAA\time_tracker-last\venv\lib\site-packages\sqlalchemy\orm\session.py", line 4487, in _flush
    with util.safe_reraise():
  File "W:\WEB_WORK\Homework\NAA\time_tracker-last\venv\lib\site-packages\sqlalchemy\util\langhelpers.py", line 146, in __exit__
    raise exc_value.with_traceback(exc_tb)
  File "W:\WEB_WORK\Homework\NAA\time_tracker-last\venv\lib\site-packages\sqlalchemy\orm\session.py", line 4448, in _flush
    flush_context.execute()
  File "W:\WEB_WORK\Homework\NAA\time_tracker-last\venv\lib\site-packages\sqlalchemy\orm\unitofwork.py", line 466, in execute
    rec.execute(self)
  File "W:\WEB_WORK\Homework\NAA\time_tracker-last\venv\lib\site-packages\sqlalchemy\orm\unitofwork.py", line 642, in execute
    util.preloaded.orm_persistence.save_obj(
  File "W:\WEB_WORK\Homework\NAA\time_tracker-last\venv\lib\site-packages\sqlalchemy\orm\persistence.py", line 93, in save_obj
    _emit_insert_statements(
  File "W:\WEB_WORK\Homework\NAA\time_tracker-last\venv\lib\site-packages\sqlalchemy\orm\persistence.py", line 1233, in _emit_insert_statements
    result = connection.execute(
  File "W:\WEB_WORK\Homework\NAA\time_tracker-last\venv\lib\site-packages\sqlalchemy\engine\base.py", line 1418, in execute
    return meth(
  File "W:\WEB_WORK\Homework\NAA\time_tracker-last\venv\lib\site-packages\sqlalchemy\sql\elements.py", line 515, in _execute_on_connection
    return connection._execute_clauseelement(
  File "W:\WEB_WORK\Homework\NAA\time_tracker-last\venv\lib\site-packages\sqlalchemy\engine\base.py", line 1640, in _execute_clauseelement
    ret = self._execute_context(
  File "W:\WEB_WORK\Homework\NAA\time_tracker-last\venv\lib\site-packages\sqlalchemy\engine\base.py", line 1846, in _execute_context
    return self._exec_single_context(
  File "W:\WEB_WORK\Homework\NAA\time_tracker-last\venv\lib\site-packages\sqlalchemy\engine\base.py", line 1986, in _exec_single_context
    self._handle_dbapi_exception(
  File "W:\WEB_WORK\Homework\NAA\time_tracker-last\venv\lib\site-packages\sqlalchemy\engine\base.py", line 2355, in _handle_dbapi_exception
    raise sqlalchemy_exception.with_traceback(exc_info[2]) from e
  File "W:\WEB_WORK\Homework\NAA\time_tracker-last\venv\lib\site-packages\sqlalchemy\engine\base.py", line 1967, in _exec_single_context
    self.dialect.do_execute(
  File "W:\WEB_WORK\Homework\NAA\time_tracker-last\venv\lib\site-packages\sqlalchemy\engine\default.py", line 941, in do_execute
    cursor.execute(statement, parameters)
sqlalchemy.exc.IntegrityError: (sqlite3.IntegrityError) UNIQUE constraint failed: time_tracker.name_of_work, time_tracker.date, time_tracker.username
[SQL: INSERT INTO time_tracker (name_of_work, date, time, description, username) VALUES (?, ?, ?, ?, ?)]
[parameters: ('ddd', '2025-01-04', '00:00:06.000000', None, 'wwww')]
(Background on this error at: https://sqlalche.me/e/20/gkpj)
2025-01-03 23:59:52,094 - [INFO] -  config - (endpoints.py).post(59) - Данные по задаче ddd добавлены в БД
2025-01-03 23:59:59,399 - [INFO] -  config - (endpoints.py).post(44) - Обновлены данные по задаче ddd. Время: 00:00:06
2025-01-04 00:00:06,184 - [INFO] -  config - (endpoints.py).post(44) - Обновлены данные по задаче ddd. Время: 00:00:16
2025-01-03 23:59:19,639 - [INFO] -  config - (endpoints.py).post(59) - Данные по задаче del добавлены в БД
2025-01-03 23:59:28,774 - [INFO] -  config - (endpoints.py).post(44) - Обновлены данные по задаче ddd. Время: 00:00:15
2025-01-03 23:59:33,454 - [INFO] -  config - (endpoints.py).post(44) - Обновлены данные по задаче ddd. Время: 00:00:26
2025-01-04 00:01:03,556 - [INFO] -  config - (endpoints.py).post(44) - Обновлены данные по задаче ddd. Время: 00:00:35
2025-01-03 23:58:17,217 - [ERROR] -  config - (config.py).load_logged_in_user(83) - Error in load_logged_in_user: The token is not yet valid (iat)
2025-01-03 23:58:17,232 - [ERROR] -  config - (config.py).load_logged_in_user(83) - Error in load_logged_in_user: The token is not yet valid (iat)
2025-01-03 23:58:25,073 - [INFO] -  config - (user.py).post(89) - Пользователь wwww вошел в систему!
2025-01-03 23:59:59,574 - [INFO] -  config - (endpoints.py).post(59) - Данные по задаче test добавлены в БД
2025-01-04 00:00:41,050 - [INFO] -  config - (endpoints.py).post(59) - Данные по задаче test добавлены в БД
2025-01-03 23:59:59,106 - [INFO] -  config - (endpoints.py).post(59) - Данные по задаче del добавлены в БД
2025-01-04 00:00:30,427 - [INFO] -  config - (endpoints.py).post(44) - Обновлены данные по задаче del. Время: 00:01:09
2025-01-03 22:16:58,882 - [INFO] -  config - (app.py).create_app(9) - Создана БД
2025-01-03 22:16:58,882 - [INFO] -  config - (app.py).create_app(12) - Зарегистрирован (<Blueprint 'timer'>, <Blueprint 'users'>)
2025-01-03 22:16:59,657 - [INFO] -  config - (app.py).create_app(9) - Создана БД
2025-01-03 22:16:59,657 - [INFO] -  config - (app.py).create_app(12) - Зарегистрирован (<Blueprint 'timer'>, <Blueprint 'users'>)
2025-01-03 22:17:03,108 - [ERROR] -  config - (config.py).load_logged_in_user(83) - Error in load_logged_in_user: The token is not yet valid (iat)
2025-01-03 22:17:03,215 - [ERROR] -  config - (config.py).load_logged_in_user(83) - Error in load_logged_in_user: The token is not yet valid (iat)
2025-01-03 22:17:04,703 - [ERROR] -  config - (config.py).load_logged_in_user(83) - Error in load_logged_in_user: The token is not yet valid (iat)
2025-01-03 22:17:04,776 - [ERROR] -  config - (config.py).load_logged_in_user(83) - Error in load_logged_in_user: The token is not yet valid (iat)
2025-01-03 22:17:10,293 - [ERROR] -  config - (config.py).load_logged_in_user(83) - Error in load_logged_in_user: The token is not yet valid (iat)
2025-01-03 22:17:10,386 - [INFO] -  config - (user.py).post(89) - Пользователь wwww вошел в систему!
2025-01-03 22:20:19,653 - [INFO] -  config - (app.py).create_app(9) - Создана БД
2025-01-03 22:20:19,653 - [INFO] -  config - (app.py).create_app(12) - Зарегистрирован (<Blueprint 'timer'>, <Blueprint 'users'>)
2025-01-03 22:20:20,330 - [INFO] -  config - (app.py).create_app(9) - Создана БД
2025-01-03 22:20:20,330 - [INFO] -  config - (app.py).create_app(12) - Зарегистрирован (<Blueprint 'timer'>, <Blueprint 'users'>)
2025-01-03 22:23:07,899 - [INFO] -  config - (app.py).create_app(9) - Создана БД
2025-01-03 22:23:07,911 - [INFO] -  config - (app.py).create_app(12) - Зарегистрирован (<Blueprint 'timer'>, <Blueprint 'users'>)
2025-01-03 22:23:11,399 - [INFO] -  config - (app.py).create_app(9) - Создана БД
2025-01-03 22:23:11,410 - [INFO] -  config - (app.py).create_app(12) - Зарегистрирован (<Blueprint 'timer'>, <Blueprint 'users'>)
2025-01-04 00:00:35,334 - [INFO] -  config - (endpoints.py).post(59) - Данные по задаче ggg добавлены в БД
2025-01-04 13:46:22,915 - [INFO] -  config - (app.py).create_app(9) - Создана БД
2025-01-04 13:46:22,915 - [INFO] -  config - (app.py).create_app(12) - Зарегистрирован (<Blueprint 'timer'>, <Blueprint 'users'>)
2025-01-04 13:46:23,596 - [INFO] -  config - (app.py).create_app(9) - Создана БД
2025-01-04 13:46:23,596 - [INFO] -  config - (app.py).create_app(12) - Зарегистрирован (<Blueprint 'timer'>, <Blueprint 'users'>)
2025-01-04 13:46:30,950 - [ERROR] -  config - (config.py).load_logged_in_user(83) - Error in load_logged_in_user: Signature has expired
2025-01-04 13:46:30,982 - [ERROR] -  config - (config.py).load_logged_in_user(83) - Error in load_logged_in_user: Signature has expired
2025-01-04 13:46:32,587 - [ERROR] -  config - (config.py).load_logged_in_user(83) - Error in load_logged_in_user: Signature has expired
2025-01-04 13:46:32,610 - [ERROR] -  config - (config.py).load_logged_in_user(83) - Error in load_logged_in_user: Signature has expired
2025-01-04 13:46:39,906 - [ERROR] -  config - (config.py).load_logged_in_user(83) - Error in load_logged_in_user: Signature has expired
2025-01-04 13:46:40,002 - [INFO] -  config - (user.py).post(89) - Пользователь wwww вошел в систему!
2025-01-11 11:33:34,679 - [INFO] -  config - (app.py).create_app(9) - Создана БД
2025-01-11 11:33:34,682 - [INFO] -  config - (app.py).create_app(12) - Зарегистрирован (<Blueprint 'timer'>, <Blueprint 'users'>)
2025-01-11 11:33:35,323 - [INFO] -  config - (app.py).create_app(9) - Создана БД
2025-01-11 11:33:35,323 - [INFO] -  config - (app.py).create_app(12) - Зарегистрирован (<Blueprint 'timer'>, <Blueprint 'users'>)
2025-01-11 11:34:03,234 - [ERROR] -  config - (config.py).load_logged_in_user(82) - Error in load_logged_in_user: Signature has expired
2025-01-11 11:34:03,272 - [ERROR] -  config - (config.py).load_logged_in_user(82) - Error in load_logged_in_user: Signature has expired
2025-01-11 11:34:03,547 - [ERROR] -  config - (config.py).load_logged_in_user(82) - Error in load_logged_in_user: Signature has expired
2025-01-11 11:34:05,116 - [ERROR] -  config - (config.py).load_logged_in_user(82) - Error in load_logged_in_user: Signature has expired
2025-01-11 11:34:05,223 - [ERROR] -  config - (config.py).load_logged_in_user(82) - Error in load_logged_in_user: Signature has expired
2025-01-11 11:34:10,454 - [ERROR] -  config - (config.py).load_logged_in_user(82) - Error in load_logged_in_user: Signature has expired
2025-01-11 11:34:10,551 - [INFO] -  config - (user.py).post(89) - Пользователь wwww вошел в систему!
