2024-11-30 11:04:02,569 - [INFO] -  config - (app.py).create_app(9) - Создана БД
2024-11-30 11:04:02,572 - [INFO] -  config - (app.py).create_app(12) - Зарегистрирован (<Blueprint 'timer'>, <Blueprint 'users'>)
2024-11-30 11:04:03,146 - [INFO] -  config - (app.py).create_app(9) - Создана БД
2024-11-30 11:04:03,160 - [INFO] -  config - (app.py).create_app(12) - Зарегистрирован (<Blueprint 'timer'>, <Blueprint 'users'>)
2024-11-30 11:04:08,376 - [INFO] -  config - (endpoints.py).get(53) - Анонимный пользователь зашел на страницу
2024-11-30 11:04:21,749 - [INFO] -  config - (user.py).post(42) - Пользователь qwerty зарегистирован!
2024-11-30 11:04:27,038 - [INFO] -  config - (user.py).post(69) - Пользователь qwerty вошел в систему!
2024-11-30 11:04:27,061 - [INFO] -  config - (endpoints.py).get(53) - Анонимный пользователь зашел на страницу
2024-11-30 11:04:37,374 - [INFO] -  config - (endpoints.py).get(53) - Анонимный пользователь зашел на страницу
2024-11-30 11:04:38,862 - [INFO] -  config - (endpoints.py).get(53) - Анонимный пользователь зашел на страницу
2024-11-30 11:04:42,369 - [INFO] -  config - (endpoints.py).get(53) - Анонимный пользователь зашел на страницу
2024-11-30 11:04:43,864 - [INFO] -  config - (endpoints.py).get(53) - Анонимный пользователь зашел на страницу
2024-11-30 11:04:44,409 - [INFO] -  config - (endpoints.py).get(53) - Анонимный пользователь зашел на страницу
2024-11-30 11:04:44,614 - [INFO] -  config - (endpoints.py).get(53) - Анонимный пользователь зашел на страницу
2024-11-30 11:04:45,500 - [INFO] -  config - (endpoints.py).get(53) - Анонимный пользователь зашел на страницу
2024-11-30 11:04:53,286 - [INFO] -  config - (endpoints.py).get(53) - Анонимный пользователь зашел на страницу
2024-11-30 11:06:09,816 - [INFO] -  config - (app.py).create_app(9) - Создана БД
2024-11-30 11:06:09,816 - [INFO] -  config - (app.py).create_app(12) - Зарегистрирован (<Blueprint 'timer'>, <Blueprint 'users'>)
2024-11-30 11:06:10,376 - [INFO] -  config - (app.py).create_app(9) - Создана БД
2024-11-30 11:06:10,376 - [INFO] -  config - (app.py).create_app(12) - Зарегистрирован (<Blueprint 'timer'>, <Blueprint 'users'>)
2024-11-30 11:06:14,462 - [INFO] -  config - (endpoints.py).get(53) - Анонимный пользователь зашел на страницу
2024-11-30 11:06:22,502 - [INFO] -  config - (endpoints.py).get(53) - Анонимный пользователь зашел на страницу
2024-11-30 11:06:57,733 - [INFO] -  config - (endpoints.py).get(53) - Анонимный пользователь зашел на страницу
2024-12-25 20:12:51,009 - [INFO] -  config - (app.py).create_app(9) - Создана БД
2024-12-25 20:12:51,028 - [INFO] -  config - (app.py).create_app(12) - Зарегистрирован (<Blueprint 'timer'>, <Blueprint 'users'>)
2024-12-25 20:12:51,738 - [INFO] -  config - (app.py).create_app(9) - Создана БД
2024-12-25 20:12:51,742 - [INFO] -  config - (app.py).create_app(12) - Зарегистрирован (<Blueprint 'timer'>, <Blueprint 'users'>)
2024-12-25 20:12:55,780 - [ERROR] -  config - (app.py).log_exception(838) - Exception on / [GET]
Traceback (most recent call last):
  File "W:\WEB_WORK\Homework\NAA\time_tracker-last\venv\lib\site-packages\flask\app.py", line 1473, in wsgi_app
    response = self.full_dispatch_request()
  File "W:\WEB_WORK\Homework\NAA\time_tracker-last\venv\lib\site-packages\flask\app.py", line 882, in full_dispatch_request
    rv = self.handle_user_exception(e)
  File "W:\WEB_WORK\Homework\NAA\time_tracker-last\venv\lib\site-packages\flask\app.py", line 880, in full_dispatch_request
    rv = self.dispatch_request()
  File "W:\WEB_WORK\Homework\NAA\time_tracker-last\venv\lib\site-packages\flask\app.py", line 865, in dispatch_request
    return self.ensure_sync(self.view_functions[rule.endpoint])(**view_args)  # type: ignore[no-any-return]
  File "W:\WEB_WORK\Homework\NAA\time_tracker-last\venv\lib\site-packages\flask\views.py", line 110, in view
    return current_app.ensure_sync(self.dispatch_request)(**kwargs)  # type: ignore[no-any-return]
  File "W:\WEB_WORK\Homework\NAA\time_tracker-last\venv\lib\site-packages\flask\views.py", line 191, in dispatch_request
    return current_app.ensure_sync(meth)(**kwargs)  # type: ignore[no-any-return]
  File "W:\WEB_WORK\Homework\NAA\time_tracker-last\sources\endpoints.py", line 21, in get
    return render_template('index.html')
  File "W:\WEB_WORK\Homework\NAA\time_tracker-last\venv\lib\site-packages\flask\templating.py", line 150, in render_template
    return _render(app, template, context)
  File "W:\WEB_WORK\Homework\NAA\time_tracker-last\venv\lib\site-packages\flask\templating.py", line 131, in _render
    rv = template.render(context)
  File "W:\WEB_WORK\Homework\NAA\time_tracker-last\venv\lib\site-packages\jinja2\environment.py", line 1304, in render
    self.environment.handle_exception()
  File "W:\WEB_WORK\Homework\NAA\time_tracker-last\venv\lib\site-packages\jinja2\environment.py", line 939, in handle_exception
    raise rewrite_traceback_stack(source=source)
  File "W:\WEB_WORK\Homework\NAA\time_tracker-last\templates\index.html", line 1, in top-level template code
    {% extends 'base.html' %} {% block title %}Учет рабочего времени{% endblock %}
  File "W:\WEB_WORK\Homework\NAA\time_tracker-last\templates\base.html", line 27, in top-level template code
    {% block content %}
  File "W:\WEB_WORK\Homework\NAA\time_tracker-last\templates\index.html", line 51, in block 'content'
    {% if pagination.total > 0 %}
  File "W:\WEB_WORK\Homework\NAA\time_tracker-last\venv\lib\site-packages\jinja2\environment.py", line 487, in getattr
    return getattr(obj, attribute)
jinja2.exceptions.UndefinedError: 'pagination' is undefined
2024-12-25 20:12:58,165 - [ERROR] -  config - (app.py).log_exception(838) - Exception on / [GET]
Traceback (most recent call last):
  File "W:\WEB_WORK\Homework\NAA\time_tracker-last\venv\lib\site-packages\flask\app.py", line 1473, in wsgi_app
    response = self.full_dispatch_request()
  File "W:\WEB_WORK\Homework\NAA\time_tracker-last\venv\lib\site-packages\flask\app.py", line 882, in full_dispatch_request
    rv = self.handle_user_exception(e)
  File "W:\WEB_WORK\Homework\NAA\time_tracker-last\venv\lib\site-packages\flask\app.py", line 880, in full_dispatch_request
    rv = self.dispatch_request()
  File "W:\WEB_WORK\Homework\NAA\time_tracker-last\venv\lib\site-packages\flask\app.py", line 865, in dispatch_request
    return self.ensure_sync(self.view_functions[rule.endpoint])(**view_args)  # type: ignore[no-any-return]
  File "W:\WEB_WORK\Homework\NAA\time_tracker-last\venv\lib\site-packages\flask\views.py", line 110, in view
    return current_app.ensure_sync(self.dispatch_request)(**kwargs)  # type: ignore[no-any-return]
  File "W:\WEB_WORK\Homework\NAA\time_tracker-last\venv\lib\site-packages\flask\views.py", line 191, in dispatch_request
    return current_app.ensure_sync(meth)(**kwargs)  # type: ignore[no-any-return]
  File "W:\WEB_WORK\Homework\NAA\time_tracker-last\sources\endpoints.py", line 21, in get
    return render_template('index.html')
  File "W:\WEB_WORK\Homework\NAA\time_tracker-last\venv\lib\site-packages\flask\templating.py", line 150, in render_template
    return _render(app, template, context)
  File "W:\WEB_WORK\Homework\NAA\time_tracker-last\venv\lib\site-packages\flask\templating.py", line 131, in _render
    rv = template.render(context)
  File "W:\WEB_WORK\Homework\NAA\time_tracker-last\venv\lib\site-packages\jinja2\environment.py", line 1304, in render
    self.environment.handle_exception()
  File "W:\WEB_WORK\Homework\NAA\time_tracker-last\venv\lib\site-packages\jinja2\environment.py", line 939, in handle_exception
    raise rewrite_traceback_stack(source=source)
  File "W:\WEB_WORK\Homework\NAA\time_tracker-last\templates\index.html", line 1, in top-level template code
    {% extends 'base.html' %} {% block title %}Учет рабочего времени{% endblock %}
  File "W:\WEB_WORK\Homework\NAA\time_tracker-last\templates\base.html", line 27, in top-level template code
    {% block content %}
  File "W:\WEB_WORK\Homework\NAA\time_tracker-last\templates\index.html", line 51, in block 'content'
    {% if pagination.total > 0 %}
  File "W:\WEB_WORK\Homework\NAA\time_tracker-last\venv\lib\site-packages\jinja2\environment.py", line 487, in getattr
    return getattr(obj, attribute)
jinja2.exceptions.UndefinedError: 'pagination' is undefined
2024-12-25 20:12:59,043 - [ERROR] -  config - (app.py).log_exception(838) - Exception on / [GET]
Traceback (most recent call last):
  File "W:\WEB_WORK\Homework\NAA\time_tracker-last\venv\lib\site-packages\flask\app.py", line 1473, in wsgi_app
    response = self.full_dispatch_request()
  File "W:\WEB_WORK\Homework\NAA\time_tracker-last\venv\lib\site-packages\flask\app.py", line 882, in full_dispatch_request
    rv = self.handle_user_exception(e)
  File "W:\WEB_WORK\Homework\NAA\time_tracker-last\venv\lib\site-packages\flask\app.py", line 880, in full_dispatch_request
    rv = self.dispatch_request()
  File "W:\WEB_WORK\Homework\NAA\time_tracker-last\venv\lib\site-packages\flask\app.py", line 865, in dispatch_request
    return self.ensure_sync(self.view_functions[rule.endpoint])(**view_args)  # type: ignore[no-any-return]
  File "W:\WEB_WORK\Homework\NAA\time_tracker-last\venv\lib\site-packages\flask\views.py", line 110, in view
    return current_app.ensure_sync(self.dispatch_request)(**kwargs)  # type: ignore[no-any-return]
  File "W:\WEB_WORK\Homework\NAA\time_tracker-last\venv\lib\site-packages\flask\views.py", line 191, in dispatch_request
    return current_app.ensure_sync(meth)(**kwargs)  # type: ignore[no-any-return]
  File "W:\WEB_WORK\Homework\NAA\time_tracker-last\sources\endpoints.py", line 21, in get
    return render_template('index.html')
  File "W:\WEB_WORK\Homework\NAA\time_tracker-last\venv\lib\site-packages\flask\templating.py", line 150, in render_template
    return _render(app, template, context)
  File "W:\WEB_WORK\Homework\NAA\time_tracker-last\venv\lib\site-packages\flask\templating.py", line 131, in _render
    rv = template.render(context)
  File "W:\WEB_WORK\Homework\NAA\time_tracker-last\venv\lib\site-packages\jinja2\environment.py", line 1304, in render
    self.environment.handle_exception()
  File "W:\WEB_WORK\Homework\NAA\time_tracker-last\venv\lib\site-packages\jinja2\environment.py", line 939, in handle_exception
    raise rewrite_traceback_stack(source=source)
  File "W:\WEB_WORK\Homework\NAA\time_tracker-last\templates\index.html", line 1, in top-level template code
    {% extends 'base.html' %} {% block title %}Учет рабочего времени{% endblock %}
  File "W:\WEB_WORK\Homework\NAA\time_tracker-last\templates\base.html", line 27, in top-level template code
    {% block content %}
  File "W:\WEB_WORK\Homework\NAA\time_tracker-last\templates\index.html", line 51, in block 'content'
    {% if pagination.total > 0 %}
  File "W:\WEB_WORK\Homework\NAA\time_tracker-last\venv\lib\site-packages\jinja2\environment.py", line 487, in getattr
    return getattr(obj, attribute)
jinja2.exceptions.UndefinedError: 'pagination' is undefined
2024-12-25 20:13:25,517 - [ERROR] -  config - (user.py).post(46) - Неудачная регистрация!
2024-12-25 20:13:57,817 - [ERROR] -  config - (user.py).post(91) - Неудачная аутентификация!
2024-12-25 20:14:36,298 - [INFO] -  config - (user.py).post(43) - Пользователь seva зарегистирован!
2024-12-25 20:14:45,573 - [INFO] -  config - (user.py).post(89) - Пользователь seva вошел в систему!
2024-12-25 20:14:45,589 - [ERROR] -  config - (app.py).log_exception(838) - Exception on / [GET]
Traceback (most recent call last):
  File "W:\WEB_WORK\Homework\NAA\time_tracker-last\venv\lib\site-packages\flask\app.py", line 1473, in wsgi_app
    response = self.full_dispatch_request()
  File "W:\WEB_WORK\Homework\NAA\time_tracker-last\venv\lib\site-packages\flask\app.py", line 882, in full_dispatch_request
    rv = self.handle_user_exception(e)
  File "W:\WEB_WORK\Homework\NAA\time_tracker-last\venv\lib\site-packages\flask\app.py", line 880, in full_dispatch_request
    rv = self.dispatch_request()
  File "W:\WEB_WORK\Homework\NAA\time_tracker-last\venv\lib\site-packages\flask\app.py", line 865, in dispatch_request
    return self.ensure_sync(self.view_functions[rule.endpoint])(**view_args)  # type: ignore[no-any-return]
  File "W:\WEB_WORK\Homework\NAA\time_tracker-last\venv\lib\site-packages\flask\views.py", line 110, in view
    return current_app.ensure_sync(self.dispatch_request)(**kwargs)  # type: ignore[no-any-return]
  File "W:\WEB_WORK\Homework\NAA\time_tracker-last\venv\lib\site-packages\flask\views.py", line 191, in dispatch_request
    return current_app.ensure_sync(meth)(**kwargs)  # type: ignore[no-any-return]
  File "W:\WEB_WORK\Homework\NAA\time_tracker-last\sources\endpoints.py", line 21, in get
    return render_template('index.html')
  File "W:\WEB_WORK\Homework\NAA\time_tracker-last\venv\lib\site-packages\flask\templating.py", line 150, in render_template
    return _render(app, template, context)
  File "W:\WEB_WORK\Homework\NAA\time_tracker-last\venv\lib\site-packages\flask\templating.py", line 131, in _render
    rv = template.render(context)
  File "W:\WEB_WORK\Homework\NAA\time_tracker-last\venv\lib\site-packages\jinja2\environment.py", line 1304, in render
    self.environment.handle_exception()
  File "W:\WEB_WORK\Homework\NAA\time_tracker-last\venv\lib\site-packages\jinja2\environment.py", line 939, in handle_exception
    raise rewrite_traceback_stack(source=source)
  File "W:\WEB_WORK\Homework\NAA\time_tracker-last\templates\index.html", line 1, in top-level template code
    {% extends 'base.html' %} {% block title %}Учет рабочего времени{% endblock %}
  File "W:\WEB_WORK\Homework\NAA\time_tracker-last\templates\base.html", line 27, in top-level template code
    {% block content %}
  File "W:\WEB_WORK\Homework\NAA\time_tracker-last\templates\index.html", line 51, in block 'content'
    {% if pagination.total > 0 %}
  File "W:\WEB_WORK\Homework\NAA\time_tracker-last\venv\lib\site-packages\jinja2\environment.py", line 487, in getattr
    return getattr(obj, attribute)
jinja2.exceptions.UndefinedError: 'pagination' is undefined
2024-12-25 20:16:22,234 - [INFO] -  config - (endpoints.py).api_data(195) - Ошибка при получении данных
2024-12-25 20:24:45,759 - [ERROR] -  config - (endpoints.py).post(28) - 1 validation error for TimeTrackerSchema
name_of_work
  Value error, Название проекта может содержать только буквы и цифры, а также не превышать 25 символов [type=value_error, input_value='ййй', input_type=str]
    For further information visit https://errors.pydantic.dev/2.10/v/value_error
2024-12-25 20:25:10,961 - [ERROR] -  config - (app.py).log_exception(838) - Exception on / [POST]
Traceback (most recent call last):
  File "W:\WEB_WORK\Homework\NAA\time_tracker-last\venv\lib\site-packages\sqlalchemy\engine\base.py", line 1967, in _exec_single_context
    self.dialect.do_execute(
  File "W:\WEB_WORK\Homework\NAA\time_tracker-last\venv\lib\site-packages\sqlalchemy\engine\default.py", line 941, in do_execute
    cursor.execute(statement, parameters)
sqlite3.OperationalError: no such column: time_tracker.username

The above exception was the direct cause of the following exception:

Traceback (most recent call last):
  File "W:\WEB_WORK\Homework\NAA\time_tracker-last\venv\lib\site-packages\flask\app.py", line 1473, in wsgi_app
    response = self.full_dispatch_request()
  File "W:\WEB_WORK\Homework\NAA\time_tracker-last\venv\lib\site-packages\flask\app.py", line 882, in full_dispatch_request
    rv = self.handle_user_exception(e)
  File "W:\WEB_WORK\Homework\NAA\time_tracker-last\venv\lib\site-packages\flask\app.py", line 880, in full_dispatch_request
    rv = self.dispatch_request()
  File "W:\WEB_WORK\Homework\NAA\time_tracker-last\venv\lib\site-packages\flask\app.py", line 865, in dispatch_request
    return self.ensure_sync(self.view_functions[rule.endpoint])(**view_args)  # type: ignore[no-any-return]
  File "W:\WEB_WORK\Homework\NAA\time_tracker-last\venv\lib\site-packages\flask\views.py", line 110, in view
    return current_app.ensure_sync(self.dispatch_request)(**kwargs)  # type: ignore[no-any-return]
  File "W:\WEB_WORK\Homework\NAA\time_tracker-last\venv\lib\site-packages\flask\views.py", line 191, in dispatch_request
    return current_app.ensure_sync(meth)(**kwargs)  # type: ignore[no-any-return]
  File "W:\WEB_WORK\Homework\NAA\time_tracker-last\venv\lib\site-packages\flask_jwt_extended\view_decorators.py", line 170, in decorator
    return current_app.ensure_sync(fn)(*args, **kwargs)
  File "W:\WEB_WORK\Homework\NAA\time_tracker-last\sources\endpoints.py", line 39, in post
    for value in values:
  File "W:\WEB_WORK\Homework\NAA\time_tracker-last\venv\lib\site-packages\sqlalchemy\orm\query.py", line 2813, in __iter__
    result = self._iter()
  File "W:\WEB_WORK\Homework\NAA\time_tracker-last\venv\lib\site-packages\sqlalchemy\orm\query.py", line 2827, in _iter
    result: Union[ScalarResult[_T], Result[_T]] = self.session.execute(
  File "W:\WEB_WORK\Homework\NAA\time_tracker-last\venv\lib\site-packages\sqlalchemy\orm\session.py", line 2362, in execute
    return self._execute_internal(
  File "W:\WEB_WORK\Homework\NAA\time_tracker-last\venv\lib\site-packages\sqlalchemy\orm\session.py", line 2247, in _execute_internal
    result: Result[Any] = compile_state_cls.orm_execute_statement(
  File "W:\WEB_WORK\Homework\NAA\time_tracker-last\venv\lib\site-packages\sqlalchemy\orm\context.py", line 305, in orm_execute_statement
    result = conn.execute(
  File "W:\WEB_WORK\Homework\NAA\time_tracker-last\venv\lib\site-packages\sqlalchemy\engine\base.py", line 1418, in execute
    return meth(
  File "W:\WEB_WORK\Homework\NAA\time_tracker-last\venv\lib\site-packages\sqlalchemy\sql\elements.py", line 515, in _execute_on_connection
    return connection._execute_clauseelement(
  File "W:\WEB_WORK\Homework\NAA\time_tracker-last\venv\lib\site-packages\sqlalchemy\engine\base.py", line 1640, in _execute_clauseelement
    ret = self._execute_context(
  File "W:\WEB_WORK\Homework\NAA\time_tracker-last\venv\lib\site-packages\sqlalchemy\engine\base.py", line 1846, in _execute_context
    return self._exec_single_context(
  File "W:\WEB_WORK\Homework\NAA\time_tracker-last\venv\lib\site-packages\sqlalchemy\engine\base.py", line 1986, in _exec_single_context
    self._handle_dbapi_exception(
  File "W:\WEB_WORK\Homework\NAA\time_tracker-last\venv\lib\site-packages\sqlalchemy\engine\base.py", line 2355, in _handle_dbapi_exception
    raise sqlalchemy_exception.with_traceback(exc_info[2]) from e
  File "W:\WEB_WORK\Homework\NAA\time_tracker-last\venv\lib\site-packages\sqlalchemy\engine\base.py", line 1967, in _exec_single_context
    self.dialect.do_execute(
  File "W:\WEB_WORK\Homework\NAA\time_tracker-last\venv\lib\site-packages\sqlalchemy\engine\default.py", line 941, in do_execute
    cursor.execute(statement, parameters)
sqlalchemy.exc.OperationalError: (sqlite3.OperationalError) no such column: time_tracker.username
[SQL: SELECT time_tracker.id AS time_tracker_id, time_tracker.name_of_work AS time_tracker_name_of_work, time_tracker.date AS time_tracker_date, time_tracker.time AS time_tracker_time, time_tracker.description AS time_tracker_description, time_tracker.username AS time_tracker_username 
FROM time_tracker 
WHERE time_tracker.date = ? AND time_tracker.username = ?]
[parameters: ('2024-12-25', 'seva')]
(Background on this error at: https://sqlalche.me/e/20/e3q8)
2024-12-25 20:26:36,202 - [ERROR] -  config - (endpoints.py).post(28) - 1 validation error for TimeTrackerSchema
name_of_work
  Value error, Название проекта может содержать только буквы и цифры, а также не превышать 25 символов [type=value_error, input_value='ввв', input_type=str]
    For further information visit https://errors.pydantic.dev/2.10/v/value_error
2024-12-25 20:32:58,080 - [ERROR] -  config - (app.py).log_exception(838) - Exception on / [POST]
Traceback (most recent call last):
  File "W:\WEB_WORK\Homework\NAA\time_tracker-last\venv\lib\site-packages\sqlalchemy\engine\base.py", line 1967, in _exec_single_context
    self.dialect.do_execute(
  File "W:\WEB_WORK\Homework\NAA\time_tracker-last\venv\lib\site-packages\sqlalchemy\engine\default.py", line 941, in do_execute
    cursor.execute(statement, parameters)
sqlite3.OperationalError: no such column: time_tracker.username

The above exception was the direct cause of the following exception:

Traceback (most recent call last):
  File "W:\WEB_WORK\Homework\NAA\time_tracker-last\venv\lib\site-packages\flask\app.py", line 1473, in wsgi_app
    response = self.full_dispatch_request()
  File "W:\WEB_WORK\Homework\NAA\time_tracker-last\venv\lib\site-packages\flask\app.py", line 882, in full_dispatch_request
    rv = self.handle_user_exception(e)
  File "W:\WEB_WORK\Homework\NAA\time_tracker-last\venv\lib\site-packages\flask\app.py", line 880, in full_dispatch_request
    rv = self.dispatch_request()
  File "W:\WEB_WORK\Homework\NAA\time_tracker-last\venv\lib\site-packages\flask\app.py", line 865, in dispatch_request
    return self.ensure_sync(self.view_functions[rule.endpoint])(**view_args)  # type: ignore[no-any-return]
  File "W:\WEB_WORK\Homework\NAA\time_tracker-last\venv\lib\site-packages\flask\views.py", line 110, in view
    return current_app.ensure_sync(self.dispatch_request)(**kwargs)  # type: ignore[no-any-return]
  File "W:\WEB_WORK\Homework\NAA\time_tracker-last\venv\lib\site-packages\flask\views.py", line 191, in dispatch_request
    return current_app.ensure_sync(meth)(**kwargs)  # type: ignore[no-any-return]
  File "W:\WEB_WORK\Homework\NAA\time_tracker-last\venv\lib\site-packages\flask_jwt_extended\view_decorators.py", line 170, in decorator
    return current_app.ensure_sync(fn)(*args, **kwargs)
  File "W:\WEB_WORK\Homework\NAA\time_tracker-last\sources\endpoints.py", line 39, in post
    for value in values:
  File "W:\WEB_WORK\Homework\NAA\time_tracker-last\venv\lib\site-packages\sqlalchemy\orm\query.py", line 2813, in __iter__
    result = self._iter()
  File "W:\WEB_WORK\Homework\NAA\time_tracker-last\venv\lib\site-packages\sqlalchemy\orm\query.py", line 2827, in _iter
    result: Union[ScalarResult[_T], Result[_T]] = self.session.execute(
  File "W:\WEB_WORK\Homework\NAA\time_tracker-last\venv\lib\site-packages\sqlalchemy\orm\session.py", line 2362, in execute
    return self._execute_internal(
  File "W:\WEB_WORK\Homework\NAA\time_tracker-last\venv\lib\site-packages\sqlalchemy\orm\session.py", line 2247, in _execute_internal
    result: Result[Any] = compile_state_cls.orm_execute_statement(
  File "W:\WEB_WORK\Homework\NAA\time_tracker-last\venv\lib\site-packages\sqlalchemy\orm\context.py", line 305, in orm_execute_statement
    result = conn.execute(
  File "W:\WEB_WORK\Homework\NAA\time_tracker-last\venv\lib\site-packages\sqlalchemy\engine\base.py", line 1418, in execute
    return meth(
  File "W:\WEB_WORK\Homework\NAA\time_tracker-last\venv\lib\site-packages\sqlalchemy\sql\elements.py", line 515, in _execute_on_connection
    return connection._execute_clauseelement(
  File "W:\WEB_WORK\Homework\NAA\time_tracker-last\venv\lib\site-packages\sqlalchemy\engine\base.py", line 1640, in _execute_clauseelement
    ret = self._execute_context(
  File "W:\WEB_WORK\Homework\NAA\time_tracker-last\venv\lib\site-packages\sqlalchemy\engine\base.py", line 1846, in _execute_context
    return self._exec_single_context(
  File "W:\WEB_WORK\Homework\NAA\time_tracker-last\venv\lib\site-packages\sqlalchemy\engine\base.py", line 1986, in _exec_single_context
    self._handle_dbapi_exception(
  File "W:\WEB_WORK\Homework\NAA\time_tracker-last\venv\lib\site-packages\sqlalchemy\engine\base.py", line 2355, in _handle_dbapi_exception
    raise sqlalchemy_exception.with_traceback(exc_info[2]) from e
  File "W:\WEB_WORK\Homework\NAA\time_tracker-last\venv\lib\site-packages\sqlalchemy\engine\base.py", line 1967, in _exec_single_context
    self.dialect.do_execute(
  File "W:\WEB_WORK\Homework\NAA\time_tracker-last\venv\lib\site-packages\sqlalchemy\engine\default.py", line 941, in do_execute
    cursor.execute(statement, parameters)
sqlalchemy.exc.OperationalError: (sqlite3.OperationalError) no such column: time_tracker.username
[SQL: SELECT time_tracker.id AS time_tracker_id, time_tracker.name_of_work AS time_tracker_name_of_work, time_tracker.date AS time_tracker_date, time_tracker.time AS time_tracker_time, time_tracker.description AS time_tracker_description, time_tracker.username AS time_tracker_username 
FROM time_tracker 
WHERE time_tracker.date = ? AND time_tracker.username = ?]
[parameters: ('2024-12-25', 'seva')]
(Background on this error at: https://sqlalche.me/e/20/e3q8)
2024-12-25 20:34:58,935 - [INFO] -  config - (endpoints.py).api_data(195) - Ошибка при получении данных
2024-12-25 20:35:34,617 - [INFO] -  config - (endpoints.py).api_data(195) - Ошибка при получении данных
2024-12-25 20:43:48,326 - [INFO] -  config - (endpoints.py).api_data(195) - Ошибка при получении данных
2024-12-25 20:47:18,693 - [INFO] -  config - (endpoints.py).api_data(195) - Ошибка при получении данных
2024-12-25 20:49:30,281 - [INFO] -  config - (endpoints.py).api_data(195) - Ошибка при получении данных
2024-12-25 20:52:04,705 - [INFO] -  config - (endpoints.py).api_data(195) - Ошибка при получении данных
2024-12-25 20:52:16,760 - [INFO] -  config - (endpoints.py).api_data(195) - Ошибка при получении данных
2024-12-25 20:52:24,408 - [INFO] -  config - (endpoints.py).api_data(195) - Ошибка при получении данных
2024-12-25 20:52:58,514 - [INFO] -  config - (endpoints.py).api_data(195) - Ошибка при получении данных
2024-12-25 20:53:04,782 - [INFO] -  config - (endpoints.py).api_data(195) - Ошибка при получении данных
2024-12-25 20:53:24,304 - [INFO] -  config - (endpoints.py).api_data(195) - Ошибка при получении данных
2024-12-25 20:57:05,621 - [INFO] -  config - (endpoints.py).api_data(195) - Ошибка при получении данных
2024-12-25 20:57:10,474 - [INFO] -  config - (endpoints.py).api_data(195) - Ошибка при получении данных
2024-12-25 20:57:51,024 - [INFO] -  config - (endpoints.py).api_data(195) - Ошибка при получении данных
2024-12-25 21:02:17,713 - [INFO] -  config - (endpoints.py).api_data(195) - Ошибка при получении данных
2024-12-25 21:02:26,846 - [INFO] -  config - (endpoints.py).api_data(195) - Ошибка при получении данных
2024-12-25 21:02:57,197 - [INFO] -  config - (endpoints.py).api_data(195) - Ошибка при получении данных
2024-12-25 21:03:20,898 - [ERROR] -  config - (app.py).log_exception(838) - Exception on /edit/25.12.2024/ddd [POST]
Traceback (most recent call last):
  File "W:\WEB_WORK\Homework\NAA\time_tracker-last\sources\endpoints.py", line 87, in post
    form_data = TimeTrackerSchema(**request.form.to_dict()).dict()
  File "W:\WEB_WORK\Homework\NAA\time_tracker-last\venv\lib\site-packages\pydantic\main.py", line 214, in __init__
    validated_self = self.__pydantic_validator__.validate_python(data, self_instance=self)
pydantic_core._pydantic_core.ValidationError: 3 validation errors for TimeTrackerSchema
name_of_work
  Field required [type=missing, input_value={}, input_type=dict]
    For further information visit https://errors.pydantic.dev/2.10/v/missing
time
  Field required [type=missing, input_value={}, input_type=dict]
    For further information visit https://errors.pydantic.dev/2.10/v/missing
date
  Field required [type=missing, input_value={}, input_type=dict]
    For further information visit https://errors.pydantic.dev/2.10/v/missing

During handling of the above exception, another exception occurred:

Traceback (most recent call last):
  File "W:\WEB_WORK\Homework\NAA\time_tracker-last\venv\lib\site-packages\flask\app.py", line 1473, in wsgi_app
    response = self.full_dispatch_request()
  File "W:\WEB_WORK\Homework\NAA\time_tracker-last\venv\lib\site-packages\flask\app.py", line 882, in full_dispatch_request
    rv = self.handle_user_exception(e)
  File "W:\WEB_WORK\Homework\NAA\time_tracker-last\venv\lib\site-packages\flask\app.py", line 880, in full_dispatch_request
    rv = self.dispatch_request()
  File "W:\WEB_WORK\Homework\NAA\time_tracker-last\venv\lib\site-packages\flask\app.py", line 865, in dispatch_request
    return self.ensure_sync(self.view_functions[rule.endpoint])(**view_args)  # type: ignore[no-any-return]
  File "W:\WEB_WORK\Homework\NAA\time_tracker-last\venv\lib\site-packages\flask\views.py", line 110, in view
    return current_app.ensure_sync(self.dispatch_request)(**kwargs)  # type: ignore[no-any-return]
  File "W:\WEB_WORK\Homework\NAA\time_tracker-last\venv\lib\site-packages\flask\views.py", line 191, in dispatch_request
    return current_app.ensure_sync(meth)(**kwargs)  # type: ignore[no-any-return]
  File "W:\WEB_WORK\Homework\NAA\time_tracker-last\venv\lib\site-packages\flask_jwt_extended\view_decorators.py", line 170, in decorator
    return current_app.ensure_sync(fn)(*args, **kwargs)
  File "W:\WEB_WORK\Homework\NAA\time_tracker-last\sources\endpoints.py", line 90, in post
    error = errors[0].split('error,')[1]
IndexError: list index out of range
2024-12-25 21:06:06,566 - [INFO] -  config - (endpoints.py).api_data(195) - Ошибка при получении данных
2024-12-25 21:06:27,227 - [INFO] -  config - (endpoints.py).api_data(195) - Ошибка при получении данных
2024-12-25 21:07:38,132 - [INFO] -  config - (endpoints.py).api_data(195) - Ошибка при получении данных
2024-12-25 21:10:20,894 - [INFO] -  config - (endpoints.py).api_data(195) - Ошибка при получении данных
2024-12-25 21:10:42,713 - [INFO] -  config - (endpoints.py).api_data(195) - Ошибка при получении данных
2024-12-25 21:10:57,740 - [INFO] -  config - (endpoints.py).api_data(195) - Ошибка при получении данных
2024-12-25 21:11:19,901 - [INFO] -  config - (endpoints.py).api_data(195) - Ошибка при получении данных
2024-12-25 21:11:52,554 - [INFO] -  config - (endpoints.py).api_data(195) - Ошибка при получении данных
2024-12-25 21:12:35,670 - [INFO] -  config - (endpoints.py).api_data(195) - Ошибка при получении данных
2024-12-25 21:14:38,206 - [INFO] -  config - (endpoints.py).api_data(195) - Ошибка при получении данных
2024-12-25 21:15:41,668 - [ERROR] -  config - (endpoints.py).post(28) - 1 validation error for TimeTrackerSchema
name_of_work
  Value error, Название проекта может содержать только буквы и цифры, а также не превышать 25 символов [type=value_error, input_value='ввв', input_type=str]
    For further information visit https://errors.pydantic.dev/2.10/v/value_error
2024-12-25 21:16:29,643 - [ERROR] -  config - (app.py).log_exception(838) - Exception on /delete/25.12.2024/ввв [DELETE]
Traceback (most recent call last):
  File "W:\WEB_WORK\Homework\NAA\time_tracker-last\venv\lib\site-packages\sqlalchemy\engine\base.py", line 1967, in _exec_single_context
    self.dialect.do_execute(
  File "W:\WEB_WORK\Homework\NAA\time_tracker-last\venv\lib\site-packages\sqlalchemy\engine\default.py", line 941, in do_execute
    cursor.execute(statement, parameters)
sqlite3.OperationalError: no such column: time_tracker.username

The above exception was the direct cause of the following exception:

Traceback (most recent call last):
  File "W:\WEB_WORK\Homework\NAA\time_tracker-last\venv\lib\site-packages\flask\app.py", line 1473, in wsgi_app
    response = self.full_dispatch_request()
  File "W:\WEB_WORK\Homework\NAA\time_tracker-last\venv\lib\site-packages\flask\app.py", line 882, in full_dispatch_request
    rv = self.handle_user_exception(e)
  File "W:\WEB_WORK\Homework\NAA\time_tracker-last\venv\lib\site-packages\flask\app.py", line 880, in full_dispatch_request
    rv = self.dispatch_request()
  File "W:\WEB_WORK\Homework\NAA\time_tracker-last\venv\lib\site-packages\flask\app.py", line 865, in dispatch_request
    return self.ensure_sync(self.view_functions[rule.endpoint])(**view_args)  # type: ignore[no-any-return]
  File "W:\WEB_WORK\Homework\NAA\time_tracker-last\venv\lib\site-packages\flask_jwt_extended\view_decorators.py", line 170, in decorator
    return current_app.ensure_sync(fn)(*args, **kwargs)
  File "W:\WEB_WORK\Homework\NAA\time_tracker-last\sources\endpoints.py", line 160, in delete_item
    ).delete():
  File "W:\WEB_WORK\Homework\NAA\time_tracker-last\venv\lib\site-packages\sqlalchemy\orm\query.py", line 3162, in delete
    result: CursorResult[Any] = self.session.execute(
  File "W:\WEB_WORK\Homework\NAA\time_tracker-last\venv\lib\site-packages\sqlalchemy\orm\session.py", line 2362, in execute
    return self._execute_internal(
  File "W:\WEB_WORK\Homework\NAA\time_tracker-last\venv\lib\site-packages\sqlalchemy\orm\session.py", line 2247, in _execute_internal
    result: Result[Any] = compile_state_cls.orm_execute_statement(
  File "W:\WEB_WORK\Homework\NAA\time_tracker-last\venv\lib\site-packages\sqlalchemy\orm\bulk_persistence.py", line 2021, in orm_execute_statement
    return super().orm_execute_statement(
  File "W:\WEB_WORK\Homework\NAA\time_tracker-last\venv\lib\site-packages\sqlalchemy\orm\context.py", line 305, in orm_execute_statement
    result = conn.execute(
  File "W:\WEB_WORK\Homework\NAA\time_tracker-last\venv\lib\site-packages\sqlalchemy\engine\base.py", line 1418, in execute
    return meth(
  File "W:\WEB_WORK\Homework\NAA\time_tracker-last\venv\lib\site-packages\sqlalchemy\sql\elements.py", line 515, in _execute_on_connection
    return connection._execute_clauseelement(
  File "W:\WEB_WORK\Homework\NAA\time_tracker-last\venv\lib\site-packages\sqlalchemy\engine\base.py", line 1640, in _execute_clauseelement
    ret = self._execute_context(
  File "W:\WEB_WORK\Homework\NAA\time_tracker-last\venv\lib\site-packages\sqlalchemy\engine\base.py", line 1846, in _execute_context
    return self._exec_single_context(
  File "W:\WEB_WORK\Homework\NAA\time_tracker-last\venv\lib\site-packages\sqlalchemy\engine\base.py", line 1986, in _exec_single_context
    self._handle_dbapi_exception(
  File "W:\WEB_WORK\Homework\NAA\time_tracker-last\venv\lib\site-packages\sqlalchemy\engine\base.py", line 2355, in _handle_dbapi_exception
    raise sqlalchemy_exception.with_traceback(exc_info[2]) from e
  File "W:\WEB_WORK\Homework\NAA\time_tracker-last\venv\lib\site-packages\sqlalchemy\engine\base.py", line 1967, in _exec_single_context
    self.dialect.do_execute(
  File "W:\WEB_WORK\Homework\NAA\time_tracker-last\venv\lib\site-packages\sqlalchemy\engine\default.py", line 941, in do_execute
    cursor.execute(statement, parameters)
sqlalchemy.exc.OperationalError: (sqlite3.OperationalError) no such column: time_tracker.username
[SQL: DELETE FROM time_tracker WHERE time_tracker.name_of_work = ? AND time_tracker.date = ? AND time_tracker.username = ?]
[parameters: ('name_of_work', '2024-12-25', 'seva')]
(Background on this error at: https://sqlalche.me/e/20/e3q8)
2024-12-25 21:18:24,782 - [INFO] -  config - (endpoints.py).api_data(195) - Ошибка при получении данных
2024-12-25 21:19:10,612 - [ERROR] -  config - (endpoints.py).post(28) - 1 validation error for TimeTrackerSchema
name_of_work
  Value error, Название проекта может содержать только буквы и цифры, а также не превышать 25 символов [type=value_error, input_value='ккк', input_type=str]
    For further information visit https://errors.pydantic.dev/2.10/v/value_error
2024-12-25 21:45:28,622 - [INFO] -  config - (app.py).create_app(9) - Создана БД
2024-12-25 21:45:28,627 - [INFO] -  config - (app.py).create_app(12) - Зарегистрирован (<Blueprint 'timer'>, <Blueprint 'users'>)
2024-12-25 21:45:29,410 - [INFO] -  config - (app.py).create_app(9) - Создана БД
2024-12-25 21:45:29,414 - [INFO] -  config - (app.py).create_app(12) - Зарегистрирован (<Blueprint 'timer'>, <Blueprint 'users'>)
2024-12-25 21:45:50,089 - [INFO] -  config - (endpoints.py).api_data(195) - Ошибка при получении данных
2024-12-25 21:45:53,917 - [INFO] -  config - (user.py).get(113) - Пользователь seva вышел из системы!
2024-12-25 21:45:53,941 - [ERROR] -  config - (config.py).load_logged_in_user(83) - Error in load_logged_in_user: Token has been revoked
2024-12-25 21:45:53,982 - [ERROR] -  config - (config.py).load_logged_in_user(83) - Error in load_logged_in_user: Token has been revoked
2024-12-25 21:45:55,373 - [ERROR] -  config - (config.py).load_logged_in_user(83) - Error in load_logged_in_user: Token has been revoked
2024-12-25 21:45:55,409 - [ERROR] -  config - (config.py).load_logged_in_user(83) - Error in load_logged_in_user: Token has been revoked
2024-12-25 21:45:55,551 - [ERROR] -  config - (config.py).load_logged_in_user(83) - Error in load_logged_in_user: Token has been revoked
2024-12-25 21:45:55,588 - [ERROR] -  config - (config.py).load_logged_in_user(83) - Error in load_logged_in_user: Token has been revoked
2024-12-25 21:45:56,856 - [ERROR] -  config - (config.py).load_logged_in_user(83) - Error in load_logged_in_user: Token has been revoked
2024-12-25 21:45:56,970 - [ERROR] -  config - (config.py).load_logged_in_user(83) - Error in load_logged_in_user: Token has been revoked
2024-12-25 21:46:07,309 - [ERROR] -  config - (config.py).load_logged_in_user(83) - Error in load_logged_in_user: Token has been revoked
2024-12-25 21:46:07,341 - [ERROR] -  config - (config.py).load_logged_in_user(83) - Error in load_logged_in_user: Token has been revoked
2024-12-25 21:46:07,395 - [ERROR] -  config - (config.py).load_logged_in_user(83) - Error in load_logged_in_user: Token has been revoked
2024-12-25 21:46:18,316 - [ERROR] -  config - (config.py).load_logged_in_user(83) - Error in load_logged_in_user: Token has been revoked
2024-12-25 21:46:18,460 - [INFO] -  config - (user.py).post(43) - Пользователь Александр зарегистирован!
2024-12-25 21:46:18,469 - [ERROR] -  config - (config.py).load_logged_in_user(83) - Error in load_logged_in_user: Token has been revoked
2024-12-25 21:46:18,496 - [ERROR] -  config - (config.py).load_logged_in_user(83) - Error in load_logged_in_user: Token has been revoked
2024-12-25 21:46:30,708 - [ERROR] -  config - (config.py).load_logged_in_user(83) - Error in load_logged_in_user: Token has been revoked
2024-12-25 21:46:30,817 - [INFO] -  config - (user.py).post(89) - Пользователь Александр вошел в систему!
2024-12-25 21:46:30,976 - [INFO] -  config - (endpoints.py).api_data(195) - Ошибка при получении данных
2024-12-25 21:47:18,725 - [ERROR] -  config - (endpoints.py).post(28) - 1 validation error for TimeTrackerSchema
name_of_work
  Value error, Название проекта может содержать только буквы и цифры, а также не превышать 25 символов [type=value_error, input_value='йцу', input_type=str]
    For further information visit https://errors.pydantic.dev/2.10/v/value_error
2024-12-25 21:47:24,021 - [INFO] -  config - (endpoints.py).api_data(195) - Ошибка при получении данных
2024-12-25 21:48:14,863 - [INFO] -  config - (endpoints.py).api_data(195) - Ошибка при получении данных
2024-12-25 21:50:29,417 - [INFO] -  config - (endpoints.py).api_data(195) - Ошибка при получении данных
2024-12-25 21:51:10,450 - [INFO] -  config - (user.py).get(113) - Пользователь Александр вышел из системы!
2024-12-25 21:51:10,465 - [ERROR] -  config - (config.py).load_logged_in_user(83) - Error in load_logged_in_user: Token has been revoked
2024-12-25 21:51:10,490 - [ERROR] -  config - (config.py).load_logged_in_user(83) - Error in load_logged_in_user: Token has been revoked
2024-12-25 21:51:11,693 - [ERROR] -  config - (config.py).load_logged_in_user(83) - Error in load_logged_in_user: Token has been revoked
2024-12-25 21:51:11,715 - [ERROR] -  config - (config.py).load_logged_in_user(83) - Error in load_logged_in_user: Token has been revoked
2024-12-25 21:51:17,843 - [ERROR] -  config - (config.py).load_logged_in_user(83) - Error in load_logged_in_user: Token has been revoked
2024-12-25 21:51:21,085 - [ERROR] -  config - (config.py).load_logged_in_user(83) - Error in load_logged_in_user: Token has been revoked
2024-12-25 21:51:21,112 - [ERROR] -  config - (config.py).load_logged_in_user(83) - Error in load_logged_in_user: Token has been revoked
2024-12-25 21:51:25,521 - [ERROR] -  config - (config.py).load_logged_in_user(83) - Error in load_logged_in_user: Token has been revoked
2024-12-25 21:51:25,636 - [INFO] -  config - (user.py).post(43) - Пользователь wwww зарегистирован!
2024-12-25 21:51:25,643 - [ERROR] -  config - (config.py).load_logged_in_user(83) - Error in load_logged_in_user: Token has been revoked
2024-12-25 21:51:25,671 - [ERROR] -  config - (config.py).load_logged_in_user(83) - Error in load_logged_in_user: Token has been revoked
2024-12-25 21:51:29,757 - [ERROR] -  config - (config.py).load_logged_in_user(83) - Error in load_logged_in_user: Token has been revoked
2024-12-25 21:51:29,841 - [INFO] -  config - (user.py).post(89) - Пользователь wwww вошел в систему!
2024-12-25 21:51:29,905 - [INFO] -  config - (endpoints.py).api_data(195) - Ошибка при получении данных
2024-12-25 21:53:36,800 - [INFO] -  config - (app.py).create_app(9) - Создана БД
2024-12-25 21:53:36,803 - [INFO] -  config - (app.py).create_app(12) - Зарегистрирован (<Blueprint 'timer'>, <Blueprint 'users'>)
2024-12-25 21:53:37,704 - [INFO] -  config - (app.py).create_app(9) - Создана БД
2024-12-25 21:53:37,708 - [INFO] -  config - (app.py).create_app(12) - Зарегистрирован (<Blueprint 'timer'>, <Blueprint 'users'>)
2024-12-25 21:53:45,353 - [ERROR] -  config - (app.py).log_exception(838) - Exception on /api/data/ [GET]
Traceback (most recent call last):
  File "W:\WEB_WORK\Homework\NAA\time_tracker-last\venv\lib\site-packages\sqlalchemy\engine\base.py", line 1967, in _exec_single_context
    self.dialect.do_execute(
  File "W:\WEB_WORK\Homework\NAA\time_tracker-last\venv\lib\site-packages\sqlalchemy\engine\default.py", line 941, in do_execute
    cursor.execute(statement, parameters)
sqlite3.OperationalError: no such column: time_tracker.username

The above exception was the direct cause of the following exception:

Traceback (most recent call last):
  File "W:\WEB_WORK\Homework\NAA\time_tracker-last\venv\lib\site-packages\flask\app.py", line 1473, in wsgi_app
    response = self.full_dispatch_request()
  File "W:\WEB_WORK\Homework\NAA\time_tracker-last\venv\lib\site-packages\flask\app.py", line 882, in full_dispatch_request
    rv = self.handle_user_exception(e)
  File "W:\WEB_WORK\Homework\NAA\time_tracker-last\venv\lib\site-packages\flask\app.py", line 880, in full_dispatch_request
    rv = self.dispatch_request()
  File "W:\WEB_WORK\Homework\NAA\time_tracker-last\venv\lib\site-packages\flask\app.py", line 865, in dispatch_request
    return self.ensure_sync(self.view_functions[rule.endpoint])(**view_args)  # type: ignore[no-any-return]
  File "W:\WEB_WORK\Homework\NAA\time_tracker-last\venv\lib\site-packages\flask_jwt_extended\view_decorators.py", line 170, in decorator
    return current_app.ensure_sync(fn)(*args, **kwargs)
  File "W:\WEB_WORK\Homework\NAA\time_tracker-last\sources\endpoints.py", line 188, in api_data
    total_time = sum_time(data_total_time.all()).strftime('%H:%M:%S')
  File "W:\WEB_WORK\Homework\NAA\time_tracker-last\venv\lib\site-packages\sqlalchemy\orm\query.py", line 2673, in all
    return self._iter().all()  # type: ignore
  File "W:\WEB_WORK\Homework\NAA\time_tracker-last\venv\lib\site-packages\sqlalchemy\orm\query.py", line 2827, in _iter
    result: Union[ScalarResult[_T], Result[_T]] = self.session.execute(
  File "W:\WEB_WORK\Homework\NAA\time_tracker-last\venv\lib\site-packages\sqlalchemy\orm\session.py", line 2362, in execute
    return self._execute_internal(
  File "W:\WEB_WORK\Homework\NAA\time_tracker-last\venv\lib\site-packages\sqlalchemy\orm\session.py", line 2247, in _execute_internal
    result: Result[Any] = compile_state_cls.orm_execute_statement(
  File "W:\WEB_WORK\Homework\NAA\time_tracker-last\venv\lib\site-packages\sqlalchemy\orm\context.py", line 305, in orm_execute_statement
    result = conn.execute(
  File "W:\WEB_WORK\Homework\NAA\time_tracker-last\venv\lib\site-packages\sqlalchemy\engine\base.py", line 1418, in execute
    return meth(
  File "W:\WEB_WORK\Homework\NAA\time_tracker-last\venv\lib\site-packages\sqlalchemy\sql\elements.py", line 515, in _execute_on_connection
    return connection._execute_clauseelement(
  File "W:\WEB_WORK\Homework\NAA\time_tracker-last\venv\lib\site-packages\sqlalchemy\engine\base.py", line 1640, in _execute_clauseelement
    ret = self._execute_context(
  File "W:\WEB_WORK\Homework\NAA\time_tracker-last\venv\lib\site-packages\sqlalchemy\engine\base.py", line 1846, in _execute_context
    return self._exec_single_context(
  File "W:\WEB_WORK\Homework\NAA\time_tracker-last\venv\lib\site-packages\sqlalchemy\engine\base.py", line 1986, in _exec_single_context
    self._handle_dbapi_exception(
  File "W:\WEB_WORK\Homework\NAA\time_tracker-last\venv\lib\site-packages\sqlalchemy\engine\base.py", line 2355, in _handle_dbapi_exception
    raise sqlalchemy_exception.with_traceback(exc_info[2]) from e
  File "W:\WEB_WORK\Homework\NAA\time_tracker-last\venv\lib\site-packages\sqlalchemy\engine\base.py", line 1967, in _exec_single_context
    self.dialect.do_execute(
  File "W:\WEB_WORK\Homework\NAA\time_tracker-last\venv\lib\site-packages\sqlalchemy\engine\default.py", line 941, in do_execute
    cursor.execute(statement, parameters)
sqlalchemy.exc.OperationalError: (sqlite3.OperationalError) no such column: time_tracker.username
[SQL: SELECT time_tracker.id AS time_tracker_id, time_tracker.name_of_work AS time_tracker_name_of_work, time_tracker.date AS time_tracker_date, time_tracker.time AS time_tracker_time, time_tracker.description AS time_tracker_description, time_tracker.username AS time_tracker_username 
FROM time_tracker 
WHERE time_tracker.username = ? AND time_tracker.date = ?]
[parameters: ('wwww', '2024-12-25')]
(Background on this error at: https://sqlalche.me/e/20/e3q8)
2024-12-25 21:55:29,877 - [INFO] -  config - (app.py).create_app(9) - Создана БД
2024-12-25 21:55:29,881 - [INFO] -  config - (app.py).create_app(12) - Зарегистрирован (<Blueprint 'timer'>, <Blueprint 'users'>)
2024-12-25 21:55:30,676 - [INFO] -  config - (app.py).create_app(9) - Создана БД
2024-12-25 21:55:30,680 - [INFO] -  config - (app.py).create_app(12) - Зарегистрирован (<Blueprint 'timer'>, <Blueprint 'users'>)
2024-12-25 21:55:46,695 - [INFO] -  config - (user.py).get(113) - Пользователь wwww вышел из системы!
2024-12-25 21:55:46,707 - [ERROR] -  config - (config.py).load_logged_in_user(83) - Error in load_logged_in_user: Token has been revoked
2024-12-25 21:55:46,748 - [ERROR] -  config - (config.py).load_logged_in_user(83) - Error in load_logged_in_user: Token has been revoked
2024-12-25 21:55:47,733 - [ERROR] -  config - (config.py).load_logged_in_user(83) - Error in load_logged_in_user: Token has been revoked
2024-12-25 21:55:47,759 - [ERROR] -  config - (config.py).load_logged_in_user(83) - Error in load_logged_in_user: Token has been revoked
2024-12-25 21:55:48,084 - [ERROR] -  config - (config.py).load_logged_in_user(83) - Error in load_logged_in_user: Token has been revoked
2024-12-25 21:55:48,123 - [ERROR] -  config - (config.py).load_logged_in_user(83) - Error in load_logged_in_user: Token has been revoked
2024-12-25 21:55:49,415 - [ERROR] -  config - (config.py).load_logged_in_user(83) - Error in load_logged_in_user: Token has been revoked
2024-12-25 21:55:49,456 - [ERROR] -  config - (config.py).load_logged_in_user(83) - Error in load_logged_in_user: Token has been revoked
2024-12-25 21:55:55,806 - [ERROR] -  config - (config.py).load_logged_in_user(83) - Error in load_logged_in_user: Token has been revoked
2024-12-25 21:55:57,652 - [ERROR] -  config - (config.py).load_logged_in_user(83) - Error in load_logged_in_user: Token has been revoked
2024-12-25 21:55:57,691 - [ERROR] -  config - (config.py).load_logged_in_user(83) - Error in load_logged_in_user: Token has been revoked
2024-12-25 21:56:02,193 - [ERROR] -  config - (config.py).load_logged_in_user(83) - Error in load_logged_in_user: Token has been revoked
2024-12-25 21:56:02,301 - [INFO] -  config - (user.py).post(43) - Пользователь wwww зарегистирован!
2024-12-25 21:56:02,312 - [ERROR] -  config - (config.py).load_logged_in_user(83) - Error in load_logged_in_user: Token has been revoked
2024-12-25 21:56:02,404 - [ERROR] -  config - (config.py).load_logged_in_user(83) - Error in load_logged_in_user: Token has been revoked
2024-12-25 21:56:06,849 - [ERROR] -  config - (config.py).load_logged_in_user(83) - Error in load_logged_in_user: Token has been revoked
2024-12-25 21:56:06,945 - [INFO] -  config - (user.py).post(89) - Пользователь wwww вошел в систему!
2024-12-25 21:57:19,646 - [INFO] -  config - (endpoints.py).post(59) - Данные по задаче eee добавлены в БД
2024-12-25 21:57:28,314 - [ERROR] -  config - (endpoints.py).delete_item(166) - Ошибка при удалении задачи: name = eee, date = 2024-12-25
2024-12-25 21:57:46,928 - [ERROR] -  config - (endpoints.py).delete_item(166) - Ошибка при удалении задачи: name = eee, date = 2024-12-25
2024-12-25 22:03:28,120 - [INFO] -  config - (app.py).create_app(9) - Создана БД
2024-12-25 22:03:28,124 - [INFO] -  config - (app.py).create_app(12) - Зарегистрирован (<Blueprint 'timer'>, <Blueprint 'users'>)
2024-12-25 22:03:28,846 - [INFO] -  config - (app.py).create_app(9) - Создана БД
2024-12-25 22:03:28,850 - [INFO] -  config - (app.py).create_app(12) - Зарегистрирован (<Blueprint 'timer'>, <Blueprint 'users'>)
2024-12-25 22:03:59,543 - [ERROR] -  config - (endpoints.py).delete_item(166) - Ошибка при удалении задачи: name = eee, date = 2024-12-25
2024-12-25 22:04:36,333 - [INFO] -  config - (app.py).create_app(9) - Создана БД
2024-12-25 22:04:36,339 - [INFO] -  config - (app.py).create_app(12) - Зарегистрирован (<Blueprint 'timer'>, <Blueprint 'users'>)
2024-12-25 22:04:39,546 - [INFO] -  config - (app.py).create_app(9) - Создана БД
2024-12-25 22:04:39,550 - [INFO] -  config - (app.py).create_app(12) - Зарегистрирован (<Blueprint 'timer'>, <Blueprint 'users'>)
2024-12-25 22:04:44,586 - [INFO] -  config - (app.py).create_app(9) - Создана БД
2024-12-25 22:04:44,590 - [INFO] -  config - (app.py).create_app(12) - Зарегистрирован (<Blueprint 'timer'>, <Blueprint 'users'>)
2024-12-25 22:04:48,683 - [INFO] -  config - (app.py).create_app(9) - Создана БД
2024-12-25 22:04:48,686 - [INFO] -  config - (app.py).create_app(12) - Зарегистрирован (<Blueprint 'timer'>, <Blueprint 'users'>)
2024-12-25 22:04:50,818 - [INFO] -  config - (app.py).create_app(9) - Создана БД
2024-12-25 22:04:50,823 - [INFO] -  config - (app.py).create_app(12) - Зарегистрирован (<Blueprint 'timer'>, <Blueprint 'users'>)
2024-12-25 22:04:52,785 - [INFO] -  config - (app.py).create_app(9) - Создана БД
2024-12-25 22:04:52,788 - [INFO] -  config - (app.py).create_app(12) - Зарегистрирован (<Blueprint 'timer'>, <Blueprint 'users'>)
2024-12-25 22:05:01,959 - [INFO] -  config - (app.py).create_app(9) - Создана БД
2024-12-25 22:05:01,963 - [INFO] -  config - (app.py).create_app(12) - Зарегистрирован (<Blueprint 'timer'>, <Blueprint 'users'>)
2024-12-25 22:05:07,123 - [ERROR] -  config - (endpoints.py).delete_item(168) - Ошибка при удалении задачи: name = eee, date = 2024-12-25
2024-12-25 22:11:34,041 - [ERROR] -  config - (endpoints.py).delete_item(168) - Ошибка при удалении задачи: name = eee, date = 2024-12-25
2024-12-25 22:12:29,756 - [ERROR] -  config - (endpoints.py).delete_item(168) - Ошибка при удалении задачи: name = eee, date = 2024-12-25
2024-12-25 22:12:52,565 - [INFO] -  config - (app.py).create_app(9) - Создана БД
2024-12-25 22:12:52,568 - [INFO] -  config - (app.py).create_app(12) - Зарегистрирован (<Blueprint 'timer'>, <Blueprint 'users'>)
2024-12-25 22:12:54,532 - [INFO] -  config - (app.py).create_app(9) - Создана БД
2024-12-25 22:12:54,536 - [INFO] -  config - (app.py).create_app(12) - Зарегистрирован (<Blueprint 'timer'>, <Blueprint 'users'>)
2024-12-25 22:13:21,215 - [INFO] -  config - (app.py).create_app(9) - Создана БД
2024-12-25 22:13:21,223 - [INFO] -  config - (app.py).create_app(12) - Зарегистрирован (<Blueprint 'timer'>, <Blueprint 'users'>)
2024-12-25 22:13:35,658 - [INFO] -  config - (endpoints.py).delete_item(162) - Удалена задача: name = eee, date = 2024-12-25
2024-12-25 22:14:16,258 - [INFO] -  config - (endpoints.py).post(59) - Данные по задаче eee добавлены в БД
2024-12-25 22:14:21,165 - [INFO] -  config - (endpoints.py).post(59) - Данные по задаче rrr добавлены в БД
2024-12-25 22:14:24,477 - [INFO] -  config - (endpoints.py).post(144) - Измененны данные по задаче eee. Название: eee, Время: 00:00:03, Дата: 2024-12-25.
2024-12-25 22:14:36,007 - [INFO] -  config - (endpoints.py).post(144) - Измененны данные по задаче eee. Название: eee, Время: 00:00:25, Дата: 2024-12-25.
2024-12-25 22:14:43,592 - [INFO] -  config - (endpoints.py).post(144) - Измененны данные по задаче eee. Название: eee, Время: 00:00:25, Дата: 2024-12-20.
2024-12-25 22:14:54,373 - [INFO] -  config - (endpoints.py).post(59) - Данные по задаче fff добавлены в БД
2024-12-25 22:15:26,344 - [INFO] -  config - (endpoints.py).post(59) - Данные по задаче eee добавлены в БД
2024-12-25 22:16:26,628 - [INFO] -  config - (endpoints.py).post(44) - Обновлены данные по задаче fff. Время: 00:00:13
2024-12-25 22:16:55,631 - [INFO] -  config - (endpoints.py).post(44) - Обновлены данные по задаче fff. Время: 00:00:26
2024-12-25 22:16:58,922 - [INFO] -  config - (endpoints.py).delete_item(162) - Удалена задача: name = fff, date = 2024-12-25
2024-12-25 22:17:03,143 - [INFO] -  config - (endpoints.py).delete_item(162) - Удалена задача: name = eee, date = 2024-12-25
2024-12-26 13:22:23,458 - [INFO] -  config - (app.py).create_app(9) - Создана БД
2024-12-26 13:22:23,458 - [INFO] -  config - (app.py).create_app(12) - Зарегистрирован (<Blueprint 'timer'>, <Blueprint 'users'>)
2024-12-26 13:22:24,189 - [INFO] -  config - (app.py).create_app(9) - Создана БД
2024-12-26 13:22:24,189 - [INFO] -  config - (app.py).create_app(12) - Зарегистрирован (<Blueprint 'timer'>, <Blueprint 'users'>)
2024-12-26 13:22:25,786 - [ERROR] -  config - (config.py).load_logged_in_user(83) - Error in load_logged_in_user: Signature has expired
2024-12-26 13:22:25,885 - [ERROR] -  config - (config.py).load_logged_in_user(83) - Error in load_logged_in_user: Signature has expired
2024-12-26 13:22:27,078 - [ERROR] -  config - (config.py).load_logged_in_user(83) - Error in load_logged_in_user: Signature has expired
2024-12-26 13:22:27,119 - [ERROR] -  config - (config.py).load_logged_in_user(83) - Error in load_logged_in_user: Signature has expired
2024-12-26 13:22:29,154 - [ERROR] -  config - (config.py).load_logged_in_user(83) - Error in load_logged_in_user: Signature has expired
2024-12-26 13:22:29,218 - [ERROR] -  config - (config.py).load_logged_in_user(83) - Error in load_logged_in_user: Signature has expired
2024-12-26 13:22:48,211 - [ERROR] -  config - (config.py).load_logged_in_user(83) - Error in load_logged_in_user: Signature has expired
2024-12-26 13:22:48,299 - [INFO] -  config - (user.py).post(89) - Пользователь wwww вошел в систему!
2024-12-26 15:42:19,095 - [INFO] -  config - (app.py).create_app(9) - Создана БД
2024-12-26 15:42:19,099 - [INFO] -  config - (app.py).create_app(12) - Зарегистрирован (<Blueprint 'timer'>, <Blueprint 'users'>)
2024-12-26 15:42:19,795 - [INFO] -  config - (app.py).create_app(9) - Создана БД
2024-12-26 15:42:19,795 - [INFO] -  config - (app.py).create_app(12) - Зарегистрирован (<Blueprint 'timer'>, <Blueprint 'users'>)
2024-12-26 15:52:03,855 - [INFO] -  config - (app.py).create_app(9) - Создана БД
2024-12-26 15:52:03,855 - [INFO] -  config - (app.py).create_app(12) - Зарегистрирован (<Blueprint 'timer'>, <Blueprint 'users'>)
2024-12-26 15:52:24,254 - [INFO] -  config - (app.py).create_app(9) - Создана БД
2024-12-26 15:52:24,258 - [INFO] -  config - (app.py).create_app(12) - Зарегистрирован (<Blueprint 'timer'>, <Blueprint 'users'>)
2024-12-26 15:53:29,066 - [INFO] -  config - (app.py).create_app(9) - Создана БД
2024-12-26 15:53:29,068 - [INFO] -  config - (app.py).create_app(12) - Зарегистрирован (<Blueprint 'timer'>, <Blueprint 'users'>)
2024-12-26 15:53:29,378 - [INFO] -  config - (endpoints.py).api_statistics(208) - Ошибка при получении данных
2024-12-26 15:54:17,370 - [INFO] -  config - (app.py).create_app(9) - Создана БД
2024-12-26 15:54:17,370 - [INFO] -  config - (app.py).create_app(12) - Зарегистрирован (<Blueprint 'timer'>, <Blueprint 'users'>)
2024-12-26 15:54:47,400 - [INFO] -  config - (app.py).create_app(9) - Создана БД
2024-12-26 15:54:47,404 - [INFO] -  config - (app.py).create_app(12) - Зарегистрирован (<Blueprint 'timer'>, <Blueprint 'users'>)
2024-12-26 15:54:48,112 - [INFO] -  config - (app.py).create_app(9) - Создана БД
2024-12-26 15:54:48,116 - [INFO] -  config - (app.py).create_app(12) - Зарегистрирован (<Blueprint 'timer'>, <Blueprint 'users'>)
2024-12-26 15:54:48,361 - [INFO] -  config - (endpoints.py).api_statistics(208) - Ошибка при получении данных
2024-12-26 15:54:50,854 - [INFO] -  config - (endpoints.py).api_statistics(208) - Ошибка при получении данных
2024-12-26 15:54:53,795 - [INFO] -  config - (endpoints.py).api_statistics(208) - Ошибка при получении данных
2024-12-26 15:55:57,709 - [INFO] -  config - (app.py).create_app(9) - Создана БД
2024-12-26 15:55:57,709 - [INFO] -  config - (app.py).create_app(12) - Зарегистрирован (<Blueprint 'timer'>, <Blueprint 'users'>)
2024-12-26 15:55:58,450 - [INFO] -  config - (app.py).create_app(9) - Создана БД
2024-12-26 15:55:58,453 - [INFO] -  config - (app.py).create_app(12) - Зарегистрирован (<Blueprint 'timer'>, <Blueprint 'users'>)
2024-12-26 15:55:59,153 - [INFO] -  config - (endpoints.py).api_statistics(208) - Ошибка при получении данных
2024-12-26 15:56:07,798 - [INFO] -  config - (app.py).create_app(9) - Создана БД
2024-12-26 15:56:07,798 - [INFO] -  config - (app.py).create_app(12) - Зарегистрирован (<Blueprint 'timer'>, <Blueprint 'users'>)
2024-12-26 16:05:18,834 - [INFO] -  config - (endpoints.py).post(59) - Данные по задаче fff добавлены в БД
2024-12-26 16:05:25,661 - [INFO] -  config - (endpoints.py).post(44) - Обновлены данные по задаче fff. Время: 00:00:09
2024-12-26 16:05:35,998 - [INFO] -  config - (endpoints.py).post(59) - Данные по задаче eee добавлены в БД
2024-12-26 16:05:49,358 - [INFO] -  config - (endpoints.py).post(44) - Обновлены данные по задаче eee. Время: 00:00:08
2024-12-26 16:05:56,159 - [INFO] -  config - (endpoints.py).post(59) - Данные по задаче ttt добавлены в БД
2024-12-26 17:23:06,167 - [INFO] -  config - (app.py).create_app(9) - Создана БД
2024-12-26 17:23:06,167 - [INFO] -  config - (app.py).create_app(12) - Зарегистрирован (<Blueprint 'timer'>, <Blueprint 'users'>)
2024-12-26 17:23:06,863 - [INFO] -  config - (app.py).create_app(9) - Создана БД
2024-12-26 17:23:06,863 - [INFO] -  config - (app.py).create_app(12) - Зарегистрирован (<Blueprint 'timer'>, <Blueprint 'users'>)
2024-12-26 18:46:47,866 - [ERROR] -  config - (config.py).load_logged_in_user(83) - Error in load_logged_in_user: Signature has expired
2024-12-26 18:46:49,401 - [ERROR] -  config - (config.py).load_logged_in_user(83) - Error in load_logged_in_user: Signature has expired
2024-12-26 18:47:00,804 - [ERROR] -  config - (config.py).load_logged_in_user(83) - Error in load_logged_in_user: Signature has expired
2024-12-26 18:47:04,473 - [ERROR] -  config - (config.py).load_logged_in_user(83) - Error in load_logged_in_user: Signature has expired
2024-12-26 18:47:04,570 - [ERROR] -  config - (config.py).load_logged_in_user(83) - Error in load_logged_in_user: Signature has expired
2024-12-26 18:47:06,624 - [ERROR] -  config - (config.py).load_logged_in_user(83) - Error in load_logged_in_user: Signature has expired
2024-12-26 18:47:06,711 - [ERROR] -  config - (config.py).load_logged_in_user(83) - Error in load_logged_in_user: Signature has expired
2024-12-26 18:47:16,799 - [ERROR] -  config - (config.py).load_logged_in_user(83) - Error in load_logged_in_user: Signature has expired
2024-12-26 18:47:23,567 - [ERROR] -  config - (config.py).load_logged_in_user(83) - Error in load_logged_in_user: Signature has expired
2024-12-26 18:47:23,661 - [INFO] -  config - (user.py).post(89) - Пользователь wwww вошел в систему!
2024-12-26 19:08:40,424 - [INFO] -  config - (app.py).create_app(9) - Создана БД
2024-12-26 19:08:40,424 - [INFO] -  config - (app.py).create_app(12) - Зарегистрирован (<Blueprint 'timer'>, <Blueprint 'users'>)
2024-12-26 19:08:41,105 - [INFO] -  config - (app.py).create_app(9) - Создана БД
2024-12-26 19:08:41,105 - [INFO] -  config - (app.py).create_app(12) - Зарегистрирован (<Blueprint 'timer'>, <Blueprint 'users'>)
2024-12-26 21:04:28,322 - [INFO] -  config - (endpoints.py).post(59) - Данные по задаче  добавлены в БД
2024-12-26 21:09:28,203 - [INFO] -  config - (endpoints.py).post(59) - Данные по задаче ddd добавлены в БД
2024-12-26 21:10:05,483 - [INFO] -  config - (endpoints.py).post(44) - Обновлены данные по задаче ddd. Время: 00:00:06
2024-12-26 21:12:55,185 - [INFO] -  config - (endpoints.py).post(44) - Обновлены данные по задаче . Время: 00:00:14
2024-12-27 10:29:44,351 - [ERROR] -  config - (config.py).load_logged_in_user(83) - Error in load_logged_in_user: Signature has expired
2024-12-27 10:29:46,259 - [ERROR] -  config - (config.py).load_logged_in_user(83) - Error in load_logged_in_user: Signature has expired
2024-12-27 10:29:50,304 - [ERROR] -  config - (config.py).load_logged_in_user(83) - Error in load_logged_in_user: Signature has expired
2024-12-27 10:29:50,321 - [ERROR] -  config - (config.py).load_logged_in_user(83) - Error in load_logged_in_user: Signature has expired
2024-12-27 10:29:51,908 - [ERROR] -  config - (config.py).load_logged_in_user(83) - Error in load_logged_in_user: Signature has expired
2024-12-27 10:29:51,944 - [ERROR] -  config - (config.py).load_logged_in_user(83) - Error in load_logged_in_user: Signature has expired
2024-12-27 10:29:58,074 - [ERROR] -  config - (config.py).load_logged_in_user(83) - Error in load_logged_in_user: Signature has expired
2024-12-27 10:29:58,166 - [INFO] -  config - (user.py).post(89) - Пользователь wwww вошел в систему!
2024-12-27 11:49:32,002 - [INFO] -  config - (app.py).create_app(9) - Создана БД
2024-12-27 11:49:32,002 - [INFO] -  config - (app.py).create_app(12) - Зарегистрирован (<Blueprint 'timer'>, <Blueprint 'users'>)
2024-12-27 11:49:32,695 - [INFO] -  config - (app.py).create_app(9) - Создана БД
2024-12-27 11:49:32,695 - [INFO] -  config - (app.py).create_app(12) - Зарегистрирован (<Blueprint 'timer'>, <Blueprint 'users'>)
